Workbook

Sheet Dashboard
A1: ÇORUM FK SCOUTING | CONTROL CENTER | AC1: ÜLKE | AD1: OYUNCU
AC2: =IFERROR(INDEX('Veri Merkezi'!$B$2:$B$1001,MATCH(0,INDEX(COUNTIF($AC$1:AC1,'Veri Merkezi'!$B$2:$B$1001)+('Veri Merkezi'!$B$2:$B$1001=""),0),0)),"") -> ARJANTİN | AD2: =IF(AC2="","",COUNTIF('Veri Merkezi'!$B$2:$B$1001,AC2)) -> 10
AC3: =IFERROR(INDEX('Veri Merkezi'!$B$2:$B$1001,MATCH(0,INDEX(COUNTIF($AC$1:AC2,'Veri Merkezi'!$B$2:$B$1001)+('Veri Merkezi'!$B$2:$B$1001=""),0),0)),"") -> FRANSA | AD3: =IF(AC3="","",COUNTIF('Veri Merkezi'!$B$2:$B$1001,AC3)) -> 7
A4: TOPLAM OYUNCU | D4: YEŞİL | G4: SARI | J4: KIRMIZI | M4: ORT. YAŞ | P4: ≤12 AY SÖZLEŞME | AC4: =IFERROR(INDEX('Veri Merkezi'!$B$2:$B$1001,MATCH(0,INDEX(COUNTIF($AC$1:AC3,'Veri Merkezi'!$B$2:$B$1001)+('Veri Merkezi'!$B$2:$B$1001=""),0),0)),"") -> BREZİLYA | AD4: =IF(AC4="","",COUNTIF('Veri Merkezi'!$B$2:$B$1001,AC4)) -> 34
A5: =COUNTA(Kaleciler!$A$4:$A$103)+COUNTA(Stoperler!$A$4:$A$103)+COUNTA('Sağ Bekler'!$A$4:$A$103)+COUNTA('Sol Bekler'!$A$4:$A$103)+COUNTA('6 Numaralar'!$A$4:$A$103)+COUNTA('8 Numaralar'!$A$4:$A$103)+COUNTA('10 Numaralar'!$A$4:$A$103)+COUNTA(Kanatlar!$A$4:$A$103)+COUNTA(Forvetler!$A$4:$A$103)+COUNTA('Takip Edilen Türk Futbolcular'!$A$4:$A$103) -> 251 | D5: =COUNTIF(Kaleciler!$I$4:$I$103,"Yeşil")+COUNTIF(Stoperler!$H$4:$I$103,"Yeşil")+COUNTIF('Sağ Bekler'!$I$4:$I$103,"Yeşil")+COUNTIF('Sol Bekler'!$I$4:$I$103,"Yeşil")+COUNTIF('6 Numaralar'!$I$4:$I$103,"Yeşil")+COUNTIF('8 Numaralar'!$I$4:$I$103,"Yeşil")+COUNTIF('10 Numaralar'!$I$4:$I$103,"Yeşil")+COUNTIF(Kanatlar!$I$4:$I$103,"Yeşil")+COUNTIF(Forvetler!$I$4:$I$103,"Yeşil")+COUNTIF('Takip Edilen Türk Futbolcular'!$H$4:$H$103,"Yeşil") -> 35 | G5: =COUNTIF(Kaleciler!$I$4:$I$103,"Sarı")+COUNTIF(Stoperler!$H$4:$I$103,"Sarı")+COUNTIF('Sağ Bekler'!$I$4:$I$103,"Sarı")+COUNTIF('Sol Bekler'!$I$4:$I$103,"Sarı")+COUNTIF('6 Numaralar'!$I$4:$I$103,"Sarı")+COUNTIF('8 Numaralar'!$I$4:$I$103,"Sarı")+COUNTIF('10 Numaralar'!$I$4:$I$103,"Sarı")+COUNTIF(Kanatlar!$I$4:$I$103,"Sarı")+COUNTIF(Forvetler!$I$4:$I$103,"Sarı")+COUNTIF('Takip Edilen Türk Futbolcular'!$H$4:$H$103,"Sarı") -> 42 | J5: =COUNTIF(Kaleciler!$I$4:$I$103,"Kırmızı")+COUNTIF(Stoperler!$H$4:$I$103,"Kırmızı")+COUNTIF('Sağ Bekler'!$I$4:$I$103,"Kırmızı")+COUNTIF('Sol Bekler'!$I$4:$I$103,"Kırmızı")+COUNTIF('6 Numaralar'!$I$4:$I$103,"Kırmızı")+COUNTIF('8 Numaralar'!$I$4:$I$103,"Kırmızı")+COUNTIF('10 Numaralar'!$I$4:$I$103,"Kırmızı")+COUNTIF(Kanatlar!$I$4:$I$103,"Kırmızı")+COUNTIF(Forvetler!$I$4:$I$103,"Kırmızı")+COUNTIF('Takip Edilen Türk Futbolcular'!$H$4:$H$103,"Kırmızı") -> 33 | M5: =IFERROR(ROUND((SUM(Kaleciler!$D$4:$D$103)+SUM(Stoperler!$D$4:$D$103)+SUM('Sağ Bekler'!$D$4:$D$103)+SUM('Sol Bekler'!$D$4:$D$103)+SUM('6 Numaralar'!$D$4:$D$103)+SUM('8 Numaralar'!$D$4:$D$103)+SUM('10 Numaralar'!$D$4:$D$103)+SUM(Kanatlar!$D$4:$D$103)+SUM(Forvetler!$D$4:$D$103)+SUM('Takip Edilen Türk Futbolcular'!$D$4:$D$103))/(COUNTIF(Kaleciler!$D$4:$D$103,">0")+COUNTIF(Stoperler!$D$4:$D$103,">0")+COUNTIF('Sağ Bekler'!$D$4:$D$103,">0")+COUNTIF('Sol Bekler'!$D$4:$D$103,">0")+COUNTIF('6 Numaralar'!$D$4:$D$103,">0")+COUNTIF('8 Numaralar'!$D$4:$D$103,">0")+COUNTIF('10 Numaralar'!$D$4:$D$103,">0")+COUNTIF(Kanatlar!$D$4:$D$103,">0")+COUNTIF(Forvetler!$D$4:$D$103,">0")+COUNTIF('Takip Edilen Türk Futbolcular'!$D$4:$D$103,">0")),1),0) -> 25.5 | P5: =COUNTIFS(Kaleciler!$H$4:$H$103,">="&TODAY(),Kaleciler!$H$4:$H$103,"<="&EDATE(TODAY(),12))+COUNTIFS(Stoperler!$G$4:$H$103,">="&TODAY(),Stoperler!$G$4:$H$103,"<="&EDATE(TODAY(),12))+COUNTIFS('Sağ Bekler'!$H$4:$H$103,">="&TODAY(),'Sağ Bekler'!$H$4:$H$103,"<="&EDATE(TODAY(),12))+COUNTIFS('Sol Bekler'!$H$4:$H$103,">="&TODAY(),'Sol Bekler'!$H$4:$H$103,"<="&EDATE(TODAY(),12))+COUNTIFS('6 Numaralar'!$H$4:$H$103,">="&TODAY(),'6 Numaralar'!$H$4:$H$103,"<="&EDATE(TODAY(),12))+COUNTIFS('8 Numaralar'!$H$4:$H$103,">="&TODAY(),'8 Numaralar'!$H$4:$H$103,"<="&EDATE(TODAY(),12))+COUNTIFS('10 Numaralar'!$H$4:$H$103,">="&TODAY(),'10 Numaralar'!$H$4:$H$103,"<="&EDATE(TODAY(),12))+COUNTIFS(Kanatlar!$H$4:$H$103,">="&TODAY(),Kanatlar!$H$4:$H$103,"<="&EDATE(TODAY(),12))+COUNTIFS(Forvetler!$H$4:$H$103,">="&TODAY(),Forvetler!$H$4:$H$103,"<="&EDATE(TODAY(),12))+COUNTIFS('Takip Edilen Türk Futbolcular'!$G$4:$G$103,">="&TODAY(),'Takip Edilen Türk Futbolcular'!$G$4:$G$103,"<="&EDATE(TODAY(),12)) -> 57 | AC5: =IFERROR(INDEX('Veri Merkezi'!$B$2:$B$1001,MATCH(0,INDEX(COUNTIF($AC$1:AC4,'Veri Merkezi'!$B$2:$B$1001)+('Veri Merkezi'!$B$2:$B$1001=""),0),0)),"") -> SIRBİSTAN | AD5: =IF(AC5="","",COUNTIF('Veri Merkezi'!$B$2:$B$1001,AC5)) -> 6
A6: İZLENEN OYUNCU SAYISI | D6: BEĞENİLEN | G6: TEKRAR DEĞERLENDİR | J6: BEĞENİLMEDİ | M6: İZLENEN OYUNCULARIN YAŞ ORTALAMASI | AC6: =IFERROR(INDEX('Veri Merkezi'!$B$2:$B$1001,MATCH(0,INDEX(COUNTIF($AC$1:AC5,'Veri Merkezi'!$B$2:$B$1001)+('Veri Merkezi'!$B$2:$B$1001=""),0),0)),"") -> GANA | AD6: =IF(AC6="","",COUNTIF('Veri Merkezi'!$B$2:$B$1001,AC6)) -> 4
P7: SÖZLEŞMESİ BİTEN | AC7: =IFERROR(INDEX('Veri Merkezi'!$B$2:$B$1001,MATCH(0,INDEX(COUNTIF($AC$1:AC6,'Veri Merkezi'!$B$2:$B$1001)+('Veri Merkezi'!$B$2:$B$1001=""),0),0)),"") -> CEZAYİR | AD7: =IF(AC7="","",COUNTIF('Veri Merkezi'!$B$2:$B$1001,AC7)) -> 2
AC8: =IFERROR(INDEX('Veri Merkezi'!$B$2:$B$1001,MATCH(0,INDEX(COUNTIF($AC$1:AC7,'Veri Merkezi'!$B$2:$B$1001)+('Veri Merkezi'!$B$2:$B$1001=""),0),0)),"") -> KONGO | AD8: =IF(AC8="","",COUNTIF('Veri Merkezi'!$B$2:$B$1001,AC8)) -> 1
A9: A LİSTE | E9: B LİSTE | I9: TAKİP | M9: 2003+ KONTENJAN | AC9: =IFERROR(INDEX('Veri Merkezi'!$B$2:$B$1001,MATCH(0,INDEX(COUNTIF($AC$1:AC8,'Veri Merkezi'!$B$2:$B$1001)+('Veri Merkezi'!$B$2:$B$1001=""),0),0)),"") -> BURKINA FASO | AD9: =IF(AC9="","",COUNTIF('Veri Merkezi'!$B$2:$B$1001,AC9)) -> 1
A10: =COUNTIFS('Veri Merkezi'!$A$2:$A$1001,"<>",'Veri Merkezi'!$S$2:$S$1001,"A Liste") -> 19 | E10: =COUNTIFS('Veri Merkezi'!$A$2:$A$1001,"<>",'Veri Merkezi'!$S$2:$S$1001,"B Liste") -> 23 | I10: =COUNTIFS('Veri Merkezi'!$A$2:$A$1001,"<>",'Veri Merkezi'!$S$2:$S$1001,"Takip") -> 23 | M10: =COUNTIFS('Veri Merkezi'!$A$2:$A$1001,"<>",'Veri Merkezi'!$C$2:$C$1001,">="&DATE(2003,1,1)) -> 77 | AC10: =IFERROR(INDEX('Veri Merkezi'!$B$2:$B$1001,MATCH(0,INDEX(COUNTIF($AC$1:AC9,'Veri Merkezi'!$B$2:$B$1001)+('Veri Merkezi'!$B$2:$B$1001=""),0),0)),"") -> HIRVATİSTAN | AD10: =IF(AC10="","",COUNTIF('Veri Merkezi'!$B$2:$B$1001,AC10)) -> 5
AC11: =IFERROR(INDEX('Veri Merkezi'!$B$2:$B$1001,MATCH(0,INDEX(COUNTIF($AC$1:AC10,'Veri Merkezi'!$B$2:$B$1001)+('Veri Merkezi'!$B$2:$B$1001=""),0),0)),"") -> İSPANYA | AD11: =IF(AC11="","",COUNTIF('Veri Merkezi'!$B$2:$B$1001,AC11)) -> 9
AC12: =IFERROR(INDEX('Veri Merkezi'!$B$2:$B$1001,MATCH(0,INDEX(COUNTIF($AC$1:AC11,'Veri Merkezi'!$B$2:$B$1001)+('Veri Merkezi'!$B$2:$B$1001=""),0),0)),"") -> ENDONEZYA | AD12: =IF(AC12="","",COUNTIF('Veri Merkezi'!$B$2:$B$1001,AC12)) -> 1
A13: KADRONUN YAPISI | POZİSYON & YAŞ | AC13: =IFERROR(INDEX('Veri Merkezi'!$B$2:$B$1001,MATCH(0,INDEX(COUNTIF($AC$1:AC12,'Veri Merkezi'!$B$2:$B$1001)+('Veri Merkezi'!$B$2:$B$1001=""),0),0)),"") -> BOSNA | AD13: =IF(AC13="","",COUNTIF('Veri Merkezi'!$B$2:$B$1001,AC13)) -> 1
AC14: =IFERROR(INDEX('Veri Merkezi'!$B$2:$B$1001,MATCH(0,INDEX(COUNTIF($AC$1:AC13,'Veri Merkezi'!$B$2:$B$1001)+('Veri Merkezi'!$B$2:$B$1001=""),0),0)),"") -> ROMANYA | AD14: =IF(AC14="","",COUNTIF('Veri Merkezi'!$B$2:$B$1001,AC14)) -> 3
AC15: =IFERROR(INDEX('Veri Merkezi'!$B$2:$B$1001,MATCH(0,INDEX(COUNTIF($AC$1:AC14,'Veri Merkezi'!$B$2:$B$1001)+('Veri Merkezi'!$B$2:$B$1001=""),0),0)),"") -> PORTEKİZ | AD15: =IF(AC15="","",COUNTIF('Veri Merkezi'!$B$2:$B$1001,AC15)) -> 6
A16: Ana Pozisyon | B16: Oyuncu | C16: Pay % | E16: SCOUTING FUNNEL | F16: Oyuncu | AC16: =IFERROR(INDEX('Veri Merkezi'!$B$2:$B$1001,MATCH(0,INDEX(COUNTIF($AC$1:AC15,'Veri Merkezi'!$B$2:$B$1001)+('Veri Merkezi'!$B$2:$B$1001=""),0),0)),"") -> HOLLANDA | AD16: =IF(AC16="","",COUNTIF('Veri Merkezi'!$B$2:$B$1001,AC16)) -> 3
A17: Kaleci | B17: =COUNTIF(Kaleciler!$A$4:$A$103,"<>") -> 0 | C17: =IFERROR(B17/$A$5,0) -> 0 | E17: Toplam Havuz | F17: =COUNTA(Kaleciler!$A$4:$A$103)+COUNTA(Stoperler!$A$4:$A$103)+COUNTA('Sağ Bekler'!$A$4:$A$103)+COUNTA('Sol Bekler'!$A$4:$A$103)+COUNTA('6 Numaralar'!$A$4:$A$103)+COUNTA('8 Numaralar'!$A$4:$A$103)+COUNTA('10 Numaralar'!$A$4:$A$103)+COUNTA(Kanatlar!$A$4:$A$103)+COUNTA(Forvetler!$A$4:$A$103)+COUNTA('Takip Edilen Türk Futbolcular'!$A$4:$A$103) -> 251 | S17: ≤20 | AC17: =IFERROR(INDEX('Veri Merkezi'!$B$2:$B$1001,MATCH(0,INDEX(COUNTIF($AC$1:AC16,'Veri Merkezi'!$B$2:$B$1001)+('Veri Merkezi'!$B$2:$B$1001=""),0),0)),"") -> ARNAVUTLUK | AD17: =IF(AC17="","",COUNTIF('Veri Merkezi'!$B$2:$B$1001,AC17)) -> 3
A18: Stoper | B18: =COUNTIF(Stoperler!$A$4:$A$103,"<>") -> 30 | C18: =IFERROR(B18/$A$5,0) -> 0.11952191 | E18: Takip + | F18: =COUNTIF(Kaleciler!$T$4:$T$103,"Takip")+COUNTIF(Stoperler!$S$4:$T$103,"Takip")+COUNTIF('Sağ Bekler'!$T$4:$T$103,"Takip")+COUNTIF('Sol Bekler'!$T$4:$T$103,"Takip")+COUNTIF('6 Numaralar'!$T$4:$T$103,"Takip")+COUNTIF('8 Numaralar'!$T$4:$T$103,"Takip")+COUNTIF('10 Numaralar'!$T$4:$T$103,"Takip")+COUNTIF(Kanatlar!$T$4:$T$103,"Takip")+COUNTIF(Forvetler!$T$4:$T$103,"Takip")+COUNTIF('Takip Edilen Türk Futbolcular'!$S$4:$S$103,"Takip")+COUNTIF(Kaleciler!$T$4:$T$103,"B Liste")+COUNTIF(Stoperler!$S$4:$T$103,"B Liste")+COUNTIF('Sağ Bekler'!$T$4:$T$103,"B Liste")+COUNTIF('Sol Bekler'!$T$4:$T$103,"B Liste")+COUNTIF('6 Numaralar'!$T$4:$T$103,"B Liste")+COUNTIF('8 Numaralar'!$T$4:$T$103,"B Liste")+COUNTIF('10 Numaralar'!$T$4:$T$103,"B Liste")+COUNTIF(Kanatlar!$T$4:$T$103,"B Liste")+COUNTIF(Forvetler!$T$4:$T$103,"B Liste")+COUNTIF('Takip Edilen Türk Futbolcular'!$S$4:$S$103,"B Liste")+COUNTIF(Kaleciler!$T$4:$T$103,"A Liste")+COUNTIF(Stoperler!$S$4:$T$103,"A Liste")+COUNTIF('Sağ Bekler'!$T$4:$T$103,"A Liste")+COUNTIF('Sol Bekler'!$T$4:$T$103,"A Liste")+COUNTIF('6 Numaralar'!$T$4:$T$103,"A Liste")+COUNTIF('8 Numaralar'!$T$4:$T$103,"A Liste")+COUNTIF('10 Numaralar'!$T$4:$T$103,"A Liste")+COUNTIF(Kanatlar!$T$4:$T$103,"A Liste")+COUNTIF(Forvetler!$T$4:$T$103,"A Liste")+COUNTIF('Takip Edilen Türk Futbolcular'!$S$4:$S$103,"A Liste") -> 65 | S18: 21-23 | AC18: =IFERROR(INDEX('Veri Merkezi'!$B$2:$B$1001,MATCH(0,INDEX(COUNTIF($AC$1:AC17,'Veri Merkezi'!$B$2:$B$1001)+('Veri Merkezi'!$B$2:$B$1001=""),0),0)),"") -> MALİ / FRANSA | AD18: =IF(AC18="","",COUNTIF('Veri Merkezi'!$B$2:$B$1001,AC18)) -> 1
A19: Bek | B19: =COUNTIF('Sağ Bekler'!$A$4:$A$103,"<>")+COUNTIF('Sol Bekler'!$A$4:$A$103,"<>") -> 14 | C19: =IFERROR(B19/$A$5,0) -> 0.055776892 | E19: B Liste + | F19: =COUNTIF(Kaleciler!$T$4:$T$103,"B Liste")+COUNTIF(Stoperler!$S$4:$T$103,"B Liste")+COUNTIF('Sağ Bekler'!$T$4:$T$103,"B Liste")+COUNTIF('Sol Bekler'!$T$4:$T$103,"B Liste")+COUNTIF('6 Numaralar'!$T$4:$T$103,"B Liste")+COUNTIF('8 Numaralar'!$T$4:$T$103,"B Liste")+COUNTIF('10 Numaralar'!$T$4:$T$103,"B Liste")+COUNTIF(Kanatlar!$T$4:$T$103,"B Liste")+COUNTIF(Forvetler!$T$4:$T$103,"B Liste")+COUNTIF('Takip Edilen Türk Futbolcular'!$S$4:$S$103,"B Liste")+COUNTIF(Kaleciler!$T$4:$T$103,"A Liste")+COUNTIF(Stoperler!$S$4:$T$103,"A Liste")+COUNTIF('Sağ Bekler'!$T$4:$T$103,"A Liste")+COUNTIF('Sol Bekler'!$T$4:$T$103,"A Liste")+COUNTIF('6 Numaralar'!$T$4:$T$103,"A Liste")+COUNTIF('8 Numaralar'!$T$4:$T$103,"A Liste")+COUNTIF('10 Numaralar'!$T$4:$T$103,"A Liste")+COUNTIF(Kanatlar!$T$4:$T$103,"A Liste")+COUNTIF(Forvetler!$T$4:$T$103,"A Liste")+COUNTIF('Takip Edilen Türk Futbolcular'!$S$4:$S$103,"A Liste") -> 42 | S19: 24-26 | AC19: =IFERROR(INDEX('Veri Merkezi'!$B$2:$B$1001,MATCH(0,INDEX(COUNTIF($AC$1:AC18,'Veri Merkezi'!$B$2:$B$1001)+('Veri Merkezi'!$B$2:$B$1001=""),0),0)),"") -> VENEZULLA | AD19: =IF(AC19="","",COUNTIF('Veri Merkezi'!$B$2:$B$1001,AC19)) -> 1
A20: Orta Saha | B20: =COUNTIF('6 Numaralar'!$A$4:$A$103,"<>")+COUNTIF('8 Numaralar'!$A$4:$A$103,"<>")+COUNTIF('10 Numaralar'!$A$4:$A$103,"<>") -> 72 | C20: =IFERROR(B20/$A$5,0) -> 0.28685259 | S20: 27-29 | AC20: =IFERROR(INDEX('Veri Merkezi'!$B$2:$B$1001,MATCH(0,INDEX(COUNTIF($AC$1:AC19,'Veri Merkezi'!$B$2:$B$1001)+('Veri Merkezi'!$B$2:$B$1001=""),0),0)),"") -> CURAÇAO / HOLLANDA | AD20: =IF(AC20="","",COUNTIF('Veri Merkezi'!$B$2:$B$1001,AC20)) -> 1
A21: Kanat | B21: =COUNTIF(Kanatlar!$A$4:$A$103,"<>") -> 97 | C21: =IFERROR(B21/$A$5,0) -> 0.38645418 | E21: Karar | F21: Pay % | S21: 30+ | AC21: =IFERROR(INDEX('Veri Merkezi'!$B$2:$B$1001,MATCH(0,INDEX(COUNTIF($AC$1:AC20,'Veri Merkezi'!$B$2:$B$1001)+('Veri Merkezi'!$B$2:$B$1001=""),0),0)),"") -> BURKİNA FASO | AD21: =IF(AC21="","",COUNTIF('Veri Merkezi'!$B$2:$B$1001,AC21)) -> 2
A22: Forvet | B22: =COUNTIF(Forvetler!$A$4:$A$103,"<>") -> 38 | C22: =IFERROR(B22/$A$5,0) -> 0.15139442 | E22: A Liste | F22: =IFERROR((COUNTIF(Kaleciler!$T$4:$T$103,"A Liste")+COUNTIF(Stoperler!$S$4:$T$103,"A Liste")+COUNTIF('Sağ Bekler'!$T$4:$T$103,"A Liste")+COUNTIF('Sol Bekler'!$T$4:$T$103,"A Liste")+COUNTIF('6 Numaralar'!$T$4:$T$103,"A Liste")+COUNTIF('8 Numaralar'!$T$4:$T$103,"A Liste")+COUNTIF('10 Numaralar'!$T$4:$T$103,"A Liste")+COUNTIF(Kanatlar!$T$4:$T$103,"A Liste")+COUNTIF(Forvetler!$T$4:$T$103,"A Liste")+COUNTIF('Takip Edilen Türk Futbolcular'!$S$4:$S$103,"A Liste"))/$A$5,0) -> 0.075697211 | AC22: =IFERROR(INDEX('Veri Merkezi'!$B$2:$B$1001,MATCH(0,INDEX(COUNTIF($AC$1:AC21,'Veri Merkezi'!$B$2:$B$1001)+('Veri Merkezi'!$B$2:$B$1001=""),0),0)),"") -> DANİMARKA | AD22: =IF(AC22="","",COUNTIF('Veri Merkezi'!$B$2:$B$1001,AC22)) -> 1
E23: B Liste | F23: =IFERROR((COUNTIF(Kaleciler!$T$4:$T$103,"B Liste")+COUNTIF(Stoperler!$S$4:$T$103,"B Liste")+COUNTIF('Sağ Bekler'!$T$4:$T$103,"B Liste")+COUNTIF('Sol Bekler'!$T$4:$T$103,"B Liste")+COUNTIF('6 Numaralar'!$T$4:$T$103,"B Liste")+COUNTIF('8 Numaralar'!$T$4:$T$103,"B Liste")+COUNTIF('10 Numaralar'!$T$4:$T$103,"B Liste")+COUNTIF(Kanatlar!$T$4:$T$103,"B Liste")+COUNTIF(Forvetler!$T$4:$T$103,"B Liste")+COUNTIF('Takip Edilen Türk Futbolcular'!$S$4:$S$103,"B Liste"))/$A$5,0) -> 0.091633466 | AC23: =IFERROR(INDEX('Veri Merkezi'!$B$2:$B$1001,MATCH(0,INDEX(COUNTIF($AC$1:AC22,'Veri Merkezi'!$B$2:$B$1001)+('Veri Merkezi'!$B$2:$B$1001=""),0),0)),"") -> İSVİÇRE | AD23: =IF(AC23="","",COUNTIF('Veri Merkezi'!$B$2:$B$1001,AC23)) -> 2
E24: Takip | F24: =IFERROR((COUNTIF(Kaleciler!$T$4:$T$103,"Takip")+COUNTIF(Stoperler!$S$4:$T$103,"Takip")+COUNTIF('Sağ Bekler'!$T$4:$T$103,"Takip")+COUNTIF('Sol Bekler'!$T$4:$T$103,"Takip")+COUNTIF('6 Numaralar'!$T$4:$T$103,"Takip")+COUNTIF('8 Numaralar'!$T$4:$T$103,"Takip")+COUNTIF('10 Numaralar'!$T$4:$T$103,"Takip")+COUNTIF(Kanatlar!$T$4:$T$103,"Takip")+COUNTIF(Forvetler!$T$4:$T$103,"Takip")+COUNTIF('Takip Edilen Türk Futbolcular'!$S$4:$S$103,"Takip"))/$A$5,0) -> 0.091633466 | AC24: =IFERROR(INDEX('Veri Merkezi'!$B$2:$B$1001,MATCH(0,INDEX(COUNTIF($AC$1:AC23,'Veri Merkezi'!$B$2:$B$1001)+('Veri Merkezi'!$B$2:$B$1001=""),0),0)),"") -> MALİ | AD24: =IF(AC24="","",COUNTIF('Veri Merkezi'!$B$2:$B$1001,AC24)) -> 2
E25: Tekrar İzle | F25: =IFERROR((COUNTIF(Kaleciler!$T$4:$T$103,"Tekrar İzle")+COUNTIF(Stoperler!$S$4:$T$103,"Tekrar İzle")+COUNTIF('Sağ Bekler'!$T$4:$T$103,"Tekrar İzle")+COUNTIF('Sol Bekler'!$T$4:$T$103,"Tekrar İzle")+COUNTIF('6 Numaralar'!$T$4:$T$103,"Tekrar İzle")+COUNTIF('8 Numaralar'!$T$4:$T$103,"Tekrar İzle")+COUNTIF('10 Numaralar'!$T$4:$T$103,"Tekrar İzle")+COUNTIF(Kanatlar!$T$4:$T$103,"Tekrar İzle")+COUNTIF(Forvetler!$T$4:$T$103,"Tekrar İzle")+COUNTIF('Takip Edilen Türk Futbolcular'!$S$4:$S$103,"Tekrar İzle"))/$A$5,0) -> 0.055776892 | AC25: =IFERROR(INDEX('Veri Merkezi'!$B$2:$B$1001,MATCH(0,INDEX(COUNTIF($AC$1:AC24,'Veri Merkezi'!$B$2:$B$1001)+('Veri Merkezi'!$B$2:$B$1001=""),0),0)),"") -> KOLOMBİYA | AD25: =IF(AC25="","",COUNTIF('Veri Merkezi'!$B$2:$B$1001,AC25)) -> 3
E26: Ele | F26: =IFERROR((COUNTIF(Kaleciler!$T$4:$T$103,"Ele")+COUNTIF(Stoperler!$S$4:$T$103,"Ele")+COUNTIF('Sağ Bekler'!$T$4:$T$103,"Ele")+COUNTIF('Sol Bekler'!$T$4:$T$103,"Ele")+COUNTIF('6 Numaralar'!$T$4:$T$103,"Ele")+COUNTIF('8 Numaralar'!$T$4:$T$103,"Ele")+COUNTIF('10 Numaralar'!$T$4:$T$103,"Ele")+COUNTIF(Kanatlar!$T$4:$T$103,"Ele")+COUNTIF(Forvetler!$T$4:$T$103,"Ele")+COUNTIF('Takip Edilen Türk Futbolcular'!$S$4:$S$103,"Ele"))/$A$5,0) -> 0.12350598 | AC26: =IFERROR(INDEX('Veri Merkezi'!$B$2:$B$1001,MATCH(0,INDEX(COUNTIF($AC$1:AC25,'Veri Merkezi'!$B$2:$B$1001)+('Veri Merkezi'!$B$2:$B$1001=""),0),0)),"") -> SURİYE | AD26: =IF(AC26="","",COUNTIF('Veri Merkezi'!$B$2:$B$1001,AC26)) -> 1
AC27: =IFERROR(INDEX('Veri Merkezi'!$B$2:$B$1001,MATCH(0,INDEX(COUNTIF($AC$1:AC26,'Veri Merkezi'!$B$2:$B$1001)+('Veri Merkezi'!$B$2:$B$1001=""),0),0)),"") -> AVUSTURYA | AD27: =IF(AC27="","",COUNTIF('Veri Merkezi'!$B$2:$B$1001,AC27)) -> 3
A28: TRANSFER ÖNCELİKLERİ | N28: SÖZLEŞME / KONTENJAN RİSKLERİ | AC28: =IFERROR(INDEX('Veri Merkezi'!$B$2:$B$1001,MATCH(0,INDEX(COUNTIF($AC$1:AC27,'Veri Merkezi'!$B$2:$B$1001)+('Veri Merkezi'!$B$2:$B$1001=""),0),0)),"") -> EKVADOR | AD28: =IF(AC28="","",COUNTIF('Veri Merkezi'!$B$2:$B$1001,AC28)) -> 3
A29: TOPLAM HAVUZ | D29: TAKİP | G29: B LİSTE | J29: A LİSTE | N29: ≤12 AY SÖZLEŞME | Q29: 2003+ | AC29: =IFERROR(INDEX('Veri Merkezi'!$B$2:$B$1001,MATCH(0,INDEX(COUNTIF($AC$1:AC28,'Veri Merkezi'!$B$2:$B$1001)+('Veri Merkezi'!$B$2:$B$1001=""),0),0)),"") -> ARNAVUTLUK / BELÇİKA | AD29: =IF(AC29="","",COUNTIF('Veri Merkezi'!$B$2:$B$1001,AC29)) -> 1
AC30: =IFERROR(INDEX('Veri Merkezi'!$B$2:$B$1001,MATCH(0,INDEX(COUNTIF($AC$1:AC29,'Veri Merkezi'!$B$2:$B$1001)+('Veri Merkezi'!$B$2:$B$1001=""),0),0)),"") -> MACARİSTAN | AD30: =IF(AC30="","",COUNTIF('Veri Merkezi'!$B$2:$B$1001,AC30)) -> 2
AC31: =IFERROR(INDEX('Veri Merkezi'!$B$2:$B$1001,MATCH(0,INDEX(COUNTIF($AC$1:AC30,'Veri Merkezi'!$B$2:$B$1001)+('Veri Merkezi'!$B$2:$B$1001=""),0),0)),"") -> KANADA | AD31: =IF(AC31="","",COUNTIF('Veri Merkezi'!$B$2:$B$1001,AC31)) -> 1
A32: A LİSTE | İLK 8 TRANSFER ÖNCELİĞİ | G32: B LİSTE | İLK 8 TRANSFER ÖNCELİĞİ | N32: ≤12 AY | SÖZLEŞMESİ BİTENLER | AC32: =IFERROR(INDEX('Veri Merkezi'!$B$2:$B$1001,MATCH(0,INDEX(COUNTIF($AC$1:AC31,'Veri Merkezi'!$B$2:$B$1001)+('Veri Merkezi'!$B$2:$B$1001=""),0),0)),"") -> SENEGAL | AD32: =IF(AC32="","",COUNTIF('Veri Merkezi'!$B$2:$B$1001,AC32)) -> 5
A33: Oyuncu | B33: Mevki | C33: Kulüp | D33: Scout Skoru | E33: Durum | F33: Karar | G33: Oyuncu | H33: Mevki | I33: Kulüp | J33: Scout Skoru | K33: Durum | L33: Karar | N33: Oyuncu | O33: Mevki | P33: Kulüp | Q33: Sözleşme | R33: Kalan Gün | AC33: =IFERROR(INDEX('Veri Merkezi'!$B$2:$B$1001,MATCH(0,INDEX(COUNTIF($AC$1:AC32,'Veri Merkezi'!$B$2:$B$1001)+('Veri Merkezi'!$B$2:$B$1001=""),0),0)),"") -> PARAGUAY | AD33: =IF(AC33="","",COUNTIF('Veri Merkezi'!$B$2:$B$1001,AC33)) -> 2
A34: =IF('A Liste'!$A4="","",'A Liste'!$A4) -> TUNGAY NIANZOU | B34: =IF('A Liste'!$B4="","",'A Liste'!$B4) -> Stoper | C34: =IF('A Liste'!$D4="","",'A Liste'!$D4) -> LILLE | D34: =IF('A Liste'!$G4="","",'A Liste'!$G4) | E34: =IF('A Liste'!$F4="","",'A Liste'!$F4) -> Yeşil | F34: =IF('A Liste'!$H4="","",'A Liste'!$H4) -> A Liste | G34: =IF('B Liste'!$A4="","",'B Liste'!$A4) -> FEDERICO GOTTONI | H34: =IF('B Liste'!$A4="","",'B Liste'!$B4) -> Stoper | I34: =IF('B Liste'!$A4="","",'B Liste'!$D4) -> ASCOLI | J34: =IF('B Liste'!$A4="","",'B Liste'!$G4) | K34: =IF('B Liste'!$A4="","",'B Liste'!$F4) -> Sarı | L34: =IF('B Liste'!$A4="","",'B Liste'!$H4) -> B Liste | N34: =IF('Sözleşmesi Bitenler'!$B4="","",'Sözleşmesi Bitenler'!$B4) -> WELLITON | O34: =IF('Sözleşmesi Bitenler'!$B4="","",'Sözleşmesi Bitenler'!$C4) -> Kanat | P34: =IF('Sözleşmesi Bitenler'!$B4="","",'Sözleşmesi Bitenler'!$E4) -> FORTALEZA | Q34: =IF('Sözleşmesi Bitenler'!$B4="","",'Sözleşmesi Bitenler'!$F4) -> 46356 | R34: =IF('Sözleşmesi Bitenler'!$B4="","",'Sözleşmesi Bitenler'!$G4) -> 55 | AC34: =IFERROR(INDEX('Veri Merkezi'!$B$2:$B$1001,MATCH(0,INDEX(COUNTIF($AC$1:AC33,'Veri Merkezi'!$B$2:$B$1001)+('Veri Merkezi'!$B$2:$B$1001=""),0),0)),"") -> BELÇİKA | AD34: =IF(AC34="","",COUNTIF('Veri Merkezi'!$B$2:$B$1001,AC34)) -> 7
A35: =IF('A Liste'!$A5="","",'A Liste'!$A5) -> ARTHUR ZAGRE | B35: =IF('A Liste'!$B5="","",'A Liste'!$B5) -> Sol Bek | C35: =IF('A Liste'!$D5="","",'A Liste'!$D5) -> UTRECHT | D35: =IF('A Liste'!$G5="","",'A Liste'!$G5) | E35: =IF('A Liste'!$F5="","",'A Liste'!$F5) -> Yeşil | F35: =IF('A Liste'!$H5="","",'A Liste'!$H5) -> A Liste | G35: =IF('B Liste'!$A5="","",'B Liste'!$A5) -> MİLOS VELJKOVİC | H35: =IF('B Liste'!$A5="","",'B Liste'!$B5) -> Stoper | I35: =IF('B Liste'!$A5="","",'B Liste'!$D5) -> KIZILYILDIZ | J35: =IF('B Liste'!$A5="","",'B Liste'!$G5) | K35: =IF('B Liste'!$A5="","",'B Liste'!$F5) -> Sarı | L35: =IF('B Liste'!$A5="","",'B Liste'!$H5) -> B Liste | N35: =IF('Sözleşmesi Bitenler'!$B5="","",'Sözleşmesi Bitenler'!$B5) -> FILIP AKDEMIR | O35: =IF('Sözleşmesi Bitenler'!$B5="","",'Sözleşmesi Bitenler'!$C5) -> Forvet | P35: =IF('Sözleşmesi Bitenler'!$B5="","",'Sözleşmesi Bitenler'!$E5) -> LUNDS BK | Q35: =IF('Sözleşmesi Bitenler'!$B5="","",'Sözleşmesi Bitenler'!$F5) -> 46356 | R35: =IF('Sözleşmesi Bitenler'!$B5="","",'Sözleşmesi Bitenler'!$G5) -> 55 | AC35: =IFERROR(INDEX('Veri Merkezi'!$B$2:$B$1001,MATCH(0,INDEX(COUNTIF($AC$1:AC34,'Veri Merkezi'!$B$2:$B$1001)+('Veri Merkezi'!$B$2:$B$1001=""),0),0)),"") -> SLOVENYA | AD35: =IF(AC35="","",COUNTIF('Veri Merkezi'!$B$2:$B$1001,AC35)) -> 2
A36: =IF('A Liste'!$A6="","",'A Liste'!$A6) -> LEONARDO LELO | B36: =IF('A Liste'!$B6="","",'A Liste'!$B6) -> Sol Bek | C36: =IF('A Liste'!$D6="","",'A Liste'!$D6) -> ALMERIA | D36: =IF('A Liste'!$G6="","",'A Liste'!$G6) | E36: =IF('A Liste'!$F6="","",'A Liste'!$F6) -> Yeşil | F36: =IF('A Liste'!$H6="","",'A Liste'!$H6) -> A Liste | G36: =IF('B Liste'!$A6="","",'B Liste'!$A6) -> SOHAIB NAIR | H36: =IF('B Liste'!$A6="","",'B Liste'!$B6) -> Stoper | I36: =IF('B Liste'!$A6="","",'B Liste'!$D6) -> ST.ETTIEN | J36: =IF('B Liste'!$A6="","",'B Liste'!$G6) | K36: =IF('B Liste'!$A6="","",'B Liste'!$F6) -> Yeşil | L36: =IF('B Liste'!$A6="","",'B Liste'!$H6) -> B Liste | N36: =IF('Sözleşmesi Bitenler'!$B6="","",'Sözleşmesi Bitenler'!$B6) -> ZE IVALDO | O36: =IF('Sözleşmesi Bitenler'!$B6="","",'Sözleşmesi Bitenler'!$C6) -> Stoper | P36: =IF('Sözleşmesi Bitenler'!$B6="","",'Sözleşmesi Bitenler'!$E6) -> REMO | Q36: =IF('Sözleşmesi Bitenler'!$B6="","",'Sözleşmesi Bitenler'!$F6) -> 46387 | R36: =IF('Sözleşmesi Bitenler'!$B6="","",'Sözleşmesi Bitenler'!$G6) -> 86 | AC36: =IFERROR(INDEX('Veri Merkezi'!$B$2:$B$1001,MATCH(0,INDEX(COUNTIF($AC$1:AC35,'Veri Merkezi'!$B$2:$B$1001)+('Veri Merkezi'!$B$2:$B$1001=""),0),0)),"") -> FİNLANDİYA | AD36: =IF(AC36="","",COUNTIF('Veri Merkezi'!$B$2:$B$1001,AC36)) -> 1
A37: =IF('A Liste'!$A7="","",'A Liste'!$A7) -> RAMIZ ZERROUKI | B37: =IF('A Liste'!$B7="","",'A Liste'!$B7) -> 6 Numara | C37: =IF('A Liste'!$D7="","",'A Liste'!$D7) -> TWENTE | D37: =IF('A Liste'!$G7="","",'A Liste'!$G7) | E37: =IF('A Liste'!$F7="","",'A Liste'!$F7) -> Yeşil | F37: =IF('A Liste'!$H7="","",'A Liste'!$H7) -> A Liste | G37: =IF('B Liste'!$A7="","",'B Liste'!$A7) -> AXEL TUANZEBE | H37: =IF('B Liste'!$A7="","",'B Liste'!$B7) -> Stoper | I37: =IF('B Liste'!$A7="","",'B Liste'!$D7) -> AUXERRE | J37: =IF('B Liste'!$A7="","",'B Liste'!$G7) | K37: =IF('B Liste'!$A7="","",'B Liste'!$F7) -> Sarı | L37: =IF('B Liste'!$A7="","",'B Liste'!$H7) -> B Liste | N37: =IF('Sözleşmesi Bitenler'!$B7="","",'Sözleşmesi Bitenler'!$B7) -> PEDRO HENRIQUE | O37: =IF('Sözleşmesi Bitenler'!$B7="","",'Sözleşmesi Bitenler'!$C7) -> Stoper | P37: =IF('Sözleşmesi Bitenler'!$B7="","",'Sözleşmesi Bitenler'!$E7) -> RB BRAGANTINO | Q37: =IF('Sözleşmesi Bitenler'!$B7="","",'Sözleşmesi Bitenler'!$F7) -> 46387 | R37: =IF('Sözleşmesi Bitenler'!$B7="","",'Sözleşmesi Bitenler'!$G7) -> 86 | AC37: =IFERROR(INDEX('Veri Merkezi'!$B$2:$B$1001,MATCH(0,INDEX(COUNTIF($AC$1:AC36,'Veri Merkezi'!$B$2:$B$1001)+('Veri Merkezi'!$B$2:$B$1001=""),0),0)),"") -> GUADELOUPE | AD37: =IF(AC37="","",COUNTIF('Veri Merkezi'!$B$2:$B$1001,AC37)) -> 1
A38: =IF('A Liste'!$A8="","",'A Liste'!$A8) -> STEPHEN EUSTAQUO | B38: =IF('A Liste'!$B8="","",'A Liste'!$B8) -> 8 Numara | C38: =IF('A Liste'!$D8="","",'A Liste'!$D8) -> SWANSEA | D38: =IF('A Liste'!$G8="","",'A Liste'!$G8) | E38: =IF('A Liste'!$F8="","",'A Liste'!$F8) -> Yeşil | F38: =IF('A Liste'!$H8="","",'A Liste'!$H8) -> A Liste | G38: =IF('B Liste'!$A8="","",'B Liste'!$A8) -> DUJE CALETE-CAR | H38: =IF('B Liste'!$A8="","",'B Liste'!$B8) -> Stoper | I38: =IF('B Liste'!$A8="","",'B Liste'!$D8) -> SASSUOLO | J38: =IF('B Liste'!$A8="","",'B Liste'!$G8) | K38: =IF('B Liste'!$A8="","",'B Liste'!$F8) -> Yeşil | L38: =IF('B Liste'!$A8="","",'B Liste'!$H8) -> B Liste | N38: =IF('Sözleşmesi Bitenler'!$B8="","",'Sözleşmesi Bitenler'!$B8) -> RODRIGO INSUA | O38: =IF('Sözleşmesi Bitenler'!$B8="","",'Sözleşmesi Bitenler'!$C8) -> Sol Bek | P38: =IF('Sözleşmesi Bitenler'!$B8="","",'Sözleşmesi Bitenler'!$E8) -> BARRACAS | Q38: =IF('Sözleşmesi Bitenler'!$B8="","",'Sözleşmesi Bitenler'!$F8) -> 46387 | R38: =IF('Sözleşmesi Bitenler'!$B8="","",'Sözleşmesi Bitenler'!$G8) -> 86 | AC38: =IFERROR(INDEX('Veri Merkezi'!$B$2:$B$1001,MATCH(0,INDEX(COUNTIF($AC$1:AC37,'Veri Merkezi'!$B$2:$B$1001)+('Veri Merkezi'!$B$2:$B$1001=""),0),0)),"") -> NİJERYA | AD38: =IF(AC38="","",COUNTIF('Veri Merkezi'!$B$2:$B$1001,AC38)) -> 8
A39: =IF('A Liste'!$A9="","",'A Liste'!$A9) -> URAN BISLIMI | B39: =IF('A Liste'!$B9="","",'A Liste'!$B9) -> 8 Numara | C39: =IF('A Liste'!$D9="","",'A Liste'!$D9) -> LUGANO | D39: =IF('A Liste'!$G9="","",'A Liste'!$G9) | E39: =IF('A Liste'!$F9="","",'A Liste'!$F9) -> Yeşil | F39: =IF('A Liste'!$H9="","",'A Liste'!$H9) -> A Liste | G39: =IF('B Liste'!$A9="","",'B Liste'!$A9) -> JOAO MARCELO MESSİAS FERREIRA | H39: =IF('B Liste'!$A9="","",'B Liste'!$B9) -> Stoper | I39: =IF('B Liste'!$A9="","",'B Liste'!$D9) -> CRUZEİRO | J39: =IF('B Liste'!$A9="","",'B Liste'!$G9) | K39: =IF('B Liste'!$A9="","",'B Liste'!$F9) -> Yeşil | L39: =IF('B Liste'!$A9="","",'B Liste'!$H9) -> B Liste | N39: =IF('Sözleşmesi Bitenler'!$B9="","",'Sözleşmesi Bitenler'!$B9) -> MONCHU | O39: =IF('Sözleşmesi Bitenler'!$B9="","",'Sözleşmesi Bitenler'!$C9) -> 8 Numara | P39: =IF('Sözleşmesi Bitenler'!$B9="","",'Sözleşmesi Bitenler'!$E9) -> FC JUAREZ | Q39: =IF('Sözleşmesi Bitenler'!$B9="","",'Sözleşmesi Bitenler'!$F9) -> 46387 | R39: =IF('Sözleşmesi Bitenler'!$B9="","",'Sözleşmesi Bitenler'!$G9) -> 86 | AC39: =IFERROR(INDEX('Veri Merkezi'!$B$2:$B$1001,MATCH(0,INDEX(COUNTIF($AC$1:AC38,'Veri Merkezi'!$B$2:$B$1001)+('Veri Merkezi'!$B$2:$B$1001=""),0),0)),"") -> FAS | AD39: =IF(AC39="","",COUNTIF('Veri Merkezi'!$B$2:$B$1001,AC39)) -> 1
A40: =IF('A Liste'!$A10="","",'A Liste'!$A10) -> JEAN LUCAS DE SOUZA | B40: =IF('A Liste'!$B10="","",'A Liste'!$B10) -> 8 Numara | C40: =IF('A Liste'!$D10="","",'A Liste'!$D10) -> BAHIA | D40: =IF('A Liste'!$G10="","",'A Liste'!$G10) | E40: =IF('A Liste'!$F10="","",'A Liste'!$F10) -> Yeşil | F40: =IF('A Liste'!$H10="","",'A Liste'!$H10) -> A Liste | G40: =IF('B Liste'!$A10="","",'B Liste'!$A10) -> MUJAID SADICK | H40: =IF('B Liste'!$A10="","",'B Liste'!$B10) -> Stoper | I40: =IF('B Liste'!$A10="","",'B Liste'!$D10) -> RAYO VALLECANO | J40: =IF('B Liste'!$A10="","",'B Liste'!$G10) | K40: =IF('B Liste'!$A10="","",'B Liste'!$F10) -> Yeşil | L40: =IF('B Liste'!$A10="","",'B Liste'!$H10) -> B Liste | N40: =IF('Sözleşmesi Bitenler'!$B10="","",'Sözleşmesi Bitenler'!$B10) -> JIN-GYU KIM | O40: =IF('Sözleşmesi Bitenler'!$B10="","",'Sözleşmesi Bitenler'!$C10) -> 8 Numara | P40: =IF('Sözleşmesi Bitenler'!$B10="","",'Sözleşmesi Bitenler'!$E10) -> JEONBUK HYUNDAI | Q40: =IF('Sözleşmesi Bitenler'!$B10="","",'Sözleşmesi Bitenler'!$F10) -> 46387 | R40: =IF('Sözleşmesi Bitenler'!$B10="","",'Sözleşmesi Bitenler'!$G10) -> 86 | AC40: =IFERROR(INDEX('Veri Merkezi'!$B$2:$B$1001,MATCH(0,INDEX(COUNTIF($AC$1:AC39,'Veri Merkezi'!$B$2:$B$1001)+('Veri Merkezi'!$B$2:$B$1001=""),0),0)),"") -> GİNE | AD40: =IF(AC40="","",COUNTIF('Veri Merkezi'!$B$2:$B$1001,AC40)) -> 2
...

Sheet A Liste
A1: A LİSTE | ÖNCELİKLİ OYUNCU HAVUZU
A3: Adı Soyadı | B3: Mevki | C3: Yaş | D3: Kulübü | E3: Sözleşme | F3: Durum | G3: Scout Skoru | H3: Karar | I3: Son İzlenme | J3: Kaynak Sayfa
A4: =IF($K4="","",IFERROR(INDEX('Veri Merkezi'!$A$2:$A$1001,$K4),"")) -> TUNGAY NIANZOU | B4: =IF($K4="","",IFERROR(INDEX('Veri Merkezi'!$E$2:$E$1001,$K4),"")) -> Stoper | C4: =IF($K4="","",IFERROR(INDEX('Veri Merkezi'!$D$2:$D$1001,$K4),"")) -> 24 | D4: =IF($K4="","",IFERROR(INDEX('Veri Merkezi'!$F$2:$F$1001,$K4),"")) -> LILLE | E4: =IF($K4="","",IFERROR(INDEX('Veri Merkezi'!$G$2:$G$1001,$K4),"")) -> 46934 | F4: =IF($K4="","",IFERROR(INDEX('Veri Merkezi'!$H$2:$H$1001,$K4),"")) -> Yeşil | G4: =IF($K4="","",IFERROR(INDEX('Veri Merkezi'!$R$2:$R$1001,$K4),"")) | H4: =IF($K4="","",IFERROR(INDEX('Veri Merkezi'!$S$2:$S$1001,$K4),"")) -> A Liste | I4: =IF($K4="","",IFERROR(INDEX('Veri Merkezi'!$T$2:$T$1001,$K4),"")) | J4: =IF($K4="","",IFERROR(INDEX('Veri Merkezi'!$U$2:$U$1001,$K4),"")) -> Stoperler | K4: =IFERROR(MATCH("A Liste",'Veri Merkezi'!$S$2:$S$1001,0),"") -> 102
A5: =IF($K5="","",IFERROR(INDEX('Veri Merkezi'!$A$2:$A$1001,$K5),"")) -> ARTHUR ZAGRE | B5: =IF($K5="","",IFERROR(INDEX('Veri Merkezi'!$E$2:$E$1001,$K5),"")) -> Sol Bek | C5: =IF($K5="","",IFERROR(INDEX('Veri Merkezi'!$D$2:$D$1001,$K5),"")) -> 25 | D5: =IF($K5="","",IFERROR(INDEX('Veri Merkezi'!$F$2:$F$1001,$K5),"")) -> UTRECHT | E5: =IF($K5="","",IFERROR(INDEX('Veri Merkezi'!$G$2:$G$1001,$K5),"")) -> 47289 | F5: =IF($K5="","",IFERROR(INDEX('Veri Merkezi'!$H$2:$H$1001,$K5),"")) -> Yeşil | G5: =IF($K5="","",IFERROR(INDEX('Veri Merkezi'!$R$2:$R$1001,$K5),"")) | H5: =IF($K5="","",IFERROR(INDEX('Veri Merkezi'!$S$2:$S$1001,$K5),"")) -> A Liste | I5: =IF($K5="","",IFERROR(INDEX('Veri Merkezi'!$T$2:$T$1001,$K5),"")) | J5: =IF($K5="","",IFERROR(INDEX('Veri Merkezi'!$U$2:$U$1001,$K5),"")) -> Sol Bekler | K5: =IF(K4="","",IFERROR(K4+MATCH("A Liste",INDEX('Veri Merkezi'!$S$2:$S$1001,K4+1):'Veri Merkezi'!$S$1001,0),"")) -> 302
A6: =IF($K6="","",IFERROR(INDEX('Veri Merkezi'!$A$2:$A$1001,$K6),"")) -> LEONARDO LELO | B6: =IF($K6="","",IFERROR(INDEX('Veri Merkezi'!$E$2:$E$1001,$K6),"")) -> Sol Bek | C6: =IF($K6="","",IFERROR(INDEX('Veri Merkezi'!$D$2:$D$1001,$K6),"")) -> 26 | D6: =IF($K6="","",IFERROR(INDEX('Veri Merkezi'!$F$2:$F$1001,$K6),"")) -> ALMERIA | E6: =IF($K6="","",IFERROR(INDEX('Veri Merkezi'!$G$2:$G$1001,$K6),"")) -> 46568 | F6: =IF($K6="","",IFERROR(INDEX('Veri Merkezi'!$H$2:$H$1001,$K6),"")) -> Yeşil | G6: =IF($K6="","",IFERROR(INDEX('Veri Merkezi'!$R$2:$R$1001,$K6),"")) | H6: =IF($K6="","",IFERROR(INDEX('Veri Merkezi'!$S$2:$S$1001,$K6),"")) -> A Liste | I6: =IF($K6="","",IFERROR(INDEX('Veri Merkezi'!$T$2:$T$1001,$K6),"")) | J6: =IF($K6="","",IFERROR(INDEX('Veri Merkezi'!$U$2:$U$1001,$K6),"")) -> Sol Bekler | K6: =IF(K5="","",IFERROR(K5+MATCH("A Liste",INDEX('Veri Merkezi'!$S$2:$S$1001,K5+1):'Veri Merkezi'!$S$1001,0),"")) -> 306
A7: =IF($K7="","",IFERROR(INDEX('Veri Merkezi'!$A$2:$A$1001,$K7),"")) -> RAMIZ ZERROUKI | B7: =IF($K7="","",IFERROR(INDEX('Veri Merkezi'!$E$2:$E$1001,$K7),"")) -> 6 Numara | C7: =IF($K7="","",IFERROR(INDEX('Veri Merkezi'!$D$2:$D$1001,$K7),"")) -> 28 | D7: =IF($K7="","",IFERROR(INDEX('Veri Merkezi'!$F$2:$F$1001,$K7),"")) -> TWENTE | E7: =IF($K7="","",IFERROR(INDEX('Veri Merkezi'!$G$2:$G$1001,$K7),"")) -> 47664 | F7: =IF($K7="","",IFERROR(INDEX('Veri Merkezi'!$H$2:$H$1001,$K7),"")) -> Yeşil | G7: =IF($K7="","",IFERROR(INDEX('Veri Merkezi'!$R$2:$R$1001,$K7),"")) | H7: =IF($K7="","",IFERROR(INDEX('Veri Merkezi'!$S$2:$S$1001,$K7),"")) -> A Liste | I7: =IF($K7="","",IFERROR(INDEX('Veri Merkezi'!$T$2:$T$1001,$K7),"")) | J7: =IF($K7="","",IFERROR(INDEX('Veri Merkezi'!$U$2:$U$1001,$K7),"")) -> 6 Numaralar | K7: =IF(K6="","",IFERROR(K6+MATCH("A Liste",INDEX('Veri Merkezi'!$S$2:$S$1001,K6+1):'Veri Merkezi'!$S$1001,0),"")) -> 407
A8: =IF($K8="","",IFERROR(INDEX('Veri Merkezi'!$A$2:$A$1001,$K8),"")) -> STEPHEN EUSTAQUO | B8: =IF($K8="","",IFERROR(INDEX('Veri Merkezi'!$E$2:$E$1001,$K8),"")) -> 8 Numara | C8: =IF($K8="","",IFERROR(INDEX('Veri Merkezi'!$D$2:$D$1001,$K8),"")) -> 29 | D8: =IF($K8="","",IFERROR(INDEX('Veri Merkezi'!$F$2:$F$1001,$K8),"")) -> SWANSEA | E8: =IF($K8="","",IFERROR(INDEX('Veri Merkezi'!$G$2:$G$1001,$K8),"")) -> 46934 | F8: =IF($K8="","",IFERROR(INDEX('Veri Merkezi'!$H$2:$H$1001,$K8),"")) -> Yeşil | G8: =IF($K8="","",IFERROR(INDEX('Veri Merkezi'!$R$2:$R$1001,$K8),"")) | H8: =IF($K8="","",IFERROR(INDEX('Veri Merkezi'!$S$2:$S$1001,$K8),"")) -> A Liste | I8: =IF($K8="","",IFERROR(INDEX('Veri Merkezi'!$T$2:$T$1001,$K8),"")) | J8: =IF($K8="","",IFERROR(INDEX('Veri Merkezi'!$U$2:$U$1001,$K8),"")) -> 8 Numaralar | K8: =IF(K7="","",IFERROR(K7+MATCH("A Liste",INDEX('Veri Merkezi'!$S$2:$S$1001,K7+1):'Veri Merkezi'!$S$1001,0),"")) -> 502
A9: =IF($K9="","",IFERROR(INDEX('Veri Merkezi'!$A$2:$A$1001,$K9),"")) -> URAN BISLIMI | B9: =IF($K9="","",IFERROR(INDEX('Veri Merkezi'!$E$2:$E$1001,$K9),"")) -> 8 Numara | C9: =IF($K9="","",IFERROR(INDEX('Veri Merkezi'!$D$2:$D$1001,$K9),"")) -> 27 | D9: =IF($K9="","",IFERROR(INDEX('Veri Merkezi'!$F$2:$F$1001,$K9),"")) -> LUGANO | E9: =IF($K9="","",IFERROR(INDEX('Veri Merkezi'!$G$2:$G$1001,$K9),"")) -> 46558 | F9: =IF($K9="","",IFERROR(INDEX('Veri Merkezi'!$H$2:$H$1001,$K9),"")) -> Yeşil | G9: =IF($K9="","",IFERROR(INDEX('Veri Merkezi'!$R$2:$R$1001,$K9),"")) | H9: =IF($K9="","",IFERROR(INDEX('Veri Merkezi'!$S$2:$S$1001,$K9),"")) -> A Liste | I9: =IF($K9="","",IFERROR(INDEX('Veri Merkezi'!$T$2:$T$1001,$K9),"")) | J9: =IF($K9="","",IFERROR(INDEX('Veri Merkezi'!$U$2:$U$1001,$K9),"")) -> 8 Numaralar | K9: =IF(K8="","",IFERROR(K8+MATCH("A Liste",INDEX('Veri Merkezi'!$S$2:$S$1001,K8+1):'Veri Merkezi'!$S$1001,0),"")) -> 503
A10: =IF($K10="","",IFERROR(INDEX('Veri Merkezi'!$A$2:$A$1001,$K10),"")) -> JEAN LUCAS DE SOUZA | B10: =IF($K10="","",IFERROR(INDEX('Veri Merkezi'!$E$2:$E$1001,$K10),"")) -> 8 Numara | C10: =IF($K10="","",IFERROR(INDEX('Veri Merkezi'!$D$2:$D$1001,$K10),"")) -> 28 | D10: =IF($K10="","",IFERROR(INDEX('Veri Merkezi'!$F$2:$F$1001,$K10),"")) -> BAHIA | E10: =IF($K10="","",IFERROR(INDEX('Veri Merkezi'!$G$2:$G$1001,$K10),"")) -> 47118 | F10: =IF($K10="","",IFERROR(INDEX('Veri Merkezi'!$H$2:$H$1001,$K10),"")) -> Yeşil | G10: =IF($K10="","",IFERROR(INDEX('Veri Merkezi'!$R$2:$R$1001,$K10),"")) | H10: =IF($K10="","",IFERROR(INDEX('Veri Merkezi'!$S$2:$S$1001,$K10),"")) -> A Liste | I10: =IF($K10="","",IFERROR(INDEX('Veri Merkezi'!$T$2:$T$1001,$K10),"")) | J10: =IF($K10="","",IFERROR(INDEX('Veri Merkezi'!$U$2:$U$1001,$K10),"")) -> 8 Numaralar | K10: =IF(K9="","",IFERROR(K9+MATCH("A Liste",INDEX('Veri Merkezi'!$S$2:$S$1001,K9+1):'Veri Merkezi'!$S$1001,0),"")) -> 505
A11: =IF($K11="","",IFERROR(INDEX('Veri Merkezi'!$A$2:$A$1001,$K11),"")) -> MONCHU | B11: =IF($K11="","",IFERROR(INDEX('Veri Merkezi'!$E$2:$E$1001,$K11),"")) -> 8 Numara | C11: =IF($K11="","",IFERROR(INDEX('Veri Merkezi'!$D$2:$D$1001,$K11),"")) -> 27 | D11: =IF($K11="","",IFERROR(INDEX('Veri Merkezi'!$F$2:$F$1001,$K11),"")) -> FC JUAREZ | E11: =IF($K11="","",IFERROR(INDEX('Veri Merkezi'!$G$2:$G$1001,$K11),"")) -> 46387 | F11: =IF($K11="","",IFERROR(INDEX('Veri Merkezi'!$H$2:$H$1001,$K11),"")) -> Yeşil | G11: =IF($K11="","",IFERROR(INDEX('Veri Merkezi'!$R$2:$R$1001,$K11),"")) | H11: =IF($K11="","",IFERROR(INDEX('Veri Merkezi'!$S$2:$S$1001,$K11),"")) -> A Liste | I11: =IF($K11="","",IFERROR(INDEX('Veri Merkezi'!$T$2:$T$1001,$K11),"")) | J11: =IF($K11="","",IFERROR(INDEX('Veri Merkezi'!$U$2:$U$1001,$K11),"")) -> 8 Numaralar | K11: =IF(K10="","",IFERROR(K10+MATCH("A Liste",INDEX('Veri Merkezi'!$S$2:$S$1001,K10+1):'Veri Merkezi'!$S$1001,0),"")) -> 506
A12: =IF($K12="","",IFERROR(INDEX('Veri Merkezi'!$A$2:$A$1001,$K12),"")) -> IVAN ILIC | B12: =IF($K12="","",IFERROR(INDEX('Veri Merkezi'!$E$2:$E$1001,$K12),"")) -> 8 Numara | C12: =IF($K12="","",IFERROR(INDEX('Veri Merkezi'!$D$2:$D$1001,$K12),"")) -> 25 | D12: =IF($K12="","",IFERROR(INDEX('Veri Merkezi'!$F$2:$F$1001,$K12),"")) -> LECCE | E12: =IF($K12="","",IFERROR(INDEX('Veri Merkezi'!$G$2:$G$1001,$K12),"")) -> 46568 | F12: =IF($K12="","",IFERROR(INDEX('Veri Merkezi'!$H$2:$H$1001,$K12),"")) -> Yeşil | G12: =IF($K12="","",IFERROR(INDEX('Veri Merkezi'!$R$2:$R$1001,$K12),"")) | H12: =IF($K12="","",IFERROR(INDEX('Veri Merkezi'!$S$2:$S$1001,$K12),"")) -> A Liste | I12: =IF($K12="","",IFERROR(INDEX('Veri Merkezi'!$T$2:$T$1001,$K12),"")) | J12: =IF($K12="","",IFERROR(INDEX('Veri Merkezi'!$U$2:$U$1001,$K12),"")) -> 8 Numaralar | K12: =IF(K11="","",IFERROR(K11+MATCH("A Liste",INDEX('Veri Merkezi'!$S$2:$S$1001,K11+1):'Veri Merkezi'!$S$1001,0),"")) -> 514
A13: =IF($K13="","",IFERROR(INDEX('Veri Merkezi'!$A$2:$A$1001,$K13),"")) -> EBENEZER AKSİNSANMİRO | B13: =IF($K13="","",IFERROR(INDEX('Veri Merkezi'!$E$2:$E$1001,$K13),"")) -> 8 Numara | C13: =IF($K13="","",IFERROR(INDEX('Veri Merkezi'!$D$2:$D$1001,$K13),"")) -> 21 | D13: =IF($K13="","",IFERROR(INDEX('Veri Merkezi'!$F$2:$F$1001,$K13),"")) -> MONZA | E13: =IF($K13="","",IFERROR(INDEX('Veri Merkezi'!$G$2:$G$1001,$K13),"")) -> 46568 | F13: =IF($K13="","",IFERROR(INDEX('Veri Merkezi'!$H$2:$H$1001,$K13),"")) -> Yeşil | G13: =IF($K13="","",IFERROR(INDEX('Veri Merkezi'!$R$2:$R$1001,$K13),"")) | H13: =IF($K13="","",IFERROR(INDEX('Veri Merkezi'!$S$2:$S$1001,$K13),"")) -> A Liste | I13: =IF($K13="","",IFERROR(INDEX('Veri Merkezi'!$T$2:$T$1001,$K13),"")) | J13: =IF($K13="","",IFERROR(INDEX('Veri Merkezi'!$U$2:$U$1001,$K13),"")) -> 8 Numaralar | K13: =IF(K12="","",IFERROR(K12+MATCH("A Liste",INDEX('Veri Merkezi'!$S$2:$S$1001,K12+1):'Veri Merkezi'!$S$1001,0),"")) -> 515
A14: =IF($K14="","",IFERROR(INDEX('Veri Merkezi'!$A$2:$A$1001,$K14),"")) -> LORENZO PELLEGRINI | B14: =IF($K14="","",IFERROR(INDEX('Veri Merkezi'!$E$2:$E$1001,$K14),"")) -> 10 Numara | C14: =IF($K14="","",IFERROR(INDEX('Veri Merkezi'!$D$2:$D$1001,$K14),"")) -> 30 | D14: =IF($K14="","",IFERROR(INDEX('Veri Merkezi'!$F$2:$F$1001,$K14),"")) -> ROMA | E14: =IF($K14="","",IFERROR(INDEX('Veri Merkezi'!$G$2:$G$1001,$K14),"")) -> 46568 | F14: =IF($K14="","",IFERROR(INDEX('Veri Merkezi'!$H$2:$H$1001,$K14),"")) -> Yeşil | G14: =IF($K14="","",IFERROR(INDEX('Veri Merkezi'!$R$2:$R$1001,$K14),"")) | H14: =IF($K14="","",IFERROR(INDEX('Veri Merkezi'!$S$2:$S$1001,$K14),"")) -> A Liste | I14: =IF($K14="","",IFERROR(INDEX('Veri Merkezi'!$T$2:$T$1001,$K14),"")) | J14: =IF($K14="","",IFERROR(INDEX('Veri Merkezi'!$U$2:$U$1001,$K14),"")) -> 10 Numaralar | K14: =IF(K13="","",IFERROR(K13+MATCH("A Liste",INDEX('Veri Merkezi'!$S$2:$S$1001,K13+1):'Veri Merkezi'!$S$1001,0),"")) -> 603
A15: =IF($K15="","",IFERROR(INDEX('Veri Merkezi'!$A$2:$A$1001,$K15),"")) -> NOE LEBRETON | B15: =IF($K15="","",IFERROR(INDEX('Veri Merkezi'!$E$2:$E$1001,$K15),"")) -> 10 Numara | C15: =IF($K15="","",IFERROR(INDEX('Veri Merkezi'!$D$2:$D$1001,$K15),"")) -> 22 | D15: =IF($K15="","",IFERROR(INDEX('Veri Merkezi'!$F$2:$F$1001,$K15),"")) -> NEC NIJMEGEN | E15: =IF($K15="","",IFERROR(INDEX('Veri Merkezi'!$G$2:$G$1001,$K15),"")) -> 47299 | F15: =IF($K15="","",IFERROR(INDEX('Veri Merkezi'!$H$2:$H$1001,$K15),"")) -> Yeşil | G15: =IF($K15="","",IFERROR(INDEX('Veri Merkezi'!$R$2:$R$1001,$K15),"")) | H15: =IF($K15="","",IFERROR(INDEX('Veri Merkezi'!$S$2:$S$1001,$K15),"")) -> A Liste | I15: =IF($K15="","",IFERROR(INDEX('Veri Merkezi'!$T$2:$T$1001,$K15),"")) | J15: =IF($K15="","",IFERROR(INDEX('Veri Merkezi'!$U$2:$U$1001,$K15),"")) -> 10 Numaralar | K15: =IF(K14="","",IFERROR(K14+MATCH("A Liste",INDEX('Veri Merkezi'!$S$2:$S$1001,K14+1):'Veri Merkezi'!$S$1001,0),"")) -> 604
A16: =IF($K16="","",IFERROR(INDEX('Veri Merkezi'!$A$2:$A$1001,$K16),"")) -> ISI PALAZON | B16: =IF($K16="","",IFERROR(INDEX('Veri Merkezi'!$E$2:$E$1001,$K16),"")) -> 10 Numara | C16: =IF($K16="","",IFERROR(INDEX('Veri Merkezi'!$D$2:$D$1001,$K16),"")) -> 31 | D16: =IF($K16="","",IFERROR(INDEX('Veri Merkezi'!$F$2:$F$1001,$K16),"")) -> RAYO VALLECANO | E16: =IF($K16="","",IFERROR(INDEX('Veri Merkezi'!$G$2:$G$1001,$K16),"")) -> 46934 | F16: =IF($K16="","",IFERROR(INDEX('Veri Merkezi'!$H$2:$H$1001,$K16),"")) -> Yeşil | G16: =IF($K16="","",IFERROR(INDEX('Veri Merkezi'!$R$2:$R$1001,$K16),"")) | H16: =IF($K16="","",IFERROR(INDEX('Veri Merkezi'!$S$2:$S$1001,$K16),"")) -> A Liste | I16: =IF($K16="","",IFERROR(INDEX('Veri Merkezi'!$T$2:$T$1001,$K16),"")) | J16: =IF($K16="","",IFERROR(INDEX('Veri Merkezi'!$U$2:$U$1001,$K16),"")) -> 10 Numaralar | K16: =IF(K15="","",IFERROR(K15+MATCH("A Liste",INDEX('Veri Merkezi'!$S$2:$S$1001,K15+1):'Veri Merkezi'!$S$1001,0),"")) -> 605
... A250: =IF($K250="","",IFERROR(INDEX('Veri Merkezi'!$A$2:$A$1001,$K250),"")) | B250: =IF($K250="","",IFERROR(INDEX('Veri Merkezi'!$E$2:$E$1001,$K250),"")) | C250: =IF($K250="","",IFERROR(INDEX('Veri Merkezi'!$D$2:$D$1001,$K250),"")) | D250: =IF($K250="","",IFERROR(INDEX('Veri Merkezi'!$F$2:$F$1001,$K250),"")) | E250: =IF($K250="","",IFERROR(INDEX('Veri Merkezi'!$G$2:$G$1001,$K250),"")) | F250: =IF($K250="","",IFERROR(INDEX('Veri Merkezi'!$H$2:$H$1001,$K250),"")) | G250: =IF($K250="","",IFERROR(INDEX('Veri Merkezi'!$R$2:$R$1001,$K250),"")) | H250: =IF($K250="","",IFERROR(INDEX('Veri Merkezi'!$S$2:$S$1001,$K250),"")) | I250: =IF($K250="","",IFERROR(INDEX('Veri Merkezi'!$T$2:$T$1001,$K250),"")) | J250: =IF($K250="","",IFERROR(INDEX('Veri Merkezi'!$U$2:$U$1001,$K250),"")) | K250: =IF(K249="","",IFERROR(K249+MATCH("A Liste",INDEX('Veri Merkezi'!$S$2:$S$1001,K249+1):'Veri Merkezi'!$S$1001,0),""))

Sheet B Liste
A1: B LİSTE | OYUNCU HAVUZU
A3: Adı Soyadı | B3: Mevki | C3: Yaş | D3: Kulübü | E3: Sözleşme | F3: Durum | G3: Scout Skoru | H3: Karar | I3: Son İzlenme | J3: Kaynak Sayfa
A4: =IF($K4="","",IFERROR(INDEX('Veri Merkezi'!$A$2:$A$1001,$K4),"")) -> FEDERICO GOTTONI | B4: =IF($K4="","",IFERROR(INDEX('Veri Merkezi'!$E$2:$E$1001,$K4),"")) -> Stoper | C4: =IF($K4="","",IFERROR(INDEX('Veri Merkezi'!$D$2:$D$1001,$K4),"")) -> 27 | D4: =IF($K4="","",IFERROR(INDEX('Veri Merkezi'!$F$2:$F$1001,$K4),"")) -> ASCOLI | E4: =IF($K4="","",IFERROR(INDEX('Veri Merkezi'!$G$2:$G$1001,$K4),"")) -> 46568 | F4: =IF($K4="","",IFERROR(INDEX('Veri Merkezi'!$H$2:$H$1001,$K4),"")) -> Sarı | G4: =IF($K4="","",IFERROR(INDEX('Veri Merkezi'!$R$2:$R$1001,$K4),"")) | H4: =IF($K4="","",IFERROR(INDEX('Veri Merkezi'!$S$2:$S$1001,$K4),"")) -> B Liste | I4: =IF($K4="","",IFERROR(INDEX('Veri Merkezi'!$T$2:$T$1001,$K4),"")) | J4: =IF($K4="","",IFERROR(INDEX('Veri Merkezi'!$U$2:$U$1001,$K4),"")) -> Stoperler | K4: =IFERROR(MATCH("B Liste",'Veri Merkezi'!$S$2:$S$1001,0),"") -> 101
A5: =IF($K5="","",IFERROR(INDEX('Veri Merkezi'!$A$2:$A$1001,$K5),"")) -> MİLOS VELJKOVİC | B5: =IF($K5="","",IFERROR(INDEX('Veri Merkezi'!$E$2:$E$1001,$K5),"")) -> Stoper | C5: =IF($K5="","",IFERROR(INDEX('Veri Merkezi'!$D$2:$D$1001,$K5),"")) -> 31 | D5: =IF($K5="","",IFERROR(INDEX('Veri Merkezi'!$F$2:$F$1001,$K5),"")) -> KIZILYILDIZ | E5: =IF($K5="","",IFERROR(INDEX('Veri Merkezi'!$G$2:$G$1001,$K5),"")) -> 46934 | F5: =IF($K5="","",IFERROR(INDEX('Veri Merkezi'!$H$2:$H$1001,$K5),"")) -> Sarı | G5: =IF($K5="","",IFERROR(INDEX('Veri Merkezi'!$R$2:$R$1001,$K5),"")) | H5: =IF($K5="","",IFERROR(INDEX('Veri Merkezi'!$S$2:$S$1001,$K5),"")) -> B Liste | I5: =IF($K5="","",IFERROR(INDEX('Veri Merkezi'!$T$2:$T$1001,$K5),"")) | J5: =IF($K5="","",IFERROR(INDEX('Veri Merkezi'!$U$2:$U$1001,$K5),"")) -> Stoperler | K5: =IF(K4="","",IFERROR(K4+MATCH("B Liste",INDEX('Veri Merkezi'!$S$2:$S$1001,K4+1):'Veri Merkezi'!$S$1001,0),"")) -> 106
A6: =IF($K6="","",IFERROR(INDEX('Veri Merkezi'!$A$2:$A$1001,$K6),"")) -> SOHAIB NAIR | B6: =IF($K6="","",IFERROR(INDEX('Veri Merkezi'!$E$2:$E$1001,$K6),"")) -> Stoper | C6: =IF($K6="","",IFERROR(INDEX('Veri Merkezi'!$D$2:$D$1001,$K6),"")) -> 24 | D6: =IF($K6="","",IFERROR(INDEX('Veri Merkezi'!$F$2:$F$1001,$K6),"")) -> ST.ETTIEN | E6: =IF($K6="","",IFERROR(INDEX('Veri Merkezi'!$G$2:$G$1001,$K6),"")) -> 47664 | F6: =IF($K6="","",IFERROR(INDEX('Veri Merkezi'!$H$2:$H$1001,$K6),"")) -> Yeşil | G6: =IF($K6="","",IFERROR(INDEX('Veri Merkezi'!$R$2:$R$1001,$K6),"")) | H6: =IF($K6="","",IFERROR(INDEX('Veri Merkezi'!$S$2:$S$1001,$K6),"")) -> B Liste | I6: =IF($K6="","",IFERROR(INDEX('Veri Merkezi'!$T$2:$T$1001,$K6),"")) | J6: =IF($K6="","",IFERROR(INDEX('Veri Merkezi'!$U$2:$U$1001,$K6),"")) -> Stoperler | K6: =IF(K5="","",IFERROR(K5+MATCH("B Liste",INDEX('Veri Merkezi'!$S$2:$S$1001,K5+1):'Veri Merkezi'!$S$1001,0),"")) -> 108
A7: =IF($K7="","",IFERROR(INDEX('Veri Merkezi'!$A$2:$A$1001,$K7),"")) -> AXEL TUANZEBE | B7: =IF($K7="","",IFERROR(INDEX('Veri Merkezi'!$E$2:$E$1001,$K7),"")) -> Stoper | C7: =IF($K7="","",IFERROR(INDEX('Veri Merkezi'!$D$2:$D$1001,$K7),"")) -> 28 | D7: =IF($K7="","",IFERROR(INDEX('Veri Merkezi'!$F$2:$F$1001,$K7),"")) -> AUXERRE | E7: =IF($K7="","",IFERROR(INDEX('Veri Merkezi'!$G$2:$G$1001,$K7),"")) -> 46568 | F7: =IF($K7="","",IFERROR(INDEX('Veri Merkezi'!$H$2:$H$1001,$K7),"")) -> Sarı | G7: =IF($K7="","",IFERROR(INDEX('Veri Merkezi'!$R$2:$R$1001,$K7),"")) | H7: =IF($K7="","",IFERROR(INDEX('Veri Merkezi'!$S$2:$S$1001,$K7),"")) -> B Liste | I7: =IF($K7="","",IFERROR(INDEX('Veri Merkezi'!$T$2:$T$1001,$K7),"")) | J7: =IF($K7="","",IFERROR(INDEX('Veri Merkezi'!$U$2:$U$1001,$K7),"")) -> Stoperler | K7: =IF(K6="","",IFERROR(K6+MATCH("B Liste",INDEX('Veri Merkezi'!$S$2:$S$1001,K6+1):'Veri Merkezi'!$S$1001,0),"")) -> 109
A8: =IF($K8="","",IFERROR(INDEX('Veri Merkezi'!$A$2:$A$1001,$K8),"")) -> DUJE CALETE-CAR | B8: =IF($K8="","",IFERROR(INDEX('Veri Merkezi'!$E$2:$E$1001,$K8),"")) -> Stoper | C8: =IF($K8="","",IFERROR(INDEX('Veri Merkezi'!$D$2:$D$1001,$K8),"")) -> 30 | D8: =IF($K8="","",IFERROR(INDEX('Veri Merkezi'!$F$2:$F$1001,$K8),"")) -> SASSUOLO | E8: =IF($K8="","",IFERROR(INDEX('Veri Merkezi'!$G$2:$G$1001,$K8),"")) -> 46934 | F8: =IF($K8="","",IFERROR(INDEX('Veri Merkezi'!$H$2:$H$1001,$K8),"")) -> Yeşil | G8: =IF($K8="","",IFERROR(INDEX('Veri Merkezi'!$R$2:$R$1001,$K8),"")) | H8: =IF($K8="","",IFERROR(INDEX('Veri Merkezi'!$S$2:$S$1001,$K8),"")) -> B Liste | I8: =IF($K8="","",IFERROR(INDEX('Veri Merkezi'!$T$2:$T$1001,$K8),"")) | J8: =IF($K8="","",IFERROR(INDEX('Veri Merkezi'!$U$2:$U$1001,$K8),"")) -> Stoperler | K8: =IF(K7="","",IFERROR(K7+MATCH("B Liste",INDEX('Veri Merkezi'!$S$2:$S$1001,K7+1):'Veri Merkezi'!$S$1001,0),"")) -> 112
A9: =IF($K9="","",IFERROR(INDEX('Veri Merkezi'!$A$2:$A$1001,$K9),"")) -> JOAO MARCELO MESSİAS FERREIRA | B9: =IF($K9="","",IFERROR(INDEX('Veri Merkezi'!$E$2:$E$1001,$K9),"")) -> Stoper | C9: =IF($K9="","",IFERROR(INDEX('Veri Merkezi'!$D$2:$D$1001,$K9),"")) -> 26 | D9: =IF($K9="","",IFERROR(INDEX('Veri Merkezi'!$F$2:$F$1001,$K9),"")) -> CRUZEİRO | E9: =IF($K9="","",IFERROR(INDEX('Veri Merkezi'!$G$2:$G$1001,$K9),"")) -> 47118 | F9: =IF($K9="","",IFERROR(INDEX('Veri Merkezi'!$H$2:$H$1001,$K9),"")) -> Yeşil | G9: =IF($K9="","",IFERROR(INDEX('Veri Merkezi'!$R$2:$R$1001,$K9),"")) | H9: =IF($K9="","",IFERROR(INDEX('Veri Merkezi'!$S$2:$S$1001,$K9),"")) -> B Liste | I9: =IF($K9="","",IFERROR(INDEX('Veri Merkezi'!$T$2:$T$1001,$K9),"")) | J9: =IF($K9="","",IFERROR(INDEX('Veri Merkezi'!$U$2:$U$1001,$K9),"")) -> Stoperler | K9: =IF(K8="","",IFERROR(K8+MATCH("B Liste",INDEX('Veri Merkezi'!$S$2:$S$1001,K8+1):'Veri Merkezi'!$S$1001,0),"")) -> 113
A10: =IF($K10="","",IFERROR(INDEX('Veri Merkezi'!$A$2:$A$1001,$K10),"")) -> MUJAID SADICK | B10: =IF($K10="","",IFERROR(INDEX('Veri Merkezi'!$E$2:$E$1001,$K10),"")) -> Stoper | C10: =IF($K10="","",IFERROR(INDEX('Veri Merkezi'!$D$2:$D$1001,$K10),"")) -> 26 | D10: =IF($K10="","",IFERROR(INDEX('Veri Merkezi'!$F$2:$F$1001,$K10),"")) -> RAYO VALLECANO | E10: =IF($K10="","",IFERROR(INDEX('Veri Merkezi'!$G$2:$G$1001,$K10),"")) -> 46558 | F10: =IF($K10="","",IFERROR(INDEX('Veri Merkezi'!$H$2:$H$1001,$K10),"")) -> Yeşil | G10: =IF($K10="","",IFERROR(INDEX('Veri Merkezi'!$R$2:$R$1001,$K10),"")) | H10: =IF($K10="","",IFERROR(INDEX('Veri Merkezi'!$S$2:$S$1001,$K10),"")) -> B Liste | I10: =IF($K10="","",IFERROR(INDEX('Veri Merkezi'!$T$2:$T$1001,$K10),"")) | J10: =IF($K10="","",IFERROR(INDEX('Veri Merkezi'!$U$2:$U$1001,$K10),"")) -> Stoperler | K10: =IF(K9="","",IFERROR(K9+MATCH("B Liste",INDEX('Veri Merkezi'!$S$2:$S$1001,K9+1):'Veri Merkezi'!$S$1001,0),"")) -> 115
A11: =IF($K11="","",IFERROR(INDEX('Veri Merkezi'!$A$2:$A$1001,$K11),"")) -> DOMINGOS DUARTE | B11: =IF($K11="","",IFERROR(INDEX('Veri Merkezi'!$E$2:$E$1001,$K11),"")) -> Stoper | C11: =IF($K11="","",IFERROR(INDEX('Veri Merkezi'!$D$2:$D$1001,$K11),"")) -> 31 | D11: =IF($K11="","",IFERROR(INDEX('Veri Merkezi'!$F$2:$F$1001,$K11),"")) -> SAO PAULO | E11: =IF($K11="","",IFERROR(INDEX('Veri Merkezi'!$G$2:$G$1001,$K11),"")) -> 46965 | F11: =IF($K11="","",IFERROR(INDEX('Veri Merkezi'!$H$2:$H$1001,$K11),"")) -> Yeşil | G11: =IF($K11="","",IFERROR(INDEX('Veri Merkezi'!$R$2:$R$1001,$K11),"")) | H11: =IF($K11="","",IFERROR(INDEX('Veri Merkezi'!$S$2:$S$1001,$K11),"")) -> B Liste | I11: =IF($K11="","",IFERROR(INDEX('Veri Merkezi'!$T$2:$T$1001,$K11),"")) | J11: =IF($K11="","",IFERROR(INDEX('Veri Merkezi'!$U$2:$U$1001,$K11),"")) -> Stoperler | K11: =IF(K10="","",IFERROR(K10+MATCH("B Liste",INDEX('Veri Merkezi'!$S$2:$S$1001,K10+1):'Veri Merkezi'!$S$1001,0),"")) -> 120
A12: =IF($K12="","",IFERROR(INDEX('Veri Merkezi'!$A$2:$A$1001,$K12),"")) -> GIVANNI VAN ZWAM | B12: =IF($K12="","",IFERROR(INDEX('Veri Merkezi'!$E$2:$E$1001,$K12),"")) -> Stoper | C12: =IF($K12="","",IFERROR(INDEX('Veri Merkezi'!$D$2:$D$1001,$K12),"")) -> 22 | D12: =IF($K12="","",IFERROR(INDEX('Veri Merkezi'!$F$2:$F$1001,$K12),"")) -> GO AHEAD | E12: =IF($K12="","",IFERROR(INDEX('Veri Merkezi'!$G$2:$G$1001,$K12),"")) -> 46568 | F12: =IF($K12="","",IFERROR(INDEX('Veri Merkezi'!$H$2:$H$1001,$K12),"")) -> Sarı | G12: =IF($K12="","",IFERROR(INDEX('Veri Merkezi'!$R$2:$R$1001,$K12),"")) | H12: =IF($K12="","",IFERROR(INDEX('Veri Merkezi'!$S$2:$S$1001,$K12),"")) -> B Liste | I12: =IF($K12="","",IFERROR(INDEX('Veri Merkezi'!$T$2:$T$1001,$K12),"")) | J12: =IF($K12="","",IFERROR(INDEX('Veri Merkezi'!$U$2:$U$1001,$K12),"")) -> Stoperler | K12: =IF(K11="","",IFERROR(K11+MATCH("B Liste",INDEX('Veri Merkezi'!$S$2:$S$1001,K11+1):'Veri Merkezi'!$S$1001,0),"")) -> 121
A13: =IF($K13="","",IFERROR(INDEX('Veri Merkezi'!$A$2:$A$1001,$K13),"")) -> DUJE CALETA-CAR | B13: =IF($K13="","",IFERROR(INDEX('Veri Merkezi'!$E$2:$E$1001,$K13),"")) -> Stoper | C13: =IF($K13="","",IFERROR(INDEX('Veri Merkezi'!$D$2:$D$1001,$K13),"")) -> 30 | D13: =IF($K13="","",IFERROR(INDEX('Veri Merkezi'!$F$2:$F$1001,$K13),"")) -> US SASSUOLO | E13: =IF($K13="","",IFERROR(INDEX('Veri Merkezi'!$G$2:$G$1001,$K13),"")) -> 46934 | F13: =IF($K13="","",IFERROR(INDEX('Veri Merkezi'!$H$2:$H$1001,$K13),"")) -> Yeşil | G13: =IF($K13="","",IFERROR(INDEX('Veri Merkezi'!$R$2:$R$1001,$K13),"")) | H13: =IF($K13="","",IFERROR(INDEX('Veri Merkezi'!$S$2:$S$1001,$K13),"")) -> B Liste | I13: =IF($K13="","",IFERROR(INDEX('Veri Merkezi'!$T$2:$T$1001,$K13),"")) | J13: =IF($K13="","",IFERROR(INDEX('Veri Merkezi'!$U$2:$U$1001,$K13),"")) -> Stoperler | K13: =IF(K12="","",IFERROR(K12+MATCH("B Liste",INDEX('Veri Merkezi'!$S$2:$S$1001,K12+1):'Veri Merkezi'!$S$1001,0),"")) -> 125
A14: =IF($K14="","",IFERROR(INDEX('Veri Merkezi'!$A$2:$A$1001,$K14),"")) -> ADRIA PEDROSA | B14: =IF($K14="","",IFERROR(INDEX('Veri Merkezi'!$E$2:$E$1001,$K14),"")) -> Sol Bek | C14: =IF($K14="","",IFERROR(INDEX('Veri Merkezi'!$D$2:$D$1001,$K14),"")) -> 28 | D14: =IF($K14="","",IFERROR(INDEX('Veri Merkezi'!$F$2:$F$1001,$K14),"")) -> ROYO VALLECANO | E14: =IF($K14="","",IFERROR(INDEX('Veri Merkezi'!$G$2:$G$1001,$K14),"")) -> 46568 | F14: =IF($K14="","",IFERROR(INDEX('Veri Merkezi'!$H$2:$H$1001,$K14),"")) -> Sarı | G14: =IF($K14="","",IFERROR(INDEX('Veri Merkezi'!$R$2:$R$1001,$K14),"")) | H14: =IF($K14="","",IFERROR(INDEX('Veri Merkezi'!$S$2:$S$1001,$K14),"")) -> B Liste | I14: =IF($K14="","",IFERROR(INDEX('Veri Merkezi'!$T$2:$T$1001,$K14),"")) | J14: =IF($K14="","",IFERROR(INDEX('Veri Merkezi'!$U$2:$U$1001,$K14),"")) -> Sol Bekler | K14: =IF(K13="","",IFERROR(K13+MATCH("B Liste",INDEX('Veri Merkezi'!$S$2:$S$1001,K13+1):'Veri Merkezi'!$S$1001,0),"")) -> 301
A15: =IF($K15="","",IFERROR(INDEX('Veri Merkezi'!$A$2:$A$1001,$K15),"")) -> PEDRO AMARAL | B15: =IF($K15="","",IFERROR(INDEX('Veri Merkezi'!$E$2:$E$1001,$K15),"")) -> Sol Bek | C15: =IF($K15="","",IFERROR(INDEX('Veri Merkezi'!$D$2:$D$1001,$K15),"")) -> 29 | D15: =IF($K15="","",IFERROR(INDEX('Veri Merkezi'!$F$2:$F$1001,$K15),"")) -> RIO AVE | E15: =IF($K15="","",IFERROR(INDEX('Veri Merkezi'!$G$2:$G$1001,$K15),"")) -> 46934 | F15: =IF($K15="","",IFERROR(INDEX('Veri Merkezi'!$H$2:$H$1001,$K15),"")) -> Sarı | G15: =IF($K15="","",IFERROR(INDEX('Veri Merkezi'!$R$2:$R$1001,$K15),"")) | H15: =IF($K15="","",IFERROR(INDEX('Veri Merkezi'!$S$2:$S$1001,$K15),"")) -> B Liste | I15: =IF($K15="","",IFERROR(INDEX('Veri Merkezi'!$T$2:$T$1001,$K15),"")) | J15: =IF($K15="","",IFERROR(INDEX('Veri Merkezi'!$U$2:$U$1001,$K15),"")) -> Sol Bekler | K15: =IF(K14="","",IFERROR(K14+MATCH("B Liste",INDEX('Veri Merkezi'!$S$2:$S$1001,K14+1):'Veri Merkezi'!$S$1001,0),"")) -> 303
A16: =IF($K16="","",IFERROR(INDEX('Veri Merkezi'!$A$2:$A$1001,$K16),"")) -> YUSSIF SAIDU | B16: =IF($K16="","",IFERROR(INDEX('Veri Merkezi'!$E$2:$E$1001,$K16),"")) -> 6 Numara | C16: =IF($K16="","",IFERROR(INDEX('Veri Merkezi'!$D$2:$D$1001,$K16),"")) -> 21 | D16: =IF($K16="","",IFERROR(INDEX('Veri Merkezi'!$F$2:$F$1001,$K16),"")) -> REAL ZARAGOZA | E16: =IF($K16="","",IFERROR(INDEX('Veri Merkezi'!$G$2:$G$1001,$K16),"")) -> 47664 | F16: =IF($K16="","",IFERROR(INDEX('Veri Merkezi'!$H$2:$H$1001,$K16),"")) -> Sarı | G16: =IF($K16="","",IFERROR(INDEX('Veri Merkezi'!$R$2:$R$1001,$K16),"")) | H16: =IF($K16="","",IFERROR(INDEX('Veri Merkezi'!$S$2:$S$1001,$K16),"")) -> B Liste | I16: =IF($K16="","",IFERROR(INDEX('Veri Merkezi'!$T$2:$T$1001,$K16),"")) | J16: =IF($K16="","",IFERROR(INDEX('Veri Merkezi'!$U$2:$U$1001,$K16),"")) -> 6 Numaralar | K16: =IF(K15="","",IFERROR(K15+MATCH("B Liste",INDEX('Veri Merkezi'!$S$2:$S$1001,K15+1):'Veri Merkezi'!$S$1001,0),"")) -> 402
... A250: =IF($K250="","",IFERROR(INDEX('Veri Merkezi'!$A$2:$A$1001,$K250),"")) | B250: =IF($K250="","",IFERROR(INDEX('Veri Merkezi'!$E$2:$E$1001,$K250),"")) | C250: =IF($K250="","",IFERROR(INDEX('Veri Merkezi'!$D$2:$D$1001,$K250),"")) | D250: =IF($K250="","",IFERROR(INDEX('Veri Merkezi'!$F$2:$F$1001,$K250),"")) | E250: =IF($K250="","",IFERROR(INDEX('Veri Merkezi'!$G$2:$G$1001,$K250),"")) | F250: =IF($K250="","",IFERROR(INDEX('Veri Merkezi'!$H$2:$H$1001,$K250),"")) | G250: =IF($K250="","",IFERROR(INDEX('Veri Merkezi'!$R$2:$R$1001,$K250),"")) | H250: =IF($K250="","",IFERROR(INDEX('Veri Merkezi'!$S$2:$S$1001,$K250),"")) | I250: =IF($K250="","",IFERROR(INDEX('Veri Merkezi'!$T$2:$T$1001,$K250),"")) | J250: =IF($K250="","",IFERROR(INDEX('Veri Merkezi'!$U$2:$U$1001,$K250),"")) | K250: =IF(K249="","",IFERROR(K249+MATCH("B Liste",INDEX('Veri Merkezi'!$S$2:$S$1001,K249+1):'Veri Merkezi'!$S$1001,0),""))

Sheet Takip Edilecekler
A1: TAKİP EDİLECEKLER | TAKİP HAVUZU
A3: Adı Soyadı | B3: Mevki | C3: Yaş | D3: Kulübü | E3: Sözleşme | F3: Durum | G3: Scout Skoru | H3: Karar | I3: Son İzlenme | J3: Kaynak Sayfa
A4: =IF($K4="","",IFERROR(INDEX('Veri Merkezi'!$A$2:$A$1001,$K4),"")) -> LEONARDO PİNHEİRO DA CONCEİÇAO | B4: =IF($K4="","",IFERROR(INDEX('Veri Merkezi'!$E$2:$E$1001,$K4),"")) -> Stoper | C4: =IF($K4="","",IFERROR(INDEX('Veri Merkezi'!$D$2:$D$1001,$K4),"")) -> 30 | D4: =IF($K4="","",IFERROR(INDEX('Veri Merkezi'!$F$2:$F$1001,$K4),"")) -> ATLETICA-PR | E4: =IF($K4="","",IFERROR(INDEX('Veri Merkezi'!$G$2:$G$1001,$K4),"")) -> 47118 | F4: =IF($K4="","",IFERROR(INDEX('Veri Merkezi'!$H$2:$H$1001,$K4),"")) -> Yeşil | G4: =IF($K4="","",IFERROR(INDEX('Veri Merkezi'!$R$2:$R$1001,$K4),"")) | H4: =IF($K4="","",IFERROR(INDEX('Veri Merkezi'!$S$2:$S$1001,$K4),"")) -> Takip | I4: =IF($K4="","",IFERROR(INDEX('Veri Merkezi'!$T$2:$T$1001,$K4),"")) | J4: =IF($K4="","",IFERROR(INDEX('Veri Merkezi'!$U$2:$U$1001,$K4),"")) -> Stoperler | K4: =IFERROR(MATCH("Takip",'Veri Merkezi'!$S$2:$S$1001,0),"") -> 105
A5: =IF($K5="","",IFERROR(INDEX('Veri Merkezi'!$A$2:$A$1001,$K5),"")) -> JAKOV MEDIC | B5: =IF($K5="","",IFERROR(INDEX('Veri Merkezi'!$E$2:$E$1001,$K5),"")) -> Stoper | C5: =IF($K5="","",IFERROR(INDEX('Veri Merkezi'!$D$2:$D$1001,$K5),"")) -> 28 | D5: =IF($K5="","",IFERROR(INDEX('Veri Merkezi'!$F$2:$F$1001,$K5),"")) -> UTRECHT | E5: =IF($K5="","",IFERROR(INDEX('Veri Merkezi'!$G$2:$G$1001,$K5),"")) -> 46568 | F5: =IF($K5="","",IFERROR(INDEX('Veri Merkezi'!$H$2:$H$1001,$K5),"")) -> Sarı | G5: =IF($K5="","",IFERROR(INDEX('Veri Merkezi'!$R$2:$R$1001,$K5),"")) | H5: =IF($K5="","",IFERROR(INDEX('Veri Merkezi'!$S$2:$S$1001,$K5),"")) -> Takip | I5: =IF($K5="","",IFERROR(INDEX('Veri Merkezi'!$T$2:$T$1001,$K5),"")) | J5: =IF($K5="","",IFERROR(INDEX('Veri Merkezi'!$U$2:$U$1001,$K5),"")) -> Stoperler | K5: =IF(K4="","",IFERROR(K4+MATCH("Takip",INDEX('Veri Merkezi'!$S$2:$S$1001,K4+1):'Veri Merkezi'!$S$1001,0),"")) -> 111
A6: =IF($K6="","",IFERROR(INDEX('Veri Merkezi'!$A$2:$A$1001,$K6),"")) -> AHMED HADZIMUJOVIC | B6: =IF($K6="","",IFERROR(INDEX('Veri Merkezi'!$E$2:$E$1001,$K6),"")) -> Stoper | C6: =IF($K6="","",IFERROR(INDEX('Veri Merkezi'!$D$2:$D$1001,$K6),"")) -> 19 | D6: =IF($K6="","",IFERROR(INDEX('Veri Merkezi'!$F$2:$F$1001,$K6),"")) -> NOVI PAZAR | E6: =IF($K6="","",IFERROR(INDEX('Veri Merkezi'!$G$2:$G$1001,$K6),"")) -> 46568 | F6: =IF($K6="","",IFERROR(INDEX('Veri Merkezi'!$H$2:$H$1001,$K6),"")) -> Sarı | G6: =IF($K6="","",IFERROR(INDEX('Veri Merkezi'!$R$2:$R$1001,$K6),"")) | H6: =IF($K6="","",IFERROR(INDEX('Veri Merkezi'!$S$2:$S$1001,$K6),"")) -> Takip | I6: =IF($K6="","",IFERROR(INDEX('Veri Merkezi'!$T$2:$T$1001,$K6),"")) | J6: =IF($K6="","",IFERROR(INDEX('Veri Merkezi'!$U$2:$U$1001,$K6),"")) -> Stoperler | K6: =IF(K5="","",IFERROR(K5+MATCH("Takip",INDEX('Veri Merkezi'!$S$2:$S$1001,K5+1):'Veri Merkezi'!$S$1001,0),"")) -> 116
A7: =IF($K7="","",IFERROR(INDEX('Veri Merkezi'!$A$2:$A$1001,$K7),"")) -> MARIO TUDOSE | B7: =IF($K7="","",IFERROR(INDEX('Veri Merkezi'!$E$2:$E$1001,$K7),"")) -> Stoper | C7: =IF($K7="","",IFERROR(INDEX('Veri Merkezi'!$D$2:$D$1001,$K7),"")) -> 21 | D7: =IF($K7="","",IFERROR(INDEX('Veri Merkezi'!$F$2:$F$1001,$K7),"")) -> FC ARGES | E7: =IF($K7="","",IFERROR(INDEX('Veri Merkezi'!$G$2:$G$1001,$K7),"")) -> 47289 | F7: =IF($K7="","",IFERROR(INDEX('Veri Merkezi'!$H$2:$H$1001,$K7),"")) -> Sarı | G7: =IF($K7="","",IFERROR(INDEX('Veri Merkezi'!$R$2:$R$1001,$K7),"")) | H7: =IF($K7="","",IFERROR(INDEX('Veri Merkezi'!$S$2:$S$1001,$K7),"")) -> Takip | I7: =IF($K7="","",IFERROR(INDEX('Veri Merkezi'!$T$2:$T$1001,$K7),"")) | J7: =IF($K7="","",IFERROR(INDEX('Veri Merkezi'!$U$2:$U$1001,$K7),"")) -> Stoperler | K7: =IF(K6="","",IFERROR(K6+MATCH("Takip",INDEX('Veri Merkezi'!$S$2:$S$1001,K6+1):'Veri Merkezi'!$S$1001,0),"")) -> 119
A8: =IF($K8="","",IFERROR(INDEX('Veri Merkezi'!$A$2:$A$1001,$K8),"")) -> CHECK KEITA | B8: =IF($K8="","",IFERROR(INDEX('Veri Merkezi'!$E$2:$E$1001,$K8),"")) -> Stoper | C8: =IF($K8="","",IFERROR(INDEX('Veri Merkezi'!$D$2:$D$1001,$K8),"")) -> 23 | D8: =IF($K8="","",IFERROR(INDEX('Veri Merkezi'!$F$2:$F$1001,$K8),"")) -> ROYAL CHARLEROI SC | E8: =IF($K8="","",IFERROR(INDEX('Veri Merkezi'!$G$2:$G$1001,$K8),"")) -> 46568 | F8: =IF($K8="","",IFERROR(INDEX('Veri Merkezi'!$H$2:$H$1001,$K8),"")) -> Sarı | G8: =IF($K8="","",IFERROR(INDEX('Veri Merkezi'!$R$2:$R$1001,$K8),"")) | H8: =IF($K8="","",IFERROR(INDEX('Veri Merkezi'!$S$2:$S$1001,$K8),"")) -> Takip | I8: =IF($K8="","",IFERROR(INDEX('Veri Merkezi'!$T$2:$T$1001,$K8),"")) | J8: =IF($K8="","",IFERROR(INDEX('Veri Merkezi'!$U$2:$U$1001,$K8),"")) -> Stoperler | K8: =IF(K7="","",IFERROR(K7+MATCH("Takip",INDEX('Veri Merkezi'!$S$2:$S$1001,K7+1):'Veri Merkezi'!$S$1001,0),"")) -> 123
