Workbook

Sheet Dashboard
A1: TÜRKİYE LİGLERİ FUTBOLCU TAKİP SİSTEMİ | CONTROL CENTER
A4: TOPLAM OYUNCU | D4: ORTALAMA YAŞ | G4: A LİSTE | J4: B LİSTE | M4: YENİDEN İZLE | P4: SÖZLEŞMESİ BİTENLER
A5: =COUNTIF(Kaleciler!B4:B103,"?*")+COUNTIF(Stoperler!B4:B103,"?*")+COUNTIF('Sağ Bekler'!B4:B103,"?*")+COUNTIF('Sol Bekler'!B4:B103,"?*")+COUNTIF('Orta Saha'!B4:B103,"?*")+COUNTIF(Kanatlar!B4:B103,"?*")+COUNTIF(Forvetler!B4:B103,"?*") -> 53 | D5: =IFERROR((SUMIFS(Kaleciler!D4:D103,Kaleciler!B4:B103,"?*")+SUMIFS(Stoperler!D4:D103,Stoperler!B4:B103,"?*")+SUMIFS('Sağ Bekler'!D4:D103,'Sağ Bekler'!B4:B103,"?*")+SUMIFS('Sol Bekler'!D4:D103,'Sol Bekler'!B4:B103,"?*")+SUMIFS('Orta Saha'!D4:D103,'Orta Saha'!B4:B103,"?*")+SUMIFS(Kanatlar!D4:D103,Kanatlar!B4:B103,"?*")+SUMIFS(Forvetler!D4:D103,Forvetler!B4:B103,"?*"))/(COUNTIFS(Kaleciler!B4:B103,"?*",Kaleciler!D4:D103,">=0")+COUNTIFS(Stoperler!B4:B103,"?*",Stoperler!D4:D103,">=0")+COUNTIFS('Sağ Bekler'!B4:B103,"?*",'Sağ Bekler'!D4:D103,">=0")+COUNTIFS('Sol Bekler'!B4:B103,"?*",'Sol Bekler'!D4:D103,">=0")+COUNTIFS('Orta Saha'!B4:B103,"?*",'Orta Saha'!D4:D103,">=0")+COUNTIFS(Kanatlar!B4:B103,"?*",Kanatlar!D4:D103,">=0")+COUNTIFS(Forvetler!B4:B103,"?*",Forvetler!D4:D103,">=0")),0) -> 19.245283 | G5: =COUNTIFS(Kaleciler!B4:B103,"?*",Kaleciler!Q4:Q103,"A Liste")+COUNTIFS(Stoperler!B4:B103,"?*",Stoperler!Q4:Q103,"A Liste")+COUNTIFS('Sağ Bekler'!B4:B103,"?*",'Sağ Bekler'!Q4:Q103,"A Liste")+COUNTIFS('Sol Bekler'!B4:B103,"?*",'Sol Bekler'!Q4:Q103,"A Liste")+COUNTIFS('Orta Saha'!B4:B103,"?*",'Orta Saha'!Q4:Q103,"A Liste")+COUNTIFS(Kanatlar!B4:B103,"?*",Kanatlar!Q4:Q103,"A Liste")+COUNTIFS(Forvetler!B4:B103,"?*",Forvetler!Q4:Q103,"A Liste") -> 10 | J5: =COUNTIFS(Kaleciler!B4:B103,"?*",Kaleciler!Q4:Q103,"B Liste")+COUNTIFS(Stoperler!B4:B103,"?*",Stoperler!Q4:Q103,"B Liste")+COUNTIFS('Sağ Bekler'!B4:B103,"?*",'Sağ Bekler'!Q4:Q103,"B Liste")+COUNTIFS('Sol Bekler'!B4:B103,"?*",'Sol Bekler'!Q4:Q103,"B Liste")+COUNTIFS('Orta Saha'!B4:B103,"?*",'Orta Saha'!Q4:Q103,"B Liste")+COUNTIFS(Kanatlar!B4:B103,"?*",Kanatlar!Q4:Q103,"B Liste")+COUNTIFS(Forvetler!B4:B103,"?*",Forvetler!Q4:Q103,"B Liste") -> 13 | M5: =COUNTIFS(Kaleciler!B4:B103,"?*",Kaleciler!Q4:Q103,"Yeniden İzle")+COUNTIFS(Stoperler!B4:B103,"?*",Stoperler!Q4:Q103,"Yeniden İzle")+COUNTIFS('Sağ Bekler'!B4:B103,"?*",'Sağ Bekler'!Q4:Q103,"Yeniden İzle")+COUNTIFS('Sol Bekler'!B4:B103,"?*",'Sol Bekler'!Q4:Q103,"Yeniden İzle")+COUNTIFS('Orta Saha'!B4:B103,"?*",'Orta Saha'!Q4:Q103,"Yeniden İzle")+COUNTIFS(Kanatlar!B4:B103,"?*",Kanatlar!Q4:Q103,"Yeniden İzle")+COUNTIFS(Forvetler!B4:B103,"?*",Forvetler!Q4:Q103,"Yeniden İzle") -> 30 | P5: =COUNTIFS(Kaleciler!$B$4:$B$103,"?*",Kaleciler!$I$4:$I$103,">0",Kaleciler!$I$4:$I$103,"<="&TODAY()+365)+COUNTIFS(Stoperler!$B$4:$B$103,"?*",Stoperler!$I$4:$I$103,">0",Stoperler!$I$4:$I$103,"<="&TODAY()+365)+COUNTIFS('Sağ Bekler'!$B$4:$B$103,"?*",'Sağ Bekler'!$I$4:$I$103,">0",'Sağ Bekler'!$I$4:$I$103,"<="&TODAY()+365)+COUNTIFS('Sol Bekler'!$B$4:$B$103,"?*",'Sol Bekler'!$I$4:$I$103,">0",'Sol Bekler'!$I$4:$I$103,"<="&TODAY()+365)+COUNTIFS('Orta Saha'!$B$4:$B$103,"?*",'Orta Saha'!$I$4:$I$103,">0",'Orta Saha'!$I$4:$I$103,"<="&TODAY()+365)+COUNTIFS(Kanatlar!$B$4:$B$103,"?*",Kanatlar!$I$4:$I$103,">0",Kanatlar!$I$4:$I$103,"<="&TODAY()+365)+COUNTIFS(Forvetler!$B$4:$B$103,"?*",Forvetler!$I$4:$I$103,">0",Forvetler!$I$4:$I$103,"<="&TODAY()+365) -> 15
A7: MEVKİ DAĞILIMI | H7: YAŞ DAĞILIMI
A15: Kaleciler | B15: =COUNTIF(Kaleciler!B4:B103,"?*") -> 1 | H15: ≤17 | I15: =COUNTIFS(Kaleciler!$B$4:$B$103,"?*",Kaleciler!$D$4:$D$103,"<=17")+COUNTIFS(Stoperler!$B$4:$B$103,"?*",Stoperler!$D$4:$D$103,"<=17")+COUNTIFS('Sağ Bekler'!$B$4:$B$103,"?*",'Sağ Bekler'!$D$4:$D$103,"<=17")+COUNTIFS('Sol Bekler'!$B$4:$B$103,"?*",'Sol Bekler'!$D$4:$D$103,"<=17")+COUNTIFS('Orta Saha'!$B$4:$B$103,"?*",'Orta Saha'!$D$4:$D$103,"<=17")+COUNTIFS(Kanatlar!$B$4:$B$103,"?*",Kanatlar!$D$4:$D$103,"<=17")+COUNTIFS(Forvetler!$B$4:$B$103,"?*",Forvetler!$D$4:$D$103,"<=17") -> 5 | Q15: 1.LİG
A16: Stoperler | B16: =COUNTIF(Stoperler!B4:B103,"?*") -> 6 | H16: 18 | I16: =COUNTIFS(Kaleciler!$B$4:$B$103,"?*",Kaleciler!$D$4:$D$103,"=18")+COUNTIFS(Stoperler!$B$4:$B$103,"?*",Stoperler!$D$4:$D$103,"=18")+COUNTIFS('Sağ Bekler'!$B$4:$B$103,"?*",'Sağ Bekler'!$D$4:$D$103,"=18")+COUNTIFS('Sol Bekler'!$B$4:$B$103,"?*",'Sol Bekler'!$D$4:$D$103,"=18")+COUNTIFS('Orta Saha'!$B$4:$B$103,"?*",'Orta Saha'!$D$4:$D$103,"=18")+COUNTIFS(Kanatlar!$B$4:$B$103,"?*",Kanatlar!$D$4:$D$103,"=18")+COUNTIFS(Forvetler!$B$4:$B$103,"?*",Forvetler!$D$4:$D$103,"=18") -> 8
A17: Sağ Bekler | B17: =COUNTIF('Sağ Bekler'!B4:B103,"?*") -> 0 | H17: 19 | I17: =COUNTIFS(Kaleciler!$B$4:$B$103,"?*",Kaleciler!$D$4:$D$103,"=19")+COUNTIFS(Stoperler!$B$4:$B$103,"?*",Stoperler!$D$4:$D$103,"=19")+COUNTIFS('Sağ Bekler'!$B$4:$B$103,"?*",'Sağ Bekler'!$D$4:$D$103,"=19")+COUNTIFS('Sol Bekler'!$B$4:$B$103,"?*",'Sol Bekler'!$D$4:$D$103,"=19")+COUNTIFS('Orta Saha'!$B$4:$B$103,"?*",'Orta Saha'!$D$4:$D$103,"=19")+COUNTIFS(Kanatlar!$B$4:$B$103,"?*",Kanatlar!$D$4:$D$103,"=19")+COUNTIFS(Forvetler!$B$4:$B$103,"?*",Forvetler!$D$4:$D$103,"=19") -> 20
A18: Sol Bekler | B18: =COUNTIF('Sol Bekler'!B4:B103,"?*") -> 3 | H18: 20 | I18: =COUNTIFS(Kaleciler!$B$4:$B$103,"?*",Kaleciler!$D$4:$D$103,"=20")+COUNTIFS(Stoperler!$B$4:$B$103,"?*",Stoperler!$D$4:$D$103,"=20")+COUNTIFS('Sağ Bekler'!$B$4:$B$103,"?*",'Sağ Bekler'!$D$4:$D$103,"=20")+COUNTIFS('Sol Bekler'!$B$4:$B$103,"?*",'Sol Bekler'!$D$4:$D$103,"=20")+COUNTIFS('Orta Saha'!$B$4:$B$103,"?*",'Orta Saha'!$D$4:$D$103,"=20")+COUNTIFS(Kanatlar!$B$4:$B$103,"?*",Kanatlar!$D$4:$D$103,"=20")+COUNTIFS(Forvetler!$B$4:$B$103,"?*",Forvetler!$D$4:$D$103,"=20") -> 15
A19: Orta Saha | B19: =COUNTIF('Orta Saha'!B4:B103,"?*") -> 20 | H19: 21 | I19: =COUNTIFS(Kaleciler!$B$4:$B$103,"?*",Kaleciler!$D$4:$D$103,"=21")+COUNTIFS(Stoperler!$B$4:$B$103,"?*",Stoperler!$D$4:$D$103,"=21")+COUNTIFS('Sağ Bekler'!$B$4:$B$103,"?*",'Sağ Bekler'!$D$4:$D$103,"=21")+COUNTIFS('Sol Bekler'!$B$4:$B$103,"?*",'Sol Bekler'!$D$4:$D$103,"=21")+COUNTIFS('Orta Saha'!$B$4:$B$103,"?*",'Orta Saha'!$D$4:$D$103,"=21")+COUNTIFS(Kanatlar!$B$4:$B$103,"?*",Kanatlar!$D$4:$D$103,"=21")+COUNTIFS(Forvetler!$B$4:$B$103,"?*",Forvetler!$D$4:$D$103,"=21") -> 3
A20: Kanatlar | B20: =COUNTIF(Kanatlar!B4:B103,"?*") -> 16 | H20: 22+ | I20: =COUNTIFS(Kaleciler!$B$4:$B$103,"?*",Kaleciler!$D$4:$D$103,">=22")+COUNTIFS(Stoperler!$B$4:$B$103,"?*",Stoperler!$D$4:$D$103,">=22")+COUNTIFS('Sağ Bekler'!$B$4:$B$103,"?*",'Sağ Bekler'!$D$4:$D$103,">=22")+COUNTIFS('Sol Bekler'!$B$4:$B$103,"?*",'Sol Bekler'!$D$4:$D$103,">=22")+COUNTIFS('Orta Saha'!$B$4:$B$103,"?*",'Orta Saha'!$D$4:$D$103,">=22")+COUNTIFS(Kanatlar!$B$4:$B$103,"?*",Kanatlar!$D$4:$D$103,">=22")+COUNTIFS(Forvetler!$B$4:$B$103,"?*",Forvetler!$D$4:$D$103,">=22") -> 2
A21: Forvetler | B21: =COUNTIF(Forvetler!B4:B103,"?*") -> 7
A24: Karar akışı: A Liste / B Liste / Yeniden İzle. Oyuncu girdikçe Dashboard otomatik güncellenir.
A26: LİG DAĞILIMI | SAYISAL
A28: Süper Lig | B28: =COUNTIFS(Kaleciler!B4:B103,"?*",Kaleciler!H4:H103,"Süper Lig")+COUNTIFS(Stoperler!B4:B103,"?*",Stoperler!H4:H103,"Süper Lig")+COUNTIFS('Sağ Bekler'!B4:B103,"?*",'Sağ Bekler'!H4:H103,"Süper Lig")+COUNTIFS('Sol Bekler'!B4:B103,"?*",'Sol Bekler'!H4:H103,"Süper Lig")+COUNTIFS('Orta Saha'!B4:B103,"?*",'Orta Saha'!H4:H103,"Süper Lig")+COUNTIFS(Kanatlar!B4:B103,"?*",Kanatlar!H4:H103,"Süper Lig")+COUNTIFS(Forvetler!B4:B103,"?*",Forvetler!H4:H103,"Süper Lig") -> 0 | U28: Sözleşmesi Bitenler | V28: =COUNTIFS(Kaleciler!$B$4:$B$103,"?*",Kaleciler!$I$4:$I$103,">0",Kaleciler!$I$4:$I$103,"<="&TODAY()+365)+COUNTIFS(Stoperler!$B$4:$B$103,"?*",Stoperler!$I$4:$I$103,">0",Stoperler!$I$4:$I$103,"<="&TODAY()+365)+COUNTIFS('Sağ Bekler'!$B$4:$B$103,"?*",'Sağ Bekler'!$I$4:$I$103,">0",'Sağ Bekler'!$I$4:$I$103,"<="&TODAY()+365)+COUNTIFS('Sol Bekler'!$B$4:$B$103,"?*",'Sol Bekler'!$I$4:$I$103,">0",'Sol Bekler'!$I$4:$I$103,"<="&TODAY()+365)+COUNTIFS('Orta Saha'!$B$4:$B$103,"?*",'Orta Saha'!$I$4:$I$103,">0",'Orta Saha'!$I$4:$I$103,"<="&TODAY()+365)+COUNTIFS(Kanatlar!$B$4:$B$103,"?*",Kanatlar!$I$4:$I$103,">0",Kanatlar!$I$4:$I$103,"<="&TODAY()+365)+COUNTIFS(Forvetler!$B$4:$B$103,"?*",Forvetler!$I$4:$I$103,">0",Forvetler!$I$4:$I$103,"<="&TODAY()+365) -> 15
A29: 1.Lig | B29: =COUNTIFS(Kaleciler!B4:B103,"?*",Kaleciler!H4:H103,"1.Lig")+COUNTIFS(Stoperler!B4:B103,"?*",Stoperler!H4:H103,"1.Lig")+COUNTIFS('Sağ Bekler'!B4:B103,"?*",'Sağ Bekler'!H4:H103,"1.Lig")+COUNTIFS('Sol Bekler'!B4:B103,"?*",'Sol Bekler'!H4:H103,"1.Lig")+COUNTIFS('Orta Saha'!B4:B103,"?*",'Orta Saha'!H4:H103,"1.Lig")+COUNTIFS(Kanatlar!B4:B103,"?*",Kanatlar!H4:H103,"1.Lig")+COUNTIFS(Forvetler!B4:B103,"?*",Forvetler!H4:H103,"1.Lig") -> 32 | U29: Devam Edenler | V29: =COUNTIFS(Kaleciler!$B$4:$B$103,"?*",Kaleciler!$I$4:$I$103,">"&TODAY()+365)+COUNTIFS(Stoperler!$B$4:$B$103,"?*",Stoperler!$I$4:$I$103,">"&TODAY()+365)+COUNTIFS('Sağ Bekler'!$B$4:$B$103,"?*",'Sağ Bekler'!$I$4:$I$103,">"&TODAY()+365)+COUNTIFS('Sol Bekler'!$B$4:$B$103,"?*",'Sol Bekler'!$I$4:$I$103,">"&TODAY()+365)+COUNTIFS('Orta Saha'!$B$4:$B$103,"?*",'Orta Saha'!$I$4:$I$103,">"&TODAY()+365)+COUNTIFS(Kanatlar!$B$4:$B$103,"?*",Kanatlar!$I$4:$I$103,">"&TODAY()+365)+COUNTIFS(Forvetler!$B$4:$B$103,"?*",Forvetler!$I$4:$I$103,">"&TODAY()+365) -> 32
A30: 2.Lig | B30: =COUNTIFS(Kaleciler!B4:B103,"?*",Kaleciler!H4:H103,"2.Lig")+COUNTIFS(Stoperler!B4:B103,"?*",Stoperler!H4:H103,"2.Lig")+COUNTIFS('Sağ Bekler'!B4:B103,"?*",'Sağ Bekler'!H4:H103,"2.Lig")+COUNTIFS('Sol Bekler'!B4:B103,"?*",'Sol Bekler'!H4:H103,"2.Lig")+COUNTIFS('Orta Saha'!B4:B103,"?*",'Orta Saha'!H4:H103,"2.Lig")+COUNTIFS(Kanatlar!B4:B103,"?*",Kanatlar!H4:H103,"2.Lig")+COUNTIFS(Forvetler!B4:B103,"?*",Forvetler!H4:H103,"2.Lig") -> 14
A31: 3.Lig | B31: =COUNTIFS(Kaleciler!B4:B103,"?*",Kaleciler!H4:H103,"3.Lig")+COUNTIFS(Stoperler!B4:B103,"?*",Stoperler!H4:H103,"3.Lig")+COUNTIFS('Sağ Bekler'!B4:B103,"?*",'Sağ Bekler'!H4:H103,"3.Lig")+COUNTIFS('Sol Bekler'!B4:B103,"?*",'Sol Bekler'!H4:H103,"3.Lig")+COUNTIFS('Orta Saha'!B4:B103,"?*",'Orta Saha'!H4:H103,"3.Lig")+COUNTIFS(Kanatlar!B4:B103,"?*",Kanatlar!H4:H103,"3.Lig")+COUNTIFS(Forvetler!B4:B103,"?*",Forvetler!H4:H103,"3.Lig") -> 7

Sheet A Liste
A1: A LİSTE | TÜRKİYE LİGLERİ
A3: Sıra No | B3: Adı Soyadı | C3: Doğum Tarihi | D3: Yaş | E3: Mevki | F3: Ayak | G3: Kulübü | H3: Lig | I3: Sözleşme Bitiş Tarihi | J3: Maç Tarihi | K3: Dakika | L3: Teknik | M3: Fiziksel | N3: Taktik | O3: Mental | P3: Potansiyel | Q3: Karar | R3: Son İzlenme | S3: İzlenme Sayısı | T3: Scout Notu
A4: =IF($X4="","",CHOOSE($X4,IF(ISBLANK(INDEX(Kaleciler!A:A,$Y4)),"",INDEX(Kaleciler!A:A,$Y4)),IF(ISBLANK(INDEX(Stoperler!A:A,$Y4)),"",INDEX(Stoperler!A:A,$Y4)),IF(ISBLANK(INDEX('Sağ Bekler'!A:A,$Y4)),"",INDEX('Sağ Bekler'!A:A,$Y4)),IF(ISBLANK(INDEX('Sol Bekler'!A:A,$Y4)),"",INDEX('Sol Bekler'!A:A,$Y4)),IF(ISBLANK(INDEX('Orta Saha'!A:A,$Y4)),"",INDEX('Orta Saha'!A:A,$Y4)),IF(ISBLANK(INDEX(Kanatlar!A:A,$Y4)),"",INDEX(Kanatlar!A:A,$Y4)),IF(ISBLANK(INDEX(Forvetler!A:A,$Y4)),"",INDEX(Forvetler!A:A,$Y4)))) -> 2 | B4: =IF($X4="","",CHOOSE($X4,IF(ISBLANK(INDEX(Kaleciler!B:B,$Y4)),"",INDEX(Kaleciler!B:B,$Y4)),IF(ISBLANK(INDEX(Stoperler!B:B,$Y4)),"",INDEX(Stoperler!B:B,$Y4)),IF(ISBLANK(INDEX('Sağ Bekler'!B:B,$Y4)),"",INDEX('Sağ Bekler'!B:B,$Y4)),IF(ISBLANK(INDEX('Sol Bekler'!B:B,$Y4)),"",INDEX('Sol Bekler'!B:B,$Y4)),IF(ISBLANK(INDEX('Orta Saha'!B:B,$Y4)),"",INDEX('Orta Saha'!B:B,$Y4)),IF(ISBLANK(INDEX(Kanatlar!B:B,$Y4)),"",INDEX(Kanatlar!B:B,$Y4)),IF(ISBLANK(INDEX(Forvetler!B:B,$Y4)),"",INDEX(Forvetler!B:B,$Y4)))) -> ADA İBİK | C4: =IF($X4="","",CHOOSE($X4,IF(ISBLANK(INDEX(Kaleciler!C:C,$Y4)),"",INDEX(Kaleciler!C:C,$Y4)),IF(ISBLANK(INDEX(Stoperler!C:C,$Y4)),"",INDEX(Stoperler!C:C,$Y4)),IF(ISBLANK(INDEX('Sağ Bekler'!C:C,$Y4)),"",INDEX('Sağ Bekler'!C:C,$Y4)),IF(ISBLANK(INDEX('Sol Bekler'!C:C,$Y4)),"",INDEX('Sol Bekler'!C:C,$Y4)),IF(ISBLANK(INDEX('Orta Saha'!C:C,$Y4)),"",INDEX('Orta Saha'!C:C,$Y4)),IF(ISBLANK(INDEX(Kanatlar!C:C,$Y4)),"",INDEX(Kanatlar!C:C,$Y4)),IF(ISBLANK(INDEX(Forvetler!C:C,$Y4)),"",INDEX(Forvetler!C:C,$Y4)))) -> 39755 | D4: =IF($X4="","",CHOOSE($X4,IF(ISBLANK(INDEX(Kaleciler!D:D,$Y4)),"",INDEX(Kaleciler!D:D,$Y4)),IF(ISBLANK(INDEX(Stoperler!D:D,$Y4)),"",INDEX(Stoperler!D:D,$Y4)),IF(ISBLANK(INDEX('Sağ Bekler'!D:D,$Y4)),"",INDEX('Sağ Bekler'!D:D,$Y4)),IF(ISBLANK(INDEX('Sol Bekler'!D:D,$Y4)),"",INDEX('Sol Bekler'!D:D,$Y4)),IF(ISBLANK(INDEX('Orta Saha'!D:D,$Y4)),"",INDEX('Orta Saha'!D:D,$Y4)),IF(ISBLANK(INDEX(Kanatlar!D:D,$Y4)),"",INDEX(Kanatlar!D:D,$Y4)),IF(ISBLANK(INDEX(Forvetler!D:D,$Y4)),"",INDEX(Forvetler!D:D,$Y4)))) -> 17 | E4: =IF($X4="","",CHOOSE($X4,IF(ISBLANK(INDEX(Kaleciler!E:E,$Y4)),"",INDEX(Kaleciler!E:E,$Y4)),IF(ISBLANK(INDEX(Stoperler!E:E,$Y4)),"",INDEX(Stoperler!E:E,$Y4)),IF(ISBLANK(INDEX('Sağ Bekler'!E:E,$Y4)),"",INDEX('Sağ Bekler'!E:E,$Y4)),IF(ISBLANK(INDEX('Sol Bekler'!E:E,$Y4)),"",INDEX('Sol Bekler'!E:E,$Y4)),IF(ISBLANK(INDEX('Orta Saha'!E:E,$Y4)),"",INDEX('Orta Saha'!E:E,$Y4)),IF(ISBLANK(INDEX(Kanatlar!E:E,$Y4)),"",INDEX(Kanatlar!E:E,$Y4)),IF(ISBLANK(INDEX(Forvetler!E:E,$Y4)),"",INDEX(Forvetler!E:E,$Y4)))) -> Stoper | F4: =IF($X4="","",CHOOSE($X4,IF(ISBLANK(INDEX(Kaleciler!F:F,$Y4)),"",INDEX(Kaleciler!F:F,$Y4)),IF(ISBLANK(INDEX(Stoperler!F:F,$Y4)),"",INDEX(Stoperler!F:F,$Y4)),IF(ISBLANK(INDEX('Sağ Bekler'!F:F,$Y4)),"",INDEX('Sağ Bekler'!F:F,$Y4)),IF(ISBLANK(INDEX('Sol Bekler'!F:F,$Y4)),"",INDEX('Sol Bekler'!F:F,$Y4)),IF(ISBLANK(INDEX('Orta Saha'!F:F,$Y4)),"",INDEX('Orta Saha'!F:F,$Y4)),IF(ISBLANK(INDEX(Kanatlar!F:F,$Y4)),"",INDEX(Kanatlar!F:F,$Y4)),IF(ISBLANK(INDEX(Forvetler!F:F,$Y4)),"",INDEX(Forvetler!F:F,$Y4)))) -> Sol | G4: =IF($X4="","",CHOOSE($X4,IF(ISBLANK(INDEX(Kaleciler!G:G,$Y4)),"",INDEX(Kaleciler!G:G,$Y4)),IF(ISBLANK(INDEX(Stoperler!G:G,$Y4)),"",INDEX(Stoperler!G:G,$Y4)),IF(ISBLANK(INDEX('Sağ Bekler'!G:G,$Y4)),"",INDEX('Sağ Bekler'!G:G,$Y4)),IF(ISBLANK(INDEX('Sol Bekler'!G:G,$Y4)),"",INDEX('Sol Bekler'!G:G,$Y4)),IF(ISBLANK(INDEX('Orta Saha'!G:G,$Y4)),"",INDEX('Orta Saha'!G:G,$Y4)),IF(ISBLANK(INDEX(Kanatlar!G:G,$Y4)),"",INDEX(Kanatlar!G:G,$Y4)),IF(ISBLANK(INDEX(Forvetler!G:G,$Y4)),"",INDEX(Forvetler!G:G,$Y4)))) -> MANİSA FK | H4: =IF($X4="","",CHOOSE($X4,IF(ISBLANK(INDEX(Kaleciler!H:H,$Y4)),"",INDEX(Kaleciler!H:H,$Y4)),IF(ISBLANK(INDEX(Stoperler!H:H,$Y4)),"",INDEX(Stoperler!H:H,$Y4)),IF(ISBLANK(INDEX('Sağ Bekler'!H:H,$Y4)),"",INDEX('Sağ Bekler'!H:H,$Y4)),IF(ISBLANK(INDEX('Sol Bekler'!H:H,$Y4)),"",INDEX('Sol Bekler'!H:H,$Y4)),IF(ISBLANK(INDEX('Orta Saha'!H:H,$Y4)),"",INDEX('Orta Saha'!H:H,$Y4)),IF(ISBLANK(INDEX(Kanatlar!H:H,$Y4)),"",INDEX(Kanatlar!H:H,$Y4)),IF(ISBLANK(INDEX(Forvetler!H:H,$Y4)),"",INDEX(Forvetler!H:H,$Y4)))) -> 1.Lig | I4: =IF($X4="","",CHOOSE($X4,IF(ISBLANK(INDEX(Kaleciler!I:I,$Y4)),"",INDEX(Kaleciler!I:I,$Y4)),IF(ISBLANK(INDEX(Stoperler!I:I,$Y4)),"",INDEX(Stoperler!I:I,$Y4)),IF(ISBLANK(INDEX('Sağ Bekler'!I:I,$Y4)),"",INDEX('Sağ Bekler'!I:I,$Y4)),IF(ISBLANK(INDEX('Sol Bekler'!I:I,$Y4)),"",INDEX('Sol Bekler'!I:I,$Y4)),IF(ISBLANK(INDEX('Orta Saha'!I:I,$Y4)),"",INDEX('Orta Saha'!I:I,$Y4)),IF(ISBLANK(INDEX(Kanatlar!I:I,$Y4)),"",INDEX(Kanatlar!I:I,$Y4)),IF(ISBLANK(INDEX(Forvetler!I:I,$Y4)),"",INDEX(Forvetler!I:I,$Y4)))) -> 46934 | J4: =IF($X4="","",CHOOSE($X4,IF(ISBLANK(INDEX(Kaleciler!J:J,$Y4)),"",INDEX(Kaleciler!J:J,$Y4)),IF(ISBLANK(INDEX(Stoperler!J:J,$Y4)),"",INDEX(Stoperler!J:J,$Y4)),IF(ISBLANK(INDEX('Sağ Bekler'!J:J,$Y4)),"",INDEX('Sağ Bekler'!J:J,$Y4)),IF(ISBLANK(INDEX('Sol Bekler'!J:J,$Y4)),"",INDEX('Sol Bekler'!J:J,$Y4)),IF(ISBLANK(INDEX('Orta Saha'!J:J,$Y4)),"",INDEX('Orta Saha'!J:J,$Y4)),IF(ISBLANK(INDEX(Kanatlar!J:J,$Y4)),"",INDEX(Kanatlar!J:J,$Y4)),IF(ISBLANK(INDEX(Forvetler!J:J,$Y4)),"",INDEX(Forvetler!J:J,$Y4)))) | K4: =IF($X4="","",CHOOSE($X4,IF(ISBLANK(INDEX(Kaleciler!K:K,$Y4)),"",INDEX(Kaleciler!K:K,$Y4)),IF(ISBLANK(INDEX(Stoperler!K:K,$Y4)),"",INDEX(Stoperler!K:K,$Y4)),IF(ISBLANK(INDEX('Sağ Bekler'!K:K,$Y4)),"",INDEX('Sağ Bekler'!K:K,$Y4)),IF(ISBLANK(INDEX('Sol Bekler'!K:K,$Y4)),"",INDEX('Sol Bekler'!K:K,$Y4)),IF(ISBLANK(INDEX('Orta Saha'!K:K,$Y4)),"",INDEX('Orta Saha'!K:K,$Y4)),IF(ISBLANK(INDEX(Kanatlar!K:K,$Y4)),"",INDEX(Kanatlar!K:K,$Y4)),IF(ISBLANK(INDEX(Forvetler!K:K,$Y4)),"",INDEX(Forvetler!K:K,$Y4)))) | L4: =IF($X4="","",CHOOSE($X4,IF(ISBLANK(INDEX(Kaleciler!L:L,$Y4)),"",INDEX(Kaleciler!L:L,$Y4)),IF(ISBLANK(INDEX(Stoperler!L:L,$Y4)),"",INDEX(Stoperler!L:L,$Y4)),IF(ISBLANK(INDEX('Sağ Bekler'!L:L,$Y4)),"",INDEX('Sağ Bekler'!L:L,$Y4)),IF(ISBLANK(INDEX('Sol Bekler'!L:L,$Y4)),"",INDEX('Sol Bekler'!L:L,$Y4)),IF(ISBLANK(INDEX('Orta Saha'!L:L,$Y4)),"",INDEX('Orta Saha'!L:L,$Y4)),IF(ISBLANK(INDEX(Kanatlar!L:L,$Y4)),"",INDEX(Kanatlar!L:L,$Y4)),IF(ISBLANK(INDEX(Forvetler!L:L,$Y4)),"",INDEX(Forvetler!L:L,$Y4)))) | M4: =IF($X4="","",CHOOSE($X4,IF(ISBLANK(INDEX(Kaleciler!M:M,$Y4)),"",INDEX(Kaleciler!M:M,$Y4)),IF(ISBLANK(INDEX(Stoperler!M:M,$Y4)),"",INDEX(Stoperler!M:M,$Y4)),IF(ISBLANK(INDEX('Sağ Bekler'!M:M,$Y4)),"",INDEX('Sağ Bekler'!M:M,$Y4)),IF(ISBLANK(INDEX('Sol Bekler'!M:M,$Y4)),"",INDEX('Sol Bekler'!M:M,$Y4)),IF(ISBLANK(INDEX('Orta Saha'!M:M,$Y4)),"",INDEX('Orta Saha'!M:M,$Y4)),IF(ISBLANK(INDEX(Kanatlar!M:M,$Y4)),"",INDEX(Kanatlar!M:M,$Y4)),IF(ISBLANK(INDEX(Forvetler!M:M,$Y4)),"",INDEX(Forvetler!M:M,$Y4)))) | N4: =IF($X4="","",CHOOSE($X4,IF(ISBLANK(INDEX(Kaleciler!N:N,$Y4)),"",INDEX(Kaleciler!N:N,$Y4)),IF(ISBLANK(INDEX(Stoperler!N:N,$Y4)),"",INDEX(Stoperler!N:N,$Y4)),IF(ISBLANK(INDEX('Sağ Bekler'!N:N,$Y4)),"",INDEX('Sağ Bekler'!N:N,$Y4)),IF(ISBLANK(INDEX('Sol Bekler'!N:N,$Y4)),"",INDEX('Sol Bekler'!N:N,$Y4)),IF(ISBLANK(INDEX('Orta Saha'!N:N,$Y4)),"",INDEX('Orta Saha'!N:N,$Y4)),IF(ISBLANK(INDEX(Kanatlar!N:N,$Y4)),"",INDEX(Kanatlar!N:N,$Y4)),IF(ISBLANK(INDEX(Forvetler!N:N,$Y4)),"",INDEX(Forvetler!N:N,$Y4)))) | O4: =IF($X4="","",CHOOSE($X4,IF(ISBLANK(INDEX(Kaleciler!O:O,$Y4)),"",INDEX(Kaleciler!O:O,$Y4)),IF(ISBLANK(INDEX(Stoperler!O:O,$Y4)),"",INDEX(Stoperler!O:O,$Y4)),IF(ISBLANK(INDEX('Sağ Bekler'!O:O,$Y4)),"",INDEX('Sağ Bekler'!O:O,$Y4)),IF(ISBLANK(INDEX('Sol Bekler'!O:O,$Y4)),"",INDEX('Sol Bekler'!O:O,$Y4)),IF(ISBLANK(INDEX('Orta Saha'!O:O,$Y4)),"",INDEX('Orta Saha'!O:O,$Y4)),IF(ISBLANK(INDEX(Kanatlar!O:O,$Y4)),"",INDEX(Kanatlar!O:O,$Y4)),IF(ISBLANK(INDEX(Forvetler!O:O,$Y4)),"",INDEX(Forvetler!O:O,$Y4)))) | P4: =IF($X4="","",CHOOSE($X4,IF(ISBLANK(INDEX(Kaleciler!P:P,$Y4)),"",INDEX(Kaleciler!P:P,$Y4)),IF(ISBLANK(INDEX(Stoperler!P:P,$Y4)),"",INDEX(Stoperler!P:P,$Y4)),IF(ISBLANK(INDEX('Sağ Bekler'!P:P,$Y4)),"",INDEX('Sağ Bekler'!P:P,$Y4)),IF(ISBLANK(INDEX('Sol Bekler'!P:P,$Y4)),"",INDEX('Sol Bekler'!P:P,$Y4)),IF(ISBLANK(INDEX('Orta Saha'!P:P,$Y4)),"",INDEX('Orta Saha'!P:P,$Y4)),IF(ISBLANK(INDEX(Kanatlar!P:P,$Y4)),"",INDEX(Kanatlar!P:P,$Y4)),IF(ISBLANK(INDEX(Forvetler!P:P,$Y4)),"",INDEX(Forvetler!P:P,$Y4)))) | Q4: =IF($X4="","",CHOOSE($X4,IF(ISBLANK(INDEX(Kaleciler!Q:Q,$Y4)),"",INDEX(Kaleciler!Q:Q,$Y4)),IF(ISBLANK(INDEX(Stoperler!Q:Q,$Y4)),"",INDEX(Stoperler!Q:Q,$Y4)),IF(ISBLANK(INDEX('Sağ Bekler'!Q:Q,$Y4)),"",INDEX('Sağ Bekler'!Q:Q,$Y4)),IF(ISBLANK(INDEX('Sol Bekler'!Q:Q,$Y4)),"",INDEX('Sol Bekler'!Q:Q,$Y4)),IF(ISBLANK(INDEX('Orta Saha'!Q:Q,$Y4)),"",INDEX('Orta Saha'!Q:Q,$Y4)),IF(ISBLANK(INDEX(Kanatlar!Q:Q,$Y4)),"",INDEX(Kanatlar!Q:Q,$Y4)),IF(ISBLANK(INDEX(Forvetler!Q:Q,$Y4)),"",INDEX(Forvetler!Q:Q,$Y4)))) -> A Liste | R4: =IF($X4="","",CHOOSE($X4,IF(ISBLANK(INDEX(Kaleciler!R:R,$Y4)),"",INDEX(Kaleciler!R:R,$Y4)),IF(ISBLANK(INDEX(Stoperler!R:R,$Y4)),"",INDEX(Stoperler!R:R,$Y4)),IF(ISBLANK(INDEX('Sağ Bekler'!R:R,$Y4)),"",INDEX('Sağ Bekler'!R:R,$Y4)),IF(ISBLANK(INDEX('Sol Bekler'!R:R,$Y4)),"",INDEX('Sol Bekler'!R:R,$Y4)),IF(ISBLANK(INDEX('Orta Saha'!R:R,$Y4)),"",INDEX('Orta Saha'!R:R,$Y4)),IF(ISBLANK(INDEX(Kanatlar!R:R,$Y4)),"",INDEX(Kanatlar!R:R,$Y4)),IF(ISBLANK(INDEX(Forvetler!R:R,$Y4)),"",INDEX(Forvetler!R:R,$Y4)))) | S4: =IF($X4="","",CHOOSE($X4,IF(ISBLANK(INDEX(Kaleciler!S:S,$Y4)),"",INDEX(Kaleciler!S:S,$Y4)),IF(ISBLANK(INDEX(Stoperler!S:S,$Y4)),"",INDEX(Stoperler!S:S,$Y4)),IF(ISBLANK(INDEX('Sağ Bekler'!S:S,$Y4)),"",INDEX('Sağ Bekler'!S:S,$Y4)),IF(ISBLANK(INDEX('Sol Bekler'!S:S,$Y4)),"",INDEX('Sol Bekler'!S:S,$Y4)),IF(ISBLANK(INDEX('Orta Saha'!S:S,$Y4)),"",INDEX('Orta Saha'!S:S,$Y4)),IF(ISBLANK(INDEX(Kanatlar!S:S,$Y4)),"",INDEX(Kanatlar!S:S,$Y4)),IF(ISBLANK(INDEX(Forvetler!S:S,$Y4)),"",INDEX(Forvetler!S:S,$Y4)))) | T4: =IF($X4="","",CHOOSE($X4,IF(ISBLANK(INDEX(Kaleciler!T:T,$Y4)),"",INDEX(Kaleciler!T:T,$Y4)),IF(ISBLANK(INDEX(Stoperler!T:T,$Y4)),"",INDEX(Stoperler!T:T,$Y4)),IF(ISBLANK(INDEX('Sağ Bekler'!T:T,$Y4)),"",INDEX('Sağ Bekler'!T:T,$Y4)),IF(ISBLANK(INDEX('Sol Bekler'!T:T,$Y4)),"",INDEX('Sol Bekler'!T:T,$Y4)),IF(ISBLANK(INDEX('Orta Saha'!T:T,$Y4)),"",INDEX('Orta Saha'!T:T,$Y4)),IF(ISBLANK(INDEX(Kanatlar!T:T,$Y4)),"",INDEX(Kanatlar!T:T,$Y4)),IF(ISBLANK(INDEX(Forvetler!T:T,$Y4)),"",INDEX(Forvetler!T:T,$Y4)))) | U4: 1 | V4: 4 | W4: =IF(Kaleciler!$Q$4="A Liste",COUNT($W$3:W3)+1,"") | X4: =IFERROR(INDEX($U$4:$U$703,MATCH(ROWS($X$4:X4),$W$4:$W$703,0)),"") -> 2 | Y4: =IFERROR(INDEX($V$4:$V$703,MATCH(ROWS($Y$4:Y4),$W$4:$W$703,0)),"") -> 5
A5: =IF($X5="","",CHOOSE($X5,IF(ISBLANK(INDEX(Kaleciler!A:A,$Y5)),"",INDEX(Kaleciler!A:A,$Y5)),IF(ISBLANK(INDEX(Stoperler!A:A,$Y5)),"",INDEX(Stoperler!A:A,$Y5)),IF(ISBLANK(INDEX('Sağ Bekler'!A:A,$Y5)),"",INDEX('Sağ Bekler'!A:A,$Y5)),IF(ISBLANK(INDEX('Sol Bekler'!A:A,$Y5)),"",INDEX('Sol Bekler'!A:A,$Y5)),IF(ISBLANK(INDEX('Orta Saha'!A:A,$Y5)),"",INDEX('Orta Saha'!A:A,$Y5)),IF(ISBLANK(INDEX(Kanatlar!A:A,$Y5)),"",INDEX(Kanatlar!A:A,$Y5)),IF(ISBLANK(INDEX(Forvetler!A:A,$Y5)),"",INDEX(Forvetler!A:A,$Y5)))) -> 5 | B5: =IF($X5="","",CHOOSE($X5,IF(ISBLANK(INDEX(Kaleciler!B:B,$Y5)),"",INDEX(Kaleciler!B:B,$Y5)),IF(ISBLANK(INDEX(Stoperler!B:B,$Y5)),"",INDEX(Stoperler!B:B,$Y5)),IF(ISBLANK(INDEX('Sağ Bekler'!B:B,$Y5)),"",INDEX('Sağ Bekler'!B:B,$Y5)),IF(ISBLANK(INDEX('Sol Bekler'!B:B,$Y5)),"",INDEX('Sol Bekler'!B:B,$Y5)),IF(ISBLANK(INDEX('Orta Saha'!B:B,$Y5)),"",INDEX('Orta Saha'!B:B,$Y5)),IF(ISBLANK(INDEX(Kanatlar!B:B,$Y5)),"",INDEX(Kanatlar!B:B,$Y5)),IF(ISBLANK(INDEX(Forvetler!B:B,$Y5)),"",INDEX(Forvetler!B:B,$Y5)))) -> DEVRAN BOZARDIÇ | C5: =IF($X5="","",CHOOSE($X5,IF(ISBLANK(INDEX(Kaleciler!C:C,$Y5)),"",INDEX(Kaleciler!C:C,$Y5)),IF(ISBLANK(INDEX(Stoperler!C:C,$Y5)),"",INDEX(Stoperler!C:C,$Y5)),IF(ISBLANK(INDEX('Sağ Bekler'!C:C,$Y5)),"",INDEX('Sağ Bekler'!C:C,$Y5)),IF(ISBLANK(INDEX('Sol Bekler'!C:C,$Y5)),"",INDEX('Sol Bekler'!C:C,$Y5)),IF(ISBLANK(INDEX('Orta Saha'!C:C,$Y5)),"",INDEX('Orta Saha'!C:C,$Y5)),IF(ISBLANK(INDEX(Kanatlar!C:C,$Y5)),"",INDEX(Kanatlar!C:C,$Y5)),IF(ISBLANK(INDEX(Forvetler!C:C,$Y5)),"",INDEX(Forvetler!C:C,$Y5)))) -> 38748 | D5: =IF($X5="","",CHOOSE($X5,IF(ISBLANK(INDEX(Kaleciler!D:D,$Y5)),"",INDEX(Kaleciler!D:D,$Y5)),IF(ISBLANK(INDEX(Stoperler!D:D,$Y5)),"",INDEX(Stoperler!D:D,$Y5)),IF(ISBLANK(INDEX('Sağ Bekler'!D:D,$Y5)),"",INDEX('Sağ Bekler'!D:D,$Y5)),IF(ISBLANK(INDEX('Sol Bekler'!D:D,$Y5)),"",INDEX('Sol Bekler'!D:D,$Y5)),IF(ISBLANK(INDEX('Orta Saha'!D:D,$Y5)),"",INDEX('Orta Saha'!D:D,$Y5)),IF(ISBLANK(INDEX(Kanatlar!D:D,$Y5)),"",INDEX(Kanatlar!D:D,$Y5)),IF(ISBLANK(INDEX(Forvetler!D:D,$Y5)),"",INDEX(Forvetler!D:D,$Y5)))) -> 20 | E5: =IF($X5="","",CHOOSE($X5,IF(ISBLANK(INDEX(Kaleciler!E:E,$Y5)),"",INDEX(Kaleciler!E:E,$Y5)),IF(ISBLANK(INDEX(Stoperler!E:E,$Y5)),"",INDEX(Stoperler!E:E,$Y5)),IF(ISBLANK(INDEX('Sağ Bekler'!E:E,$Y5)),"",INDEX('Sağ Bekler'!E:E,$Y5)),IF(ISBLANK(INDEX('Sol Bekler'!E:E,$Y5)),"",INDEX('Sol Bekler'!E:E,$Y5)),IF(ISBLANK(INDEX('Orta Saha'!E:E,$Y5)),"",INDEX('Orta Saha'!E:E,$Y5)),IF(ISBLANK(INDEX(Kanatlar!E:E,$Y5)),"",INDEX(Kanatlar!E:E,$Y5)),IF(ISBLANK(INDEX(Forvetler!E:E,$Y5)),"",INDEX(Forvetler!E:E,$Y5)))) -> Stoper | F5: =IF($X5="","",CHOOSE($X5,IF(ISBLANK(INDEX(Kaleciler!F:F,$Y5)),"",INDEX(Kaleciler!F:F,$Y5)),IF(ISBLANK(INDEX(Stoperler!F:F,$Y5)),"",INDEX(Stoperler!F:F,$Y5)),IF(ISBLANK(INDEX('Sağ Bekler'!F:F,$Y5)),"",INDEX('Sağ Bekler'!F:F,$Y5)),IF(ISBLANK(INDEX('Sol Bekler'!F:F,$Y5)),"",INDEX('Sol Bekler'!F:F,$Y5)),IF(ISBLANK(INDEX('Orta Saha'!F:F,$Y5)),"",INDEX('Orta Saha'!F:F,$Y5)),IF(ISBLANK(INDEX(Kanatlar!F:F,$Y5)),"",INDEX(Kanatlar!F:F,$Y5)),IF(ISBLANK(INDEX(Forvetler!F:F,$Y5)),"",INDEX(Forvetler!F:F,$Y5)))) -> Sol | G5: =IF($X5="","",CHOOSE($X5,IF(ISBLANK(INDEX(Kaleciler!G:G,$Y5)),"",INDEX(Kaleciler!G:G,$Y5)),IF(ISBLANK(INDEX(Stoperler!G:G,$Y5)),"",INDEX(Stoperler!G:G,$Y5)),IF(ISBLANK(INDEX('Sağ Bekler'!G:G,$Y5)),"",INDEX('Sağ Bekler'!G:G,$Y5)),IF(ISBLANK(INDEX('Sol Bekler'!G:G,$Y5)),"",INDEX('Sol Bekler'!G:G,$Y5)),IF(ISBLANK(INDEX('Orta Saha'!G:G,$Y5)),"",INDEX('Orta Saha'!G:G,$Y5)),IF(ISBLANK(INDEX(Kanatlar!G:G,$Y5)),"",INDEX(Kanatlar!G:G,$Y5)),IF(ISBLANK(INDEX(Forvetler!G:G,$Y5)),"",INDEX(Forvetler!G:G,$Y5)))) -> BATMAN PETROLSPOR | H5: =IF($X5="","",CHOOSE($X5,IF(ISBLANK(INDEX(Kaleciler!H:H,$Y5)),"",INDEX(Kaleciler!H:H,$Y5)),IF(ISBLANK(INDEX(Stoperler!H:H,$Y5)),"",INDEX(Stoperler!H:H,$Y5)),IF(ISBLANK(INDEX('Sağ Bekler'!H:H,$Y5)),"",INDEX('Sağ Bekler'!H:H,$Y5)),IF(ISBLANK(INDEX('Sol Bekler'!H:H,$Y5)),"",INDEX('Sol Bekler'!H:H,$Y5)),IF(ISBLANK(INDEX('Orta Saha'!H:H,$Y5)),"",INDEX('Orta Saha'!H:H,$Y5)),IF(ISBLANK(INDEX(Kanatlar!H:H,$Y5)),"",INDEX(Kanatlar!H:H,$Y5)),IF(ISBLANK(INDEX(Forvetler!H:H,$Y5)),"",INDEX(Forvetler!H:H,$Y5)))) -> 1.Lig | I5: =IF($X5="","",CHOOSE($X5,IF(ISBLANK(INDEX(Kaleciler!I:I,$Y5)),"",INDEX(Kaleciler!I:I,$Y5)),IF(ISBLANK(INDEX(Stoperler!I:I,$Y5)),"",INDEX(Stoperler!I:I,$Y5)),IF(ISBLANK(INDEX('Sağ Bekler'!I:I,$Y5)),"",INDEX('Sağ Bekler'!I:I,$Y5)),IF(ISBLANK(INDEX('Sol Bekler'!I:I,$Y5)),"",INDEX('Sol Bekler'!I:I,$Y5)),IF(ISBLANK(INDEX('Orta Saha'!I:I,$Y5)),"",INDEX('Orta Saha'!I:I,$Y5)),IF(ISBLANK(INDEX(Kanatlar!I:I,$Y5)),"",INDEX(Kanatlar!I:I,$Y5)),IF(ISBLANK(INDEX(Forvetler!I:I,$Y5)),"",INDEX(Forvetler!I:I,$Y5)))) -> 46934 | J5: =IF($X5="","",CHOOSE($X5,IF(ISBLANK(INDEX(Kaleciler!J:J,$Y5)),"",INDEX(Kaleciler!J:J,$Y5)),IF(ISBLANK(INDEX(Stoperler!J:J,$Y5)),"",INDEX(Stoperler!J:J,$Y5)),IF(ISBLANK(INDEX('Sağ Bekler'!J:J,$Y5)),"",INDEX('Sağ Bekler'!J:J,$Y5)),IF(ISBLANK(INDEX('Sol Bekler'!J:J,$Y5)),"",INDEX('Sol Bekler'!J:J,$Y5)),IF(ISBLANK(INDEX('Orta Saha'!J:J,$Y5)),"",INDEX('Orta Saha'!J:J,$Y5)),IF(ISBLANK(INDEX(Kanatlar!J:J,$Y5)),"",INDEX(Kanatlar!J:J,$Y5)),IF(ISBLANK(INDEX(Forvetler!J:J,$Y5)),"",INDEX(Forvetler!J:J,$Y5)))) | K5: =IF($X5="","",CHOOSE($X5,IF(ISBLANK(INDEX(Kaleciler!K:K,$Y5)),"",INDEX(Kaleciler!K:K,$Y5)),IF(ISBLANK(INDEX(Stoperler!K:K,$Y5)),"",INDEX(Stoperler!K:K,$Y5)),IF(ISBLANK(INDEX('Sağ Bekler'!K:K,$Y5)),"",INDEX('Sağ Bekler'!K:K,$Y5)),IF(ISBLANK(INDEX('Sol Bekler'!K:K,$Y5)),"",INDEX('Sol Bekler'!K:K,$Y5)),IF(ISBLANK(INDEX('Orta Saha'!K:K,$Y5)),"",INDEX('Orta Saha'!K:K,$Y5)),IF(ISBLANK(INDEX(Kanatlar!K:K,$Y5)),"",INDEX(Kanatlar!K:K,$Y5)),IF(ISBLANK(INDEX(Forvetler!K:K,$Y5)),"",INDEX(Forvetler!K:K,$Y5)))) | L5: =IF($X5="","",CHOOSE($X5,IF(ISBLANK(INDEX(Kaleciler!L:L,$Y5)),"",INDEX(Kaleciler!L:L,$Y5)),IF(ISBLANK(INDEX(Stoperler!L:L,$Y5)),"",INDEX(Stoperler!L:L,$Y5)),IF(ISBLANK(INDEX('Sağ Bekler'!L:L,$Y5)),"",INDEX('Sağ Bekler'!L:L,$Y5)),IF(ISBLANK(INDEX('Sol Bekler'!L:L,$Y5)),"",INDEX('Sol Bekler'!L:L,$Y5)),IF(ISBLANK(INDEX('Orta Saha'!L:L,$Y5)),"",INDEX('Orta Saha'!L:L,$Y5)),IF(ISBLANK(INDEX(Kanatlar!L:L,$Y5)),"",INDEX(Kanatlar!L:L,$Y5)),IF(ISBLANK(INDEX(Forvetler!L:L,$Y5)),"",INDEX(Forvetler!L:L,$Y5)))) | M5: =IF($X5="","",CHOOSE($X5,IF(ISBLANK(INDEX(Kaleciler!M:M,$Y5)),"",INDEX(Kaleciler!M:M,$Y5)),IF(ISBLANK(INDEX(Stoperler!M:M,$Y5)),"",INDEX(Stoperler!M:M,$Y5)),IF(ISBLANK(INDEX('Sağ Bekler'!M:M,$Y5)),"",INDEX('Sağ Bekler'!M:M,$Y5)),IF(ISBLANK(INDEX('Sol Bekler'!M:M,$Y5)),"",INDEX('Sol Bekler'!M:M,$Y5)),IF(ISBLANK(INDEX('Orta Saha'!M:M,$Y5)),"",INDEX('Orta Saha'!M:M,$Y5)),IF(ISBLANK(INDEX(Kanatlar!M:M,$Y5)),"",INDEX(Kanatlar!M:M,$Y5)),IF(ISBLANK(INDEX(Forvetler!M:M,$Y5)),"",INDEX(Forvetler!M:M,$Y5)))) | N5: =IF($X5="","",CHOOSE($X5,IF(ISBLANK(INDEX(Kaleciler!N:N,$Y5)),"",INDEX(Kaleciler!N:N,$Y5)),IF(ISBLANK(INDEX(Stoperler!N:N,$Y5)),"",INDEX(Stoperler!N:N,$Y5)),IF(ISBLANK(INDEX('Sağ Bekler'!N:N,$Y5)),"",INDEX('Sağ Bekler'!N:N,$Y5)),IF(ISBLANK(INDEX('Sol Bekler'!N:N,$Y5)),"",INDEX('Sol Bekler'!N:N,$Y5)),IF(ISBLANK(INDEX('Orta Saha'!N:N,$Y5)),"",INDEX('Orta Saha'!N:N,$Y5)),IF(ISBLANK(INDEX(Kanatlar!N:N,$Y5)),"",INDEX(Kanatlar!N:N,$Y5)),IF(ISBLANK(INDEX(Forvetler!N:N,$Y5)),"",INDEX(Forvetler!N:N,$Y5)))) | O5: =IF($X5="","",CHOOSE($X5,IF(ISBLANK(INDEX(Kaleciler!O:O,$Y5)),"",INDEX(Kaleciler!O:O,$Y5)),IF(ISBLANK(INDEX(Stoperler!O:O,$Y5)),"",INDEX(Stoperler!O:O,$Y5)),IF(ISBLANK(INDEX('Sağ Bekler'!O:O,$Y5)),"",INDEX('Sağ Bekler'!O:O,$Y5)),IF(ISBLANK(INDEX('Sol Bekler'!O:O,$Y5)),"",INDEX('Sol Bekler'!O:O,$Y5)),IF(ISBLANK(INDEX('Orta Saha'!O:O,$Y5)),"",INDEX('Orta Saha'!O:O,$Y5)),IF(ISBLANK(INDEX(Kanatlar!O:O,$Y5)),"",INDEX(Kanatlar!O:O,$Y5)),IF(ISBLANK(INDEX(Forvetler!O:O,$Y5)),"",INDEX(Forvetler!O:O,$Y5)))) | P5: =IF($X5="","",CHOOSE($X5,IF(ISBLANK(INDEX(Kaleciler!P:P,$Y5)),"",INDEX(Kaleciler!P:P,$Y5)),IF(ISBLANK(INDEX(Stoperler!P:P,$Y5)),"",INDEX(Stoperler!P:P,$Y5)),IF(ISBLANK(INDEX('Sağ Bekler'!P:P,$Y5)),"",INDEX('Sağ Bekler'!P:P,$Y5)),IF(ISBLANK(INDEX('Sol Bekler'!P:P,$Y5)),"",INDEX('Sol Bekler'!P:P,$Y5)),IF(ISBLANK(INDEX('Orta Saha'!P:P,$Y5)),"",INDEX('Orta Saha'!P:P,$Y5)),IF(ISBLANK(INDEX(Kanatlar!P:P,$Y5)),"",INDEX(Kanatlar!P:P,$Y5)),IF(ISBLANK(INDEX(Forvetler!P:P,$Y5)),"",INDEX(Forvetler!P:P,$Y5)))) | Q5: =IF($X5="","",CHOOSE($X5,IF(ISBLANK(INDEX(Kaleciler!Q:Q,$Y5)),"",INDEX(Kaleciler!Q:Q,$Y5)),IF(ISBLANK(INDEX(Stoperler!Q:Q,$Y5)),"",INDEX(Stoperler!Q:Q,$Y5)),IF(ISBLANK(INDEX('Sağ Bekler'!Q:Q,$Y5)),"",INDEX('Sağ Bekler'!Q:Q,$Y5)),IF(ISBLANK(INDEX('Sol Bekler'!Q:Q,$Y5)),"",INDEX('Sol Bekler'!Q:Q,$Y5)),IF(ISBLANK(INDEX('Orta Saha'!Q:Q,$Y5)),"",INDEX('Orta Saha'!Q:Q,$Y5)),IF(ISBLANK(INDEX(Kanatlar!Q:Q,$Y5)),"",INDEX(Kanatlar!Q:Q,$Y5)),IF(ISBLANK(INDEX(Forvetler!Q:Q,$Y5)),"",INDEX(Forvetler!Q:Q,$Y5)))) -> A Liste | R5: =IF($X5="","",CHOOSE($X5,IF(ISBLANK(INDEX(Kaleciler!R:R,$Y5)),"",INDEX(Kaleciler!R:R,$Y5)),IF(ISBLANK(INDEX(Stoperler!R:R,$Y5)),"",INDEX(Stoperler!R:R,$Y5)),IF(ISBLANK(INDEX('Sağ Bekler'!R:R,$Y5)),"",INDEX('Sağ Bekler'!R:R,$Y5)),IF(ISBLANK(INDEX('Sol Bekler'!R:R,$Y5)),"",INDEX('Sol Bekler'!R:R,$Y5)),IF(ISBLANK(INDEX('Orta Saha'!R:R,$Y5)),"",INDEX('Orta Saha'!R:R,$Y5)),IF(ISBLANK(INDEX(Kanatlar!R:R,$Y5)),"",INDEX(Kanatlar!R:R,$Y5)),IF(ISBLANK(INDEX(Forvetler!R:R,$Y5)),"",INDEX(Forvetler!R:R,$Y5)))) | S5: =IF($X5="","",CHOOSE($X5,IF(ISBLANK(INDEX(Kaleciler!S:S,$Y5)),"",INDEX(Kaleciler!S:S,$Y5)),IF(ISBLANK(INDEX(Stoperler!S:S,$Y5)),"",INDEX(Stoperler!S:S,$Y5)),IF(ISBLANK(INDEX('Sağ Bekler'!S:S,$Y5)),"",INDEX('Sağ Bekler'!S:S,$Y5)),IF(ISBLANK(INDEX('Sol Bekler'!S:S,$Y5)),"",INDEX('Sol Bekler'!S:S,$Y5)),IF(ISBLANK(INDEX('Orta Saha'!S:S,$Y5)),"",INDEX('Orta Saha'!S:S,$Y5)),IF(ISBLANK(INDEX(Kanatlar!S:S,$Y5)),"",INDEX(Kanatlar!S:S,$Y5)),IF(ISBLANK(INDEX(Forvetler!S:S,$Y5)),"",INDEX(Forvetler!S:S,$Y5)))) | T5: =IF($X5="","",CHOOSE($X5,IF(ISBLANK(INDEX(Kaleciler!T:T,$Y5)),"",INDEX(Kaleciler!T:T,$Y5)),IF(ISBLANK(INDEX(Stoperler!T:T,$Y5)),"",INDEX(Stoperler!T:T,$Y5)),IF(ISBLANK(INDEX('Sağ Bekler'!T:T,$Y5)),"",INDEX('Sağ Bekler'!T:T,$Y5)),IF(ISBLANK(INDEX('Sol Bekler'!T:T,$Y5)),"",INDEX('Sol Bekler'!T:T,$Y5)),IF(ISBLANK(INDEX('Orta Saha'!T:T,$Y5)),"",INDEX('Orta Saha'!T:T,$Y5)),IF(ISBLANK(INDEX(Kanatlar!T:T,$Y5)),"",INDEX(Kanatlar!T:T,$Y5)),IF(ISBLANK(INDEX(Forvetler!T:T,$Y5)),"",INDEX(Forvetler!T:T,$Y5)))) | U5: 1 | V5: 5 | W5: =IF(Kaleciler!$Q$5="A Liste",COUNT($W$3:W4)+1,"") | X5: =IFERROR(INDEX($U$4:$U$703,MATCH(ROWS($X$4:X5),$W$4:$W$703,0)),"") -> 2 | Y5: =IFERROR(INDEX($V$4:$V$703,MATCH(ROWS($Y$4:Y5),$W$4:$W$703,0)),"") -> 8
A6: =IF($X6="","",CHOOSE($X6,IF(ISBLANK(INDEX(Kaleciler!A:A,$Y6)),"",INDEX(Kaleciler!A:A,$Y6)),IF(ISBLANK(INDEX(Stoperler!A:A,$Y6)),"",INDEX(Stoperler!A:A,$Y6)),IF(ISBLANK(INDEX('Sağ Bekler'!A:A,$Y6)),"",INDEX('Sağ Bekler'!A:A,$Y6)),IF(ISBLANK(INDEX('Sol Bekler'!A:A,$Y6)),"",INDEX('Sol Bekler'!A:A,$Y6)),IF(ISBLANK(INDEX('Orta Saha'!A:A,$Y6)),"",INDEX('Orta Saha'!A:A,$Y6)),IF(ISBLANK(INDEX(Kanatlar!A:A,$Y6)),"",INDEX(Kanatlar!A:A,$Y6)),IF(ISBLANK(INDEX(Forvetler!A:A,$Y6)),"",INDEX(Forvetler!A:A,$Y6)))) -> 3 | B6: =IF($X6="","",CHOOSE($X6,IF(ISBLANK(INDEX(Kaleciler!B:B,$Y6)),"",INDEX(Kaleciler!B:B,$Y6)),IF(ISBLANK(INDEX(Stoperler!B:B,$Y6)),"",INDEX(Stoperler!B:B,$Y6)),IF(ISBLANK(INDEX('Sağ Bekler'!B:B,$Y6)),"",INDEX('Sağ Bekler'!B:B,$Y6)),IF(ISBLANK(INDEX('Sol Bekler'!B:B,$Y6)),"",INDEX('Sol Bekler'!B:B,$Y6)),IF(ISBLANK(INDEX('Orta Saha'!B:B,$Y6)),"",INDEX('Orta Saha'!B:B,$Y6)),IF(ISBLANK(INDEX(Kanatlar!B:B,$Y6)),"",INDEX(Kanatlar!B:B,$Y6)),IF(ISBLANK(INDEX(Forvetler!B:B,$Y6)),"",INDEX(Forvetler!B:B,$Y6)))) -> LEON ÇALIŞKAN | C6: =IF($X6="","",CHOOSE($X6,IF(ISBLANK(INDEX(Kaleciler!C:C,$Y6)),"",INDEX(Kaleciler!C:C,$Y6)),IF(ISBLANK(INDEX(Stoperler!C:C,$Y6)),"",INDEX(Stoperler!C:C,$Y6)),IF(ISBLANK(INDEX('Sağ Bekler'!C:C,$Y6)),"",INDEX('Sağ Bekler'!C:C,$Y6)),IF(ISBLANK(INDEX('Sol Bekler'!C:C,$Y6)),"",INDEX('Sol Bekler'!C:C,$Y6)),IF(ISBLANK(INDEX('Orta Saha'!C:C,$Y6)),"",INDEX('Orta Saha'!C:C,$Y6)),IF(ISBLANK(INDEX(Kanatlar!C:C,$Y6)),"",INDEX(Kanatlar!C:C,$Y6)),IF(ISBLANK(INDEX(Forvetler!C:C,$Y6)),"",INDEX(Forvetler!C:C,$Y6)))) -> 38975 | D6: =IF($X6="","",CHOOSE($X6,IF(ISBLANK(INDEX(Kaleciler!D:D,$Y6)),"",INDEX(Kaleciler!D:D,$Y6)),IF(ISBLANK(INDEX(Stoperler!D:D,$Y6)),"",INDEX(Stoperler!D:D,$Y6)),IF(ISBLANK(INDEX('Sağ Bekler'!D:D,$Y6)),"",INDEX('Sağ Bekler'!D:D,$Y6)),IF(ISBLANK(INDEX('Sol Bekler'!D:D,$Y6)),"",INDEX('Sol Bekler'!D:D,$Y6)),IF(ISBLANK(INDEX('Orta Saha'!D:D,$Y6)),"",INDEX('Orta Saha'!D:D,$Y6)),IF(ISBLANK(INDEX(Kanatlar!D:D,$Y6)),"",INDEX(Kanatlar!D:D,$Y6)),IF(ISBLANK(INDEX(Forvetler!D:D,$Y6)),"",INDEX(Forvetler!D:D,$Y6)))) -> 20 | E6: =IF($X6="","",CHOOSE($X6,IF(ISBLANK(INDEX(Kaleciler!E:E,$Y6)),"",INDEX(Kaleciler!E:E,$Y6)),IF(ISBLANK(INDEX(Stoperler!E:E,$Y6)),"",INDEX(Stoperler!E:E,$Y6)),IF(ISBLANK(INDEX('Sağ Bekler'!E:E,$Y6)),"",INDEX('Sağ Bekler'!E:E,$Y6)),IF(ISBLANK(INDEX('Sol Bekler'!E:E,$Y6)),"",INDEX('Sol Bekler'!E:E,$Y6)),IF(ISBLANK(INDEX('Orta Saha'!E:E,$Y6)),"",INDEX('Orta Saha'!E:E,$Y6)),IF(ISBLANK(INDEX(Kanatlar!E:E,$Y6)),"",INDEX(Kanatlar!E:E,$Y6)),IF(ISBLANK(INDEX(Forvetler!E:E,$Y6)),"",INDEX(Forvetler!E:E,$Y6)))) -> Orta Saha | F6: =IF($X6="","",CHOOSE($X6,IF(ISBLANK(INDEX(Kaleciler!F:F,$Y6)),"",INDEX(Kaleciler!F:F,$Y6)),IF(ISBLANK(INDEX(Stoperler!F:F,$Y6)),"",INDEX(Stoperler!F:F,$Y6)),IF(ISBLANK(INDEX('Sağ Bekler'!F:F,$Y6)),"",INDEX('Sağ Bekler'!F:F,$Y6)),IF(ISBLANK(INDEX('Sol Bekler'!F:F,$Y6)),"",INDEX('Sol Bekler'!F:F,$Y6)),IF(ISBLANK(INDEX('Orta Saha'!F:F,$Y6)),"",INDEX('Orta Saha'!F:F,$Y6)),IF(ISBLANK(INDEX(Kanatlar!F:F,$Y6)),"",INDEX(Kanatlar!F:F,$Y6)),IF(ISBLANK(INDEX(Forvetler!F:F,$Y6)),"",INDEX(Forvetler!F:F,$Y6)))) -> Sol | G6: =IF($X6="","",CHOOSE($X6,IF(ISBLANK(INDEX(Kaleciler!G:G,$Y6)),"",INDEX(Kaleciler!G:G,$Y6)),IF(ISBLANK(INDEX(Stoperler!G:G,$Y6)),"",INDEX(Stoperler!G:G,$Y6)),IF(ISBLANK(INDEX('Sağ Bekler'!G:G,$Y6)),"",INDEX('Sağ Bekler'!G:G,$Y6)),IF(ISBLANK(INDEX('Sol Bekler'!G:G,$Y6)),"",INDEX('Sol Bekler'!G:G,$Y6)),IF(ISBLANK(INDEX('Orta Saha'!G:G,$Y6)),"",INDEX('Orta Saha'!G:G,$Y6)),IF(ISBLANK(INDEX(Kanatlar!G:G,$Y6)),"",INDEX(Kanatlar!G:G,$Y6)),IF(ISBLANK(INDEX(Forvetler!G:G,$Y6)),"",INDEX(Forvetler!G:G,$Y6)))) -> IĞDIR FK | H6: =IF($X6="","",CHOOSE($X6,IF(ISBLANK(INDEX(Kaleciler!H:H,$Y6)),"",INDEX(Kaleciler!H:H,$Y6)),IF(ISBLANK(INDEX(Stoperler!H:H,$Y6)),"",INDEX(Stoperler!H:H,$Y6)),IF(ISBLANK(INDEX('Sağ Bekler'!H:H,$Y6)),"",INDEX('Sağ Bekler'!H:H,$Y6)),IF(ISBLANK(INDEX('Sol Bekler'!H:H,$Y6)),"",INDEX('Sol Bekler'!H:H,$Y6)),IF(ISBLANK(INDEX('Orta Saha'!H:H,$Y6)),"",INDEX('Orta Saha'!H:H,$Y6)),IF(ISBLANK(INDEX(Kanatlar!H:H,$Y6)),"",INDEX(Kanatlar!H:H,$Y6)),IF(ISBLANK(INDEX(Forvetler!H:H,$Y6)),"",INDEX(Forvetler!H:H,$Y6)))) -> 1.Lig | I6: =IF($X6="","",CHOOSE($X6,IF(ISBLANK(INDEX(Kaleciler!I:I,$Y6)),"",INDEX(Kaleciler!I:I,$Y6)),IF(ISBLANK(INDEX(Stoperler!I:I,$Y6)),"",INDEX(Stoperler!I:I,$Y6)),IF(ISBLANK(INDEX('Sağ Bekler'!I:I,$Y6)),"",INDEX('Sağ Bekler'!I:I,$Y6)),IF(ISBLANK(INDEX('Sol Bekler'!I:I,$Y6)),"",INDEX('Sol Bekler'!I:I,$Y6)),IF(ISBLANK(INDEX('Orta Saha'!I:I,$Y6)),"",INDEX('Orta Saha'!I:I,$Y6)),IF(ISBLANK(INDEX(Kanatlar!I:I,$Y6)),"",INDEX(Kanatlar!I:I,$Y6)),IF(ISBLANK(INDEX(Forvetler!I:I,$Y6)),"",INDEX(Forvetler!I:I,$Y6)))) | J6: =IF($X6="","",CHOOSE($X6,IF(ISBLANK(INDEX(Kaleciler!J:J,$Y6)),"",INDEX(Kaleciler!J:J,$Y6)),IF(ISBLANK(INDEX(Stoperler!J:J,$Y6)),"",INDEX(Stoperler!J:J,$Y6)),IF(ISBLANK(INDEX('Sağ Bekler'!J:J,$Y6)),"",INDEX('Sağ Bekler'!J:J,$Y6)),IF(ISBLANK(INDEX('Sol Bekler'!J:J,$Y6)),"",INDEX('Sol Bekler'!J:J,$Y6)),IF(ISBLANK(INDEX('Orta Saha'!J:J,$Y6)),"",INDEX('Orta Saha'!J:J,$Y6)),IF(ISBLANK(INDEX(Kanatlar!J:J,$Y6)),"",INDEX(Kanatlar!J:J,$Y6)),IF(ISBLANK(INDEX(Forvetler!J:J,$Y6)),"",INDEX(Forvetler!J:J,$Y6)))) | K6: =IF($X6="","",CHOOSE($X6,IF(ISBLANK(INDEX(Kaleciler!K:K,$Y6)),"",INDEX(Kaleciler!K:K,$Y6)),IF(ISBLANK(INDEX(Stoperler!K:K,$Y6)),"",INDEX(Stoperler!K:K,$Y6)),IF(ISBLANK(INDEX('Sağ Bekler'!K:K,$Y6)),"",INDEX('Sağ Bekler'!K:K,$Y6)),IF(ISBLANK(INDEX('Sol Bekler'!K:K,$Y6)),"",INDEX('Sol Bekler'!K:K,$Y6)),IF(ISBLANK(INDEX('Orta Saha'!K:K,$Y6)),"",INDEX('Orta Saha'!K:K,$Y6)),IF(ISBLANK(INDEX(Kanatlar!K:K,$Y6)),"",INDEX(Kanatlar!K:K,$Y6)),IF(ISBLANK(INDEX(Forvetler!K:K,$Y6)),"",INDEX(Forvetler!K:K,$Y6)))) | L6: =IF($X6="","",CHOOSE($X6,IF(ISBLANK(INDEX(Kaleciler!L:L,$Y6)),"",INDEX(Kaleciler!L:L,$Y6)),IF(ISBLANK(INDEX(Stoperler!L:L,$Y6)),"",INDEX(Stoperler!L:L,$Y6)),IF(ISBLANK(INDEX('Sağ Bekler'!L:L,$Y6)),"",INDEX('Sağ Bekler'!L:L,$Y6)),IF(ISBLANK(INDEX('Sol Bekler'!L:L,$Y6)),"",INDEX('Sol Bekler'!L:L,$Y6)),IF(ISBLANK(INDEX('Orta Saha'!L:L,$Y6)),"",INDEX('Orta Saha'!L:L,$Y6)),IF(ISBLANK(INDEX(Kanatlar!L:L,$Y6)),"",INDEX(Kanatlar!L:L,$Y6)),IF(ISBLANK(INDEX(Forvetler!L:L,$Y6)),"",INDEX(Forvetler!L:L,$Y6)))) | M6: =IF($X6="","",CHOOSE($X6,IF(ISBLANK(INDEX(Kaleciler!M:M,$Y6)),"",INDEX(Kaleciler!M:M,$Y6)),IF(ISBLANK(INDEX(Stoperler!M:M,$Y6)),"",INDEX(Stoperler!M:M,$Y6)),IF(ISBLANK(INDEX('Sağ Bekler'!M:M,$Y6)),"",INDEX('Sağ Bekler'!M:M,$Y6)),IF(ISBLANK(INDEX('Sol Bekler'!M:M,$Y6)),"",INDEX('Sol Bekler'!M:M,$Y6)),IF(ISBLANK(INDEX('Orta Saha'!M:M,$Y6)),"",INDEX('Orta Saha'!M:M,$Y6)),IF(ISBLANK(INDEX(Kanatlar!M:M,$Y6)),"",INDEX(Kanatlar!M:M,$Y6)),IF(ISBLANK(INDEX(Forvetler!M:M,$Y6)),"",INDEX(Forvetler!M:M,$Y6)))) | N6: =IF($X6="","",CHOOSE($X6,IF(ISBLANK(INDEX(Kaleciler!N:N,$Y6)),"",INDEX(Kaleciler!N:N,$Y6)),IF(ISBLANK(INDEX(Stoperler!N:N,$Y6)),"",INDEX(Stoperler!N:N,$Y6)),IF(ISBLANK(INDEX('Sağ Bekler'!N:N,$Y6)),"",INDEX('Sağ Bekler'!N:N,$Y6)),IF(ISBLANK(INDEX('Sol Bekler'!N:N,$Y6)),"",INDEX('Sol Bekler'!N:N,$Y6)),IF(ISBLANK(INDEX('Orta Saha'!N:N,$Y6)),"",INDEX('Orta Saha'!N:N,$Y6)),IF(ISBLANK(INDEX(Kanatlar!N:N,$Y6)),"",INDEX(Kanatlar!N:N,$Y6)),IF(ISBLANK(INDEX(Forvetler!N:N,$Y6)),"",INDEX(Forvetler!N:N,$Y6)))) | O6: =IF($X6="","",CHOOSE($X6,IF(ISBLANK(INDEX(Kaleciler!O:O,$Y6)),"",INDEX(Kaleciler!O:O,$Y6)),IF(ISBLANK(INDEX(Stoperler!O:O,$Y6)),"",INDEX(Stoperler!O:O,$Y6)),IF(ISBLANK(INDEX('Sağ Bekler'!O:O,$Y6)),"",INDEX('Sağ Bekler'!O:O,$Y6)),IF(ISBLANK(INDEX('Sol Bekler'!O:O,$Y6)),"",INDEX('Sol Bekler'!O:O,$Y6)),IF(ISBLANK(INDEX('Orta Saha'!O:O,$Y6)),"",INDEX('Orta Saha'!O:O,$Y6)),IF(ISBLANK(INDEX(Kanatlar!O:O,$Y6)),"",INDEX(Kanatlar!O:O,$Y6)),IF(ISBLANK(INDEX(Forvetler!O:O,$Y6)),"",INDEX(Forvetler!O:O,$Y6)))) | P6: =IF($X6="","",CHOOSE($X6,IF(ISBLANK(INDEX(Kaleciler!P:P,$Y6)),"",INDEX(Kaleciler!P:P,$Y6)),IF(ISBLANK(INDEX(Stoperler!P:P,$Y6)),"",INDEX(Stoperler!P:P,$Y6)),IF(ISBLANK(INDEX('Sağ Bekler'!P:P,$Y6)),"",INDEX('Sağ Bekler'!P:P,$Y6)),IF(ISBLANK(INDEX('Sol Bekler'!P:P,$Y6)),"",INDEX('Sol Bekler'!P:P,$Y6)),IF(ISBLANK(INDEX('Orta Saha'!P:P,$Y6)),"",INDEX('Orta Saha'!P:P,$Y6)),IF(ISBLANK(INDEX(Kanatlar!P:P,$Y6)),"",INDEX(Kanatlar!P:P,$Y6)),IF(ISBLANK(INDEX(Forvetler!P:P,$Y6)),"",INDEX(Forvetler!P:P,$Y6)))) | Q6: =IF($X6="","",CHOOSE($X6,IF(ISBLANK(INDEX(Kaleciler!Q:Q,$Y6)),"",INDEX(Kaleciler!Q:Q,$Y6)),IF(ISBLANK(INDEX(Stoperler!Q:Q,$Y6)),"",INDEX(Stoperler!Q:Q,$Y6)),IF(ISBLANK(INDEX('Sağ Bekler'!Q:Q,$Y6)),"",INDEX('Sağ Bekler'!Q:Q,$Y6)),IF(ISBLANK(INDEX('Sol Bekler'!Q:Q,$Y6)),"",INDEX('Sol Bekler'!Q:Q,$Y6)),IF(ISBLANK(INDEX('Orta Saha'!Q:Q,$Y6)),"",INDEX('Orta Saha'!Q:Q,$Y6)),IF(ISBLANK(INDEX(Kanatlar!Q:Q,$Y6)),"",INDEX(Kanatlar!Q:Q,$Y6)),IF(ISBLANK(INDEX(Forvetler!Q:Q,$Y6)),"",INDEX(Forvetler!Q:Q,$Y6)))) -> A Liste | R6: =IF($X6="","",CHOOSE($X6,IF(ISBLANK(INDEX(Kaleciler!R:R,$Y6)),"",INDEX(Kaleciler!R:R,$Y6)),IF(ISBLANK(INDEX(Stoperler!R:R,$Y6)),"",INDEX(Stoperler!R:R,$Y6)),IF(ISBLANK(INDEX('Sağ Bekler'!R:R,$Y6)),"",INDEX('Sağ Bekler'!R:R,$Y6)),IF(ISBLANK(INDEX('Sol Bekler'!R:R,$Y6)),"",INDEX('Sol Bekler'!R:R,$Y6)),IF(ISBLANK(INDEX('Orta Saha'!R:R,$Y6)),"",INDEX('Orta Saha'!R:R,$Y6)),IF(ISBLANK(INDEX(Kanatlar!R:R,$Y6)),"",INDEX(Kanatlar!R:R,$Y6)),IF(ISBLANK(INDEX(Forvetler!R:R,$Y6)),"",INDEX(Forvetler!R:R,$Y6)))) | S6: =IF($X6="","",CHOOSE($X6,IF(ISBLANK(INDEX(Kaleciler!S:S,$Y6)),"",INDEX(Kaleciler!S:S,$Y6)),IF(ISBLANK(INDEX(Stoperler!S:S,$Y6)),"",INDEX(Stoperler!S:S,$Y6)),IF(ISBLANK(INDEX('Sağ Bekler'!S:S,$Y6)),"",INDEX('Sağ Bekler'!S:S,$Y6)),IF(ISBLANK(INDEX('Sol Bekler'!S:S,$Y6)),"",INDEX('Sol Bekler'!S:S,$Y6)),IF(ISBLANK(INDEX('Orta Saha'!S:S,$Y6)),"",INDEX('Orta Saha'!S:S,$Y6)),IF(ISBLANK(INDEX(Kanatlar!S:S,$Y6)),"",INDEX(Kanatlar!S:S,$Y6)),IF(ISBLANK(INDEX(Forvetler!S:S,$Y6)),"",INDEX(Forvetler!S:S,$Y6)))) | T6: =IF($X6="","",CHOOSE($X6,IF(ISBLANK(INDEX(Kaleciler!T:T,$Y6)),"",INDEX(Kaleciler!T:T,$Y6)),IF(ISBLANK(INDEX(Stoperler!T:T,$Y6)),"",INDEX(Stoperler!T:T,$Y6)),IF(ISBLANK(INDEX('Sağ Bekler'!T:T,$Y6)),"",INDEX('Sağ Bekler'!T:T,$Y6)),IF(ISBLANK(INDEX('Sol Bekler'!T:T,$Y6)),"",INDEX('Sol Bekler'!T:T,$Y6)),IF(ISBLANK(INDEX('Orta Saha'!T:T,$Y6)),"",INDEX('Orta Saha'!T:T,$Y6)),IF(ISBLANK(INDEX(Kanatlar!T:T,$Y6)),"",INDEX(Kanatlar!T:T,$Y6)),IF(ISBLANK(INDEX(Forvetler!T:T,$Y6)),"",INDEX(Forvetler!T:T,$Y6)))) | U6: 1 | V6: 6 | W6: =IF(Kaleciler!$Q$6="A Liste",COUNT($W$3:W5)+1,"") | X6: =IFERROR(INDEX($U$4:$U$703,MATCH(ROWS($X$4:X6),$W$4:$W$703,0)),"") -> 5 | Y6: =IFERROR(INDEX($V$4:$V$703,MATCH(ROWS($Y$4:Y6),$W$4:$W$703,0)),"") -> 6
A7: =IF($X7="","",CHOOSE($X7,IF(ISBLANK(INDEX(Kaleciler!A:A,$Y7)),"",INDEX(Kaleciler!A:A,$Y7)),IF(ISBLANK(INDEX(Stoperler!A:A,$Y7)),"",INDEX(Stoperler!A:A,$Y7)),IF(ISBLANK(INDEX('Sağ Bekler'!A:A,$Y7)),"",INDEX('Sağ Bekler'!A:A,$Y7)),IF(ISBLANK(INDEX('Sol Bekler'!A:A,$Y7)),"",INDEX('Sol Bekler'!A:A,$Y7)),IF(ISBLANK(INDEX('Orta Saha'!A:A,$Y7)),"",INDEX('Orta Saha'!A:A,$Y7)),IF(ISBLANK(INDEX(Kanatlar!A:A,$Y7)),"",INDEX(Kanatlar!A:A,$Y7)),IF(ISBLANK(INDEX(Forvetler!A:A,$Y7)),"",INDEX(Forvetler!A:A,$Y7)))) -> 8 | B7: =IF($X7="","",CHOOSE($X7,IF(ISBLANK(INDEX(Kaleciler!B:B,$Y7)),"",INDEX(Kaleciler!B:B,$Y7)),IF(ISBLANK(INDEX(Stoperler!B:B,$Y7)),"",INDEX(Stoperler!B:B,$Y7)),IF(ISBLANK(INDEX('Sağ Bekler'!B:B,$Y7)),"",INDEX('Sağ Bekler'!B:B,$Y7)),IF(ISBLANK(INDEX('Sol Bekler'!B:B,$Y7)),"",INDEX('Sol Bekler'!B:B,$Y7)),IF(ISBLANK(INDEX('Orta Saha'!B:B,$Y7)),"",INDEX('Orta Saha'!B:B,$Y7)),IF(ISBLANK(INDEX(Kanatlar!B:B,$Y7)),"",INDEX(Kanatlar!B:B,$Y7)),IF(ISBLANK(INDEX(Forvetler!B:B,$Y7)),"",INDEX(Forvetler!B:B,$Y7)))) -> EFEHAN PEKDEMİR | C7: =IF($X7="","",CHOOSE($X7,IF(ISBLANK(INDEX(Kaleciler!C:C,$Y7)),"",INDEX(Kaleciler!C:C,$Y7)),IF(ISBLANK(INDEX(Stoperler!C:C,$Y7)),"",INDEX(Stoperler!C:C,$Y7)),IF(ISBLANK(INDEX('Sağ Bekler'!C:C,$Y7)),"",INDEX('Sağ Bekler'!C:C,$Y7)),IF(ISBLANK(INDEX('Sol Bekler'!C:C,$Y7)),"",INDEX('Sol Bekler'!C:C,$Y7)),IF(ISBLANK(INDEX('Orta Saha'!C:C,$Y7)),"",INDEX('Orta Saha'!C:C,$Y7)),IF(ISBLANK(INDEX(Kanatlar!C:C,$Y7)),"",INDEX(Kanatlar!C:C,$Y7)),IF(ISBLANK(INDEX(Forvetler!C:C,$Y7)),"",INDEX(Forvetler!C:C,$Y7)))) -> 39265 | D7: =IF($X7="","",CHOOSE($X7,IF(ISBLANK(INDEX(Kaleciler!D:D,$Y7)),"",INDEX(Kaleciler!D:D,$Y7)),IF(ISBLANK(INDEX(Stoperler!D:D,$Y7)),"",INDEX(Stoperler!D:D,$Y7)),IF(ISBLANK(INDEX('Sağ Bekler'!D:D,$Y7)),"",INDEX('Sağ Bekler'!D:D,$Y7)),IF(ISBLANK(INDEX('Sol Bekler'!D:D,$Y7)),"",INDEX('Sol Bekler'!D:D,$Y7)),IF(ISBLANK(INDEX('Orta Saha'!D:D,$Y7)),"",INDEX('Orta Saha'!D:D,$Y7)),IF(ISBLANK(INDEX(Kanatlar!D:D,$Y7)),"",INDEX(Kanatlar!D:D,$Y7)),IF(ISBLANK(INDEX(Forvetler!D:D,$Y7)),"",INDEX(Forvetler!D:D,$Y7)))) -> 19 | E7: =IF($X7="","",CHOOSE($X7,IF(ISBLANK(INDEX(Kaleciler!E:E,$Y7)),"",INDEX(Kaleciler!E:E,$Y7)),IF(ISBLANK(INDEX(Stoperler!E:E,$Y7)),"",INDEX(Stoperler!E:E,$Y7)),IF(ISBLANK(INDEX('Sağ Bekler'!E:E,$Y7)),"",INDEX('Sağ Bekler'!E:E,$Y7)),IF(ISBLANK(INDEX('Sol Bekler'!E:E,$Y7)),"",INDEX('Sol Bekler'!E:E,$Y7)),IF(ISBLANK(INDEX('Orta Saha'!E:E,$Y7)),"",INDEX('Orta Saha'!E:E,$Y7)),IF(ISBLANK(INDEX(Kanatlar!E:E,$Y7)),"",INDEX(Kanatlar!E:E,$Y7)),IF(ISBLANK(INDEX(Forvetler!E:E,$Y7)),"",INDEX(Forvetler!E:E,$Y7)))) -> Orta Saha | F7: =IF($X7="","",CHOOSE($X7,IF(ISBLANK(INDEX(Kaleciler!F:F,$Y7)),"",INDEX(Kaleciler!F:F,$Y7)),IF(ISBLANK(INDEX(Stoperler!F:F,$Y7)),"",INDEX(Stoperler!F:F,$Y7)),IF(ISBLANK(INDEX('Sağ Bekler'!F:F,$Y7)),"",INDEX('Sağ Bekler'!F:F,$Y7)),IF(ISBLANK(INDEX('Sol Bekler'!F:F,$Y7)),"",INDEX('Sol Bekler'!F:F,$Y7)),IF(ISBLANK(INDEX('Orta Saha'!F:F,$Y7)),"",INDEX('Orta Saha'!F:F,$Y7)),IF(ISBLANK(INDEX(Kanatlar!F:F,$Y7)),"",INDEX(Kanatlar!F:F,$Y7)),IF(ISBLANK(INDEX(Forvetler!F:F,$Y7)),"",INDEX(Forvetler!F:F,$Y7)))) -> Sağ | G7: =IF($X7="","",CHOOSE($X7,IF(ISBLANK(INDEX(Kaleciler!G:G,$Y7)),"",INDEX(Kaleciler!G:G,$Y7)),IF(ISBLANK(INDEX(Stoperler!G:G,$Y7)),"",INDEX(Stoperler!G:G,$Y7)),IF(ISBLANK(INDEX('Sağ Bekler'!G:G,$Y7)),"",INDEX('Sağ Bekler'!G:G,$Y7)),IF(ISBLANK(INDEX('Sol Bekler'!G:G,$Y7)),"",INDEX('Sol Bekler'!G:G,$Y7)),IF(ISBLANK(INDEX('Orta Saha'!G:G,$Y7)),"",INDEX('Orta Saha'!G:G,$Y7)),IF(ISBLANK(INDEX(Kanatlar!G:G,$Y7)),"",INDEX(Kanatlar!G:G,$Y7)),IF(ISBLANK(INDEX(Forvetler!G:G,$Y7)),"",INDEX(Forvetler!G:G,$Y7)))) -> PENDİKSPOR | H7: =IF($X7="","",CHOOSE($X7,IF(ISBLANK(INDEX(Kaleciler!H:H,$Y7)),"",INDEX(Kaleciler!H:H,$Y7)),IF(ISBLANK(INDEX(Stoperler!H:H,$Y7)),"",INDEX(Stoperler!H:H,$Y7)),IF(ISBLANK(INDEX('Sağ Bekler'!H:H,$Y7)),"",INDEX('Sağ Bekler'!H:H,$Y7)),IF(ISBLANK(INDEX('Sol Bekler'!H:H,$Y7)),"",INDEX('Sol Bekler'!H:H,$Y7)),IF(ISBLANK(INDEX('Orta Saha'!H:H,$Y7)),"",INDEX('Orta Saha'!H:H,$Y7)),IF(ISBLANK(INDEX(Kanatlar!H:H,$Y7)),"",INDEX(Kanatlar!H:H,$Y7)),IF(ISBLANK(INDEX(Forvetler!H:H,$Y7)),"",INDEX(Forvetler!H:H,$Y7)))) -> 1.Lig | I7: =IF($X7="","",CHOOSE($X7,IF(ISBLANK(INDEX(Kaleciler!I:I,$Y7)),"",INDEX(Kaleciler!I:I,$Y7)),IF(ISBLANK(INDEX(Stoperler!I:I,$Y7)),"",INDEX(Stoperler!I:I,$Y7)),IF(ISBLANK(INDEX('Sağ Bekler'!I:I,$Y7)),"",INDEX('Sağ Bekler'!I:I,$Y7)),IF(ISBLANK(INDEX('Sol Bekler'!I:I,$Y7)),"",INDEX('Sol Bekler'!I:I,$Y7)),IF(ISBLANK(INDEX('Orta Saha'!I:I,$Y7)),"",INDEX('Orta Saha'!I:I,$Y7)),IF(ISBLANK(INDEX(Kanatlar!I:I,$Y7)),"",INDEX(Kanatlar!I:I,$Y7)),IF(ISBLANK(INDEX(Forvetler!I:I,$Y7)),"",INDEX(Forvetler!I:I,$Y7)))) -> 46934 | J7: =IF($X7="","",CHOOSE($X7,IF(ISBLANK(INDEX(Kaleciler!J:J,$Y7)),"",INDEX(Kaleciler!J:J,$Y7)),IF(ISBLANK(INDEX(Stoperler!J:J,$Y7)),"",INDEX(Stoperler!J:J,$Y7)),IF(ISBLANK(INDEX('Sağ Bekler'!J:J,$Y7)),"",INDEX('Sağ Bekler'!J:J,$Y7)),IF(ISBLANK(INDEX('Sol Bekler'!J:J,$Y7)),"",INDEX('Sol Bekler'!J:J,$Y7)),IF(ISBLANK(INDEX('Orta Saha'!J:J,$Y7)),"",INDEX('Orta Saha'!J:J,$Y7)),IF(ISBLANK(INDEX(Kanatlar!J:J,$Y7)),"",INDEX(Kanatlar!J:J,$Y7)),IF(ISBLANK(INDEX(Forvetler!J:J,$Y7)),"",INDEX(Forvetler!J:J,$Y7)))) | K7: =IF($X7="","",CHOOSE($X7,IF(ISBLANK(INDEX(Kaleciler!K:K,$Y7)),"",INDEX(Kaleciler!K:K,$Y7)),IF(ISBLANK(INDEX(Stoperler!K:K,$Y7)),"",INDEX(Stoperler!K:K,$Y7)),IF(ISBLANK(INDEX('Sağ Bekler'!K:K,$Y7)),"",INDEX('Sağ Bekler'!K:K,$Y7)),IF(ISBLANK(INDEX('Sol Bekler'!K:K,$Y7)),"",INDEX('Sol Bekler'!K:K,$Y7)),IF(ISBLANK(INDEX('Orta Saha'!K:K,$Y7)),"",INDEX('Orta Saha'!K:K,$Y7)),IF(ISBLANK(INDEX(Kanatlar!K:K,$Y7)),"",INDEX(Kanatlar!K:K,$Y7)),IF(ISBLANK(INDEX(Forvetler!K:K,$Y7)),"",INDEX(Forvetler!K:K,$Y7)))) | L7: =IF($X7="","",CHOOSE($X7,IF(ISBLANK(INDEX(Kaleciler!L:L,$Y7)),"",INDEX(Kaleciler!L:L,$Y7)),IF(ISBLANK(INDEX(Stoperler!L:L,$Y7)),"",INDEX(Stoperler!L:L,$Y7)),IF(ISBLANK(INDEX('Sağ Bekler'!L:L,$Y7)),"",INDEX('Sağ Bekler'!L:L,$Y7)),IF(ISBLANK(INDEX('Sol Bekler'!L:L,$Y7)),"",INDEX('Sol Bekler'!L:L,$Y7)),IF(ISBLANK(INDEX('Orta Saha'!L:L,$Y7)),"",INDEX('Orta Saha'!L:L,$Y7)),IF(ISBLANK(INDEX(Kanatlar!L:L,$Y7)),"",INDEX(Kanatlar!L:L,$Y7)),IF(ISBLANK(INDEX(Forvetler!L:L,$Y7)),"",INDEX(Forvetler!L:L,$Y7)))) | M7: =IF($X7="","",CHOOSE($X7,IF(ISBLANK(INDEX(Kaleciler!M:M,$Y7)),"",INDEX(Kaleciler!M:M,$Y7)),IF(ISBLANK(INDEX(Stoperler!M:M,$Y7)),"",INDEX(Stoperler!M:M,$Y7)),IF(ISBLANK(INDEX('Sağ Bekler'!M:M,$Y7)),"",INDEX('Sağ Bekler'!M:M,$Y7)),IF(ISBLANK(INDEX('Sol Bekler'!M:M,$Y7)),"",INDEX('Sol Bekler'!M:M,$Y7)),IF(ISBLANK(INDEX('Orta Saha'!M:M,$Y7)),"",INDEX('Orta Saha'!M:M,$Y7)),IF(ISBLANK(INDEX(Kanatlar!M:M,$Y7)),"",INDEX(Kanatlar!M:M,$Y7)),IF(ISBLANK(INDEX(Forvetler!M:M,$Y7)),"",INDEX(Forvetler!M:M,$Y7)))) | N7: =IF($X7="","",CHOOSE($X7,IF(ISBLANK(INDEX(Kaleciler!N:N,$Y7)),"",INDEX(Kaleciler!N:N,$Y7)),IF(ISBLANK(INDEX(Stoperler!N:N,$Y7)),"",INDEX(Stoperler!N:N,$Y7)),IF(ISBLANK(INDEX('Sağ Bekler'!N:N,$Y7)),"",INDEX('Sağ Bekler'!N:N,$Y7)),IF(ISBLANK(INDEX('Sol Bekler'!N:N,$Y7)),"",INDEX('Sol Bekler'!N:N,$Y7)),IF(ISBLANK(INDEX('Orta Saha'!N:N,$Y7)),"",INDEX('Orta Saha'!N:N,$Y7)),IF(ISBLANK(INDEX(Kanatlar!N:N,$Y7)),"",INDEX(Kanatlar!N:N,$Y7)),IF(ISBLANK(INDEX(Forvetler!N:N,$Y7)),"",INDEX(Forvetler!N:N,$Y7)))) | O7: =IF($X7="","",CHOOSE($X7,IF(ISBLANK(INDEX(Kaleciler!O:O,$Y7)),"",INDEX(Kaleciler!O:O,$Y7)),IF(ISBLANK(INDEX(Stoperler!O:O,$Y7)),"",INDEX(Stoperler!O:O,$Y7)),IF(ISBLANK(INDEX('Sağ Bekler'!O:O,$Y7)),"",INDEX('Sağ Bekler'!O:O,$Y7)),IF(ISBLANK(INDEX('Sol Bekler'!O:O,$Y7)),"",INDEX('Sol Bekler'!O:O,$Y7)),IF(ISBLANK(INDEX('Orta Saha'!O:O,$Y7)),"",INDEX('Orta Saha'!O:O,$Y7)),IF(ISBLANK(INDEX(Kanatlar!O:O,$Y7)),"",INDEX(Kanatlar!O:O,$Y7)),IF(ISBLANK(INDEX(Forvetler!O:O,$Y7)),"",INDEX(Forvetler!O:O,$Y7)))) | P7: =IF($X7="","",CHOOSE($X7,IF(ISBLANK(INDEX(Kaleciler!P:P,$Y7)),"",INDEX(Kaleciler!P:P,$Y7)),IF(ISBLANK(INDEX(Stoperler!P:P,$Y7)),"",INDEX(Stoperler!P:P,$Y7)),IF(ISBLANK(INDEX('Sağ Bekler'!P:P,$Y7)),"",INDEX('Sağ Bekler'!P:P,$Y7)),IF(ISBLANK(INDEX('Sol Bekler'!P:P,$Y7)),"",INDEX('Sol Bekler'!P:P,$Y7)),IF(ISBLANK(INDEX('Orta Saha'!P:P,$Y7)),"",INDEX('Orta Saha'!P:P,$Y7)),IF(ISBLANK(INDEX(Kanatlar!P:P,$Y7)),"",INDEX(Kanatlar!P:P,$Y7)),IF(ISBLANK(INDEX(Forvetler!P:P,$Y7)),"",INDEX(Forvetler!P:P,$Y7)))) | Q7: =IF($X7="","",CHOOSE($X7,IF(ISBLANK(INDEX(Kaleciler!Q:Q,$Y7)),"",INDEX(Kaleciler!Q:Q,$Y7)),IF(ISBLANK(INDEX(Stoperler!Q:Q,$Y7)),"",INDEX(Stoperler!Q:Q,$Y7)),IF(ISBLANK(INDEX('Sağ Bekler'!Q:Q,$Y7)),"",INDEX('Sağ Bekler'!Q:Q,$Y7)),IF(ISBLANK(INDEX('Sol Bekler'!Q:Q,$Y7)),"",INDEX('Sol Bekler'!Q:Q,$Y7)),IF(ISBLANK(INDEX('Orta Saha'!Q:Q,$Y7)),"",INDEX('Orta Saha'!Q:Q,$Y7)),IF(ISBLANK(INDEX(Kanatlar!Q:Q,$Y7)),"",INDEX(Kanatlar!Q:Q,$Y7)),IF(ISBLANK(INDEX(Forvetler!Q:Q,$Y7)),"",INDEX(Forvetler!Q:Q,$Y7)))) -> A Liste | R7: =IF($X7="","",CHOOSE($X7,IF(ISBLANK(INDEX(Kaleciler!R:R,$Y7)),"",INDEX(Kaleciler!R:R,$Y7)),IF(ISBLANK(INDEX(Stoperler!R:R,$Y7)),"",INDEX(Stoperler!R:R,$Y7)),IF(ISBLANK(INDEX('Sağ Bekler'!R:R,$Y7)),"",INDEX('Sağ Bekler'!R:R,$Y7)),IF(ISBLANK(INDEX('Sol Bekler'!R:R,$Y7)),"",INDEX('Sol Bekler'!R:R,$Y7)),IF(ISBLANK(INDEX('Orta Saha'!R:R,$Y7)),"",INDEX('Orta Saha'!R:R,$Y7)),IF(ISBLANK(INDEX(Kanatlar!R:R,$Y7)),"",INDEX(Kanatlar!R:R,$Y7)),IF(ISBLANK(INDEX(Forvetler!R:R,$Y7)),"",INDEX(Forvetler!R:R,$Y7)))) | S7: =IF($X7="","",CHOOSE($X7,IF(ISBLANK(INDEX(Kaleciler!S:S,$Y7)),"",INDEX(Kaleciler!S:S,$Y7)),IF(ISBLANK(INDEX(Stoperler!S:S,$Y7)),"",INDEX(Stoperler!S:S,$Y7)),IF(ISBLANK(INDEX('Sağ Bekler'!S:S,$Y7)),"",INDEX('Sağ Bekler'!S:S,$Y7)),IF(ISBLANK(INDEX('Sol Bekler'!S:S,$Y7)),"",INDEX('Sol Bekler'!S:S,$Y7)),IF(ISBLANK(INDEX('Orta Saha'!S:S,$Y7)),"",INDEX('Orta Saha'!S:S,$Y7)),IF(ISBLANK(INDEX(Kanatlar!S:S,$Y7)),"",INDEX(Kanatlar!S:S,$Y7)),IF(ISBLANK(INDEX(Forvetler!S:S,$Y7)),"",INDEX(Forvetler!S:S,$Y7)))) | T7: =IF($X7="","",CHOOSE($X7,IF(ISBLANK(INDEX(Kaleciler!T:T,$Y7)),"",INDEX(Kaleciler!T:T,$Y7)),IF(ISBLANK(INDEX(Stoperler!T:T,$Y7)),"",INDEX(Stoperler!T:T,$Y7)),IF(ISBLANK(INDEX('Sağ Bekler'!T:T,$Y7)),"",INDEX('Sağ Bekler'!T:T,$Y7)),IF(ISBLANK(INDEX('Sol Bekler'!T:T,$Y7)),"",INDEX('Sol Bekler'!T:T,$Y7)),IF(ISBLANK(INDEX('Orta Saha'!T:T,$Y7)),"",INDEX('Orta Saha'!T:T,$Y7)),IF(ISBLANK(INDEX(Kanatlar!T:T,$Y7)),"",INDEX(Kanatlar!T:T,$Y7)),IF(ISBLANK(INDEX(Forvetler!T:T,$Y7)),"",INDEX(Forvetler!T:T,$Y7)))) | U7: 1 | V7: 7 | W7: =IF(Kaleciler!$Q$7="A Liste",COUNT($W$3:W6)+1,"") | X7: =IFERROR(INDEX($U$4:$U$703,MATCH(ROWS($X$4:X7),$W$4:$W$703,0)),"") -> 5 | Y7: =IFERROR(INDEX($V$4:$V$703,MATCH(ROWS($Y$4:Y7),$W$4:$W$703,0)),"") -> 11
